Workbook

Sheet RawQ1
A1: person | B1: personLabel | C1: geslachtLabel | D1: geboortejaar | E1: geboorteplaatsLabel | F1: imageLink
A2: http://www.wikidata.org/entity/Q115818424 | B2: Achiel Piepers | C2: mannelijk | D2: 1871 | E2: Kuurne
A3: http://www.wikidata.org/entity/Q119013873 | B3: Achiel Van de Putte | C3: mannelijk | D3: 1868 | E3: Rollegem-Kapelle
A4: http://www.wikidata.org/entity/Q119217729 | B4: Achille Croquison | C4: mannelijk | D4: 1845 | E4: Kortrijk
A5: http://www.wikidata.org/entity/Q115834468 | B5: Achilles Bohyn | C5: mannelijk | D5: 1851 | E5: Kruishoutem
A6: http://www.wikidata.org/entity/Q123417058 | B6: Adela Pauline Courtens | C6: vrouwelijk | D6: 1832 | E6: Harelbeke
A7: http://www.wikidata.org/entity/Q125306156 | B7: Adelaida Antonia Vuylsteke | C7: vrouwelijk | D7: 1825 | E7: Menen
A8: http://www.wikidata.org/entity/Q113754119 | B8: Adolf De Wolf | C8: mannelijk | D8: 1844 | E8: Brugge
A9: http://www.wikidata.org/entity/Q2524668 | B9: Adolf Duclos | C9: mannelijk | D9: 1841 | E9: Brugge | F9: http://commons.wikimedia.org/wiki/Special:FilePath/Adolf%20Duclos001.jpg
A10: http://www.wikidata.org/entity/Q4722117 | B10: Adolf Lootens | C10: mannelijk | D10: 1835 | E10: Brugge
A11: http://www.wikidata.org/entity/Q43140929 | B11: Adolf Pauwels | C11: mannelijk | D11: 1864 | E11: Berchem
A12: http://www.wikidata.org/entity/Q100534520 | B12: Adolf Verriest | C12: mannelijk | D12: 1830 | E12: Deerlijk | F12: http://commons.wikimedia.org/wiki/Special:FilePath/Adolf%20Karel%20vader%20Petrus%20moeder%20Carolina%20Verriest%20in%201861.jpg
A13: http://www.wikidata.org/entity/Q5580544 | B13: Adrianus Bogaers | C13: mannelijk | D13: 1795 | E13: Den Haag | F13: http://commons.wikimedia.org/wiki/Special:FilePath/Adrianus%20Bogaers.jpg
A14: http://www.wikidata.org/entity/Q123051567 | B14: Agnes Cecilia Young | C14: vrouwelijk
A15: http://www.wikidata.org/entity/Q116687284 | B15: Agnes Mary Christophers | C15: vrouwelijk | D15: 1822 | E15: St Pancras
A16: http://www.wikidata.org/entity/Q115814290 | B16: Aimé Erneste Marie Dierick | C16: mannelijk | D16: 1865 | E16: Izegem
A17: http://www.wikidata.org/entity/Q115834690 | B17: Aimé Lagae | C17: mannelijk | D17: 1806 | E17: Heule
A18: http://www.wikidata.org/entity/Q15627098 | B18: Albany James Christie | C18: mannelijk | D18: 1817 | E18: Groot-Londen
A19: http://www.wikidata.org/entity/Q15627098 | B19: Albany James Christie | C19: mannelijk | D19: 1817 | E19: Southwark
A20: http://www.wikidata.org/entity/Q2832059 | B20: Albéric Emmanuel Henri Marie Ghislain Ruzette | C20: mannelijk | D20: 1866 | E20: Sint-Joost-ten-Node | F20: http://commons.wikimedia.org/wiki/Special:FilePath/Weekblad%20Pallieter%20-%20voorpagina%201924%2023%20baron%20ruzette.jpg
A21: http://www.wikidata.org/entity/Q118772822 | B21: Albert Aimé Marie Vandewalle | C21: mannelijk
A22: http://www.wikidata.org/entity/Q586323 | B22: Albert Verwey | C22: mannelijk | D22: 1865 | E22: Amsterdam | F22: http://commons.wikimedia.org/wiki/Special:FilePath/Portret%20van%20Albert%20Verwey%20Rijksmuseum%20SK-C-1680.jpeg
A23: http://www.wikidata.org/entity/Q56036018 | B23: Alexandre Bonvarlet | C23: mannelijk | D23: 1826 | E23: Duinkerke | F23: http://commons.wikimedia.org/wiki/Special:FilePath/Alexandre%20Bonvarlet%20by%20Michel%20Berthaud.jpg
A24: http://www.wikidata.org/entity/Q125490771 | B24: Alexandre Marie Ghislain Gillès de Pélichy | C24: mannelijk | D24: 1844 | E24: Antwerpen
A25: http://www.wikidata.org/entity/Q2332586 | B25: Alexis De Carne | C25: mannelijk | D25: 1848 | E25: Stavele
A26: http://www.wikidata.org/entity/Q119729450 | B26: Alfons Algoet | C26: mannelijk | D26: 1847 | E26: Brugge
A27: http://www.wikidata.org/entity/Q118142378 | B27: Alfons Bouckaert | C27: mannelijk | D27: 1867 | E27: Beveren
A28: http://www.wikidata.org/entity/Q110039191 | B28: Alfons Dassonville | C28: mannelijk | D28: 1860 | E28: Heule
A29: http://www.wikidata.org/entity/Q2100582 | B29: Alfons De Cock | C29: mannelijk | D29: 1850 | E29: Herdersem | F29: http://commons.wikimedia.org/wiki/Special:FilePath/Alfons%20de%20Cock%2C%20PA05233.jpg
A30: http://www.wikidata.org/entity/Q2638823 | B30: Alfons Janssens | C30: mannelijk | D30: 1841 | E30: Sint-Niklaas | F30: http://commons.wikimedia.org/wiki/Special:FilePath/Alfons%20Janssens.jpg
A31: http://www.wikidata.org/entity/Q56036059 | B31: Alfons Maria Napoleon Prayon-van Zuylen van Nyevelt | C31: mannelijk | D31: 1848 | E31: Gent
A32: http://www.wikidata.org/entity/Q2675588 | B32: Alfons Mervillie | C32: mannelijk | D32: 1856 | E32: Wontergem
A33: http://www.wikidata.org/entity/Q2539969 | B33: Alfons Siffer | C33: mannelijk | D33: 1850 | E33: Zomergem | F33: http://commons.wikimedia.org/wiki/Special:FilePath/Alfons%20Siffer%201850-1941.jpg
A34: http://www.wikidata.org/entity/Q119621396 | B34: Alfons Steinmetz | C34: mannelijk | D34: 1838
A35: http://www.wikidata.org/entity/Q120973166 | B35: Alfons Van Doorne | C35: mannelijk | D35: 1849 | E35: Poeke
A36: http://www.wikidata.org/entity/Q2050293 | B36: Alfons Van Hee | C36: mannelijk | D36: 1846 | E36: Lo-Reninge
A37: http://www.wikidata.org/entity/Q26845752 | B37: Alfred Guichon de Grandpont | C37: mannelijk | D37: 1807 | E37: Dijon
A38: http://www.wikidata.org/entity/Q115820635 | B38: Alfred Neut | C38: mannelijk | D38: 1845 | E38: Gent
A39: http://www.wikidata.org/entity/Q115821483 | B39: Aloïs Baelen | C39: mannelijk | D39: 1839 | E39: Poperinge
A40: http://www.wikidata.org/entity/Q2580620 | B40: Aloïs Nelis | C40: mannelijk | D40: 1842 | E40: Antwerpen
...

Sheet RawQ2
A1: Source | B1: Target | C1: Label
A2: Q101627274 | B2: Q110039191 | C2: heeft als correspondent
A3: Q2546317 | B3: Q3515115 | C3: heeft als correspondent
A4: Q110039361 | B4: Q2675588 | C4: heeft als correspondent
A5: Q110039159 | B5: Q15461013 | C5: heeft als correspondent
A6: Q17428533 | B6: Q3166510 | C6: heeft als correspondent
A7: Q115834834 | B7: Q2779054 | C7: heeft als correspondent
A8: Q115831509 | B8: Q20902162 | C8: heeft als correspondent
A9: Q113466955 | B9: Q3032807 | C9: heeft als correspondent
A10: Q115817263 | B10: Q115818849 | C10: heeft als correspondent
A11: Q115831509 | B11: Q120552708 | C11: heeft als correspondent
A12: Q115831509 | B12: Q123689724 | C12: heeft als correspondent
... A157: Q115835763 | B157: Q42196616 | C157: heeft als correspondent

Sheet RawQ3
A1: personA | B1: personB | C1: relatieTypeLabel
A2: http://www.wikidata.org/entity/Q100534520 | B2: http://www.wikidata.org/entity/Q981444 | C2: http://www.wikidata.org/prop/direct/P3373
A3: http://www.wikidata.org/entity/Q122854006 | B3: http://www.wikidata.org/entity/Q2672741 | C3: http://www.wikidata.org/prop/direct/P40
A4: http://www.wikidata.org/entity/Q122854006 | B4: http://www.wikidata.org/entity/Q2672741 | C4: http://www.wikidata.org/prop/direct/P22
A5: http://www.wikidata.org/entity/Q100534520 | B5: http://www.wikidata.org/entity/Q2190493 | C5: http://www.wikidata.org/prop/direct/P3373
A6: http://www.wikidata.org/entity/Q116687401 | B6: http://www.wikidata.org/entity/Q56036064 | C6: http://www.wikidata.org/prop/direct/P26
A7: http://www.wikidata.org/entity/Q122831483 | B7: http://www.wikidata.org/entity/Q13576607 | C7: http://www.wikidata.org/prop/direct/P3373
A8: http://www.wikidata.org/entity/Q2672741 | B8: http://www.wikidata.org/entity/Q354052 | C8: http://www.wikidata.org/prop/direct/P40
A9: http://www.wikidata.org/entity/Q2672741 | B9: http://www.wikidata.org/entity/Q354052 | C9: http://www.wikidata.org/prop/direct/P22
A10: http://www.wikidata.org/entity/Q2606766 | B10: http://www.wikidata.org/entity/Q3080591 | C10: http://www.wikidata.org/prop/direct/P3373
A11: http://www.wikidata.org/entity/Q2606766 | B11: http://www.wikidata.org/entity/Q3538623 | C11: http://www.wikidata.org/prop/direct/P22
A12: http://www.wikidata.org/entity/Q2606766 | B12: http://www.wikidata.org/entity/Q3538623 | C12: http://www.wikidata.org/prop/direct/P40
... A203: http://www.wikidata.org/entity/Q118732528 | B203: http://www.wikidata.org/entity/Q118732552 | C203: http://www.wikidata.org/prop/direct/P26

Sheet Nodes
A1: ID | B1: Label | C1: Type | D1: Gender | E1: Year of Birth | F1: Place of Birth | G1: Image link
A2: Q115839088 | B2: August Delbaere | C2: Person | D2: mannelijk | E2: 1847 | F2: Aalbeke | G2: Geen foto beschikbaar
A3: Q55672664 | B3: Hortense Delbaere | C3: Person | D3: vrouwelijk | E3: 1842 | F3: Aalbeke | G3: Geen foto beschikbaar
A4: Q115836535 | B4: Josephus Charle | C4: Person | D4: mannelijk | E4: 1823 | F4: Aalbeke | G4: Geen foto beschikbaar
A5: Q57197744 | B5: Ernestine De Seille | C5: Person | D5: vrouwelijk | E5: 1833 | F5: Aalter | G5: Geen foto beschikbaar
A6: Q115835763 | B6: Gerrit Pieter Roos | C6: Person | D6: mannelijk | E6: 1822 | F6: Aardenburg | G6: Geen foto beschikbaar
A7: Q125516501 | B7: Leonida Euphrasia Demonie | C7: Person | D7: vrouwelijk | E7: 1835 | F7: Aarsele | G7: Geen foto beschikbaar
A8: Q124619468 | B8: Amandus Devloo | C8: Person | D8: mannelijk | E8: 1856 | F8: Alveringem | G8: Geen foto beschikbaar
A9: Q125351404 | B9: Louis Vander Heyde | C9: Person | D9: mannelijk | E9: 1841 | F9: Alveringem | G9: Geen foto beschikbaar
A10: Q56036018 | B10: Albert Verwey | C10: Person | D10: mannelijk | E10: 1865 | F10: Amsterdam | G10: =IFERROR(VLOOKUP(B10,RawQ1!B:F,5,TRUE), "geen foto beschikbaar") -> http://commons.wikimedia.org/wiki/Special:FilePath/Portret%20van%20Albert%20Verwey%20Rijksmuseum%20SK-C-1680.jpeg
A11: Q2627945 | B11: Ian Theodor Beelen | C11: Person | D11: mannelijk | E11: 1807 | F11: Amsterdam | G11: Geen foto beschikbaar
A12: Q2424814 | B12: Jacob Verdam | C12: Person | D12: mannelijk | E12: 1845 | F12: Amsterdam | G12: =IFERROR(VLOOKUP(B12,RawQ1!B:F,5,TRUE), "geen foto beschikbaar") -> http://commons.wikimedia.org/wiki/Special:FilePath/Portret%20van%20Jacob%20Verdam%2C%20hoogleraar%20Nederlandse%20Taal%20te%20Leiden%20Icones%20298.tiff
A13: Q115839975 | B13: Joannes Alberdingk | C13: Person | D13: mannelijk | E13: 1788 | F13: Amsterdam | G13: Geen foto beschikbaar
A14: Q115831509 | B14: Joseph Alberdingk Thijm | C14: Person | D14: mannelijk | E14: 1820 | F14: Amsterdam | G14: =IFERROR(VLOOKUP(B14,RawQ1!B:F,5,TRUE), "geen foto beschikbaar") -> http://commons.wikimedia.org/wiki/Special:FilePath/Josephus%20Alberdingk%20Thijm%20portret%20%281864-1889%29.png
A15: Q119003821 | B15: Louis David Petit | C15: Person | D15: mannelijk | E15: 1847 | F15: Amsterdam | G15: Geen foto beschikbaar
A16: Q115979048 | B16: Paul Alberdingk Thijm | C16: Person | D16: mannelijk | E16: 1827 | F16: Amsterdam | G16: =IFERROR(VLOOKUP(B16,RawQ1!B:F,5,TRUE), "geen foto beschikbaar") -> http://commons.wikimedia.org/wiki/Special:FilePath/Portret%20van%20Paul%20Alberdingk%20Thijm.jpg
A17: Q2332586 | B17: Alexandre Marie Ghislain Gillès de Pélichy | C17: Person | D17: mannelijk | E17: 1844 | F17: Antwerpen | G17: Geen foto beschikbaar
A18: Q119013806 | B18: Aloïs Nelis | C18: Person | D18: mannelijk | E18: 1842 | F18: Antwerpen | G18: Geen foto beschikbaar
A19: Q42596 | B19: Frans De Cort | C19: Person | D19: mannelijk | E19: 1834 | F19: Antwerpen | G19: Geen foto beschikbaar
A20: Q571426 | B20: Hendrik Claes | C20: Person | D20: mannelijk | E20: 1849 | F20: Antwerpen | G20: Geen foto beschikbaar
A21: Q115815004 | B21: Hendrik Conscience | C21: Person | D21: mannelijk | E21: 1812 | F21: Antwerpen | G21: =IFERROR(VLOOKUP(B21,RawQ1!B:F,5,TRUE), "geen foto beschikbaar") -> http://commons.wikimedia.org/wiki/Special:FilePath/Hendrik%20Conscience.jpg
A22: Q7190386 | B22: Jan Van Beers | C22: Person | D22: mannelijk | E22: 1821 | F22: Antwerpen | G22: =IFERROR(VLOOKUP(B22,RawQ1!B:F,5,TRUE), "geen foto beschikbaar") -> http://commons.wikimedia.org/wiki/Special:FilePath/Jan%20Van%20Beers.jpg
A23: Q123741345 | B23: Julius Bouten | C23: Person | D23: mannelijk | E23: 1859 | F23: Antwerpen | G23: Geen foto beschikbaar
A24: Q672816 | B24: Max Rooses | C24: Person | D24: mannelijk | E24: 1839 | F24: Antwerpen | G24: =IFERROR(VLOOKUP(B24,RawQ1!B:F,5,TRUE), "geen foto beschikbaar") -> http://commons.wikimedia.org/wiki/Special:FilePath/Max%20Rooses.jpg
A25: Q42306892 | B25: Pieter Génard | C25: Person | D25: mannelijk | E25: 1830 | F25: Antwerpen | G25: =IFERROR(VLOOKUP(B25,RawQ1!B:F,5,TRUE), "geen foto beschikbaar") -> http://commons.wikimedia.org/wiki/Special:FilePath/PieterG%C3%A9nard.jpg
A26: Q113681935 | B26: Victor Alexis dela Montagne | C26: Person | D26: mannelijk | E26: 1854 | F26: Antwerpen | G26: =IFERROR(VLOOKUP(B26,RawQ1!B:F,5,TRUE), "geen foto beschikbaar") -> http://commons.wikimedia.org/wiki/Special:FilePath/Victor%20De%20la%20Montagne.png
A27: Q2658862 | B27: Auguste Reynaert | C27: Person | D27: mannelijk | E27: 1833 | F27: Anzegem | G27: =IFERROR(VLOOKUP(B27,RawQ1!B:F,5,TRUE), "geen foto beschikbaar") -> http://commons.wikimedia.org/wiki/Special:FilePath/Kortrijk%20Astridpark-11.JPG
A28: Q116687356 | B28: Leonardus Lootens | C28: Person | D28: mannelijk | E28: 1858 | F28: Anzegem | G28: Geen foto beschikbaar
A29: Q2770967 | B29: Eugenie Marie Delbaere | C29: Person | D29: vrouwelijk | E29: 1854 | F29: Ardooie | G29: Geen foto beschikbaar
A30: Q114945031 | B30: Leonie Sophie Marie De Ketelaere | C30: Person | D30: vrouwelijk | E30: 1850 | F30: Assebroek | G30: Geen foto beschikbaar
A31: Q2754460 | B31: Pieter Raoux | C31: Person | D31: mannelijk | E31: 1845 | F31: Assebroek | G31: Geen foto beschikbaar
A32: Q5026719 | B32: Camille Lateur | C32: Person | D32: mannelijk | E32: 1841 | F32: Avelgem | G32: Geen foto beschikbaar
A33: Q2087117 | B33: Raymond Muyldermans | C33: Person | D33: mannelijk | E33: 1864 | F33: Balen | G33: Geen foto beschikbaar
A34: Q21549953 | B34: Joaquim Rubió i Ors | C34: Person | D34: mannelijk | E34: 1818 | F34: Barcelona | G34: =IFERROR(VLOOKUP(B34,RawQ1!B:F,5,TRUE), "geen foto beschikbaar") -> http://commons.wikimedia.org/wiki/Special:FilePath/Rubio%20i%20ors.jpg
A35: Q123689972 | B35: Camiel-Hector Marichal | C35: Person | D35: mannelijk | E35: 1860 | F35: Beernem | G35: Geen foto beschikbaar
A36: Q56174577 | B36: Catherine O'Farrell | C36: Person | D36: vrouwelijk | E36: 1869 | F36: Belfast | G36: Geen foto beschikbaar
A37: Q116689485 | B37: Élie Henri Marie Félix de Coussemaker | C37: Person | D37: mannelijk | E37: 1845 | F37: Belle | G37: Geen foto beschikbaar
A38: Q15461013 | B38: François Auguste Van Costenoble | C38: Person | D38: mannelijk | E38: 1821 | F38: Belle | G38: Geen foto beschikbaar
A39: Q115827506 | B39: Ignace de Coussemaker | C39: Person | D39: mannelijk | E39: 1842 | F39: Belle | G39: Geen foto beschikbaar
A40: Q117244395 | B40: René-François Flahault | C40: Person | D40: mannelijk | E40: 1838 | F40: Belle | G40: Geen foto beschikbaar
...

Sheet Edges
A1: Source | B1: Target | C1: Label | D1: Type | E1: Weight | F1: Relationship Type
A2: Q101627274 | B2: Q110039191 | C2: heeft als correspondent | D2: Directed | E2: 1 | F2: heeft als correspondent
A3: Q2546317 | B3: Q3515115 | C3: heeft als correspondent | D3: Directed | E3: 1 | F3: heeft als correspondent
A4: Q110039361 | B4: Q2675588 | C4: heeft als correspondent | D4: Directed | E4: 1 | F4: heeft als correspondent
A5: Q110039159 | B5: Q15461013 | C5: heeft als correspondent | D5: Directed | E5: 1 | F5: heeft als correspondent
A6: Q17428533 | B6: Q3166510 | C6: heeft als correspondent | D6: Directed | E6: 1 | F6: heeft als correspondent
A7: Q115834834 | B7: Q2779054 | C7: heeft als correspondent | D7: Directed | E7: 1 | F7: heeft als correspondent
A8: Q115831509 | B8: Q20902162 | C8: heeft als correspondent | D8: Directed | E8: 1 | F8: heeft als correspondent
A9: Q113466955 | B9: Q3032807 | C9: heeft als correspondent | D9: Directed | E9: 1 | F9: heeft als correspondent
A10: Q115817263 | B10: Q115818849 | C10: heeft als correspondent | D10: Directed | E10: 1 | F10: heeft als correspondent
A11: Q115831509 | B11: Q120552708 | C11: heeft als correspondent | D11: Directed | E11: 1 | F11: heeft als correspondent
A12: Q115831509 | B12: Q123689724 | C12: heeft als correspondent | D12: Directed | E12: 1 | F12: heeft als correspondent
A13: Q113466955 | B13: Q118151362 | C13: heeft als correspondent | D13: Directed | E13: 1 | F13: heeft als correspondent
... A359: Q118732528 | B359: Q118732552 | C359: Partner | D359: Directed | E359: 1 | F359: familieverband
