Workbook

Sheet RawQ1AV1
A1: person | B1: personLabel | C1: relatieItemLabel | D1: richting | E1: wikidataLink | F1: wikipediaLink | G1: commonsLink | H1: image | I1: bioPortaalLink | J1: viafLink
A2: http://www.wikidata.org/entity/Q115818424 | B2: Achiel Piepers | C2: relevant persoon | D2: Guido naar Persoon | E2: https://www.wikidata.org/wiki/Q115818424
A3: http://www.wikidata.org/entity/Q119013873 | B3: Achiel Van de Putte | C3: relevant persoon | D3: Guido naar Persoon | E3: https://www.wikidata.org/wiki/Q119013873
A4: http://www.wikidata.org/entity/Q119217729 | B4: Achille Croquison | C4: relevant persoon | D4: Guido naar Persoon | E4: https://www.wikidata.org/wiki/Q119217729
A5: http://www.wikidata.org/entity/Q115834468 | B5: Achilles Bohyn | C5: relevant persoon | D5: Guido naar Persoon | E5: https://www.wikidata.org/wiki/Q115834468
A6: http://www.wikidata.org/entity/Q123417058 | B6: Adela Pauline Courtens | C6: relevant persoon | D6: Guido naar Persoon | E6: https://www.wikidata.org/wiki/Q123417058
A7: http://www.wikidata.org/entity/Q125306156 | B7: Adelaida Antonia Vuylsteke | C7: relevant persoon | D7: Guido naar Persoon | E7: https://www.wikidata.org/wiki/Q125306156
A8: http://www.wikidata.org/entity/Q113754119 | B8: Adolf De Wolf | C8: relevant persoon | D8: Guido naar Persoon | E8: https://www.wikidata.org/wiki/Q113754119 | F8: https://nl.wikipedia.org/wiki/Adolf_De_Wolf
A9: http://www.wikidata.org/entity/Q113754119 | B9: Adolf De Wolf | C9: student | D9: Guido naar Persoon | E9: https://www.wikidata.org/wiki/Q113754119 | F9: https://nl.wikipedia.org/wiki/Adolf_De_Wolf
A10: http://www.wikidata.org/entity/Q2524668 | B10: Adolf Duclos | C10: relevant persoon | D10: Guido naar Persoon | E10: https://www.wikidata.org/wiki/Q2524668 | F10: https://nl.wikipedia.org/wiki/Adolf_Duclos | G10: https://commons.wikimedia.org/wiki/Category:Adolf Duclos | H10: http://commons.wikimedia.org/wiki/Special:FilePath/Adolf%20Duclos001.jpg | J10: https://viaf.org/viaf/89293479
A11: http://www.wikidata.org/entity/Q4722117 | B11: Adolf Lootens | C11: relevant persoon | D11: Guido naar Persoon | E11: https://www.wikidata.org/wiki/Q4722117 | F11: https://nl.wikipedia.org/wiki/Adolf_Lootens | J11: https://viaf.org/viaf/281835917
A12: http://www.wikidata.org/entity/Q43140929 | B12: Adolf Pauwels | C12: relevant persoon | D12: Guido naar Persoon | E12: https://www.wikidata.org/wiki/Q43140929 | J12: https://viaf.org/viaf/27812240
A13: http://www.wikidata.org/entity/Q100534520 | B13: Adolf Verriest | C13: relevant persoon | D13: Guido naar Persoon | E13: https://www.wikidata.org/wiki/Q100534520 | F13: https://nl.wikipedia.org/wiki/Adolf_Verriest | H13: http://commons.wikimedia.org/wiki/Special:FilePath/Adolf%20Karel%20vader%20Petrus%20moeder%20Carolina%20Verriest%20in%201861.jpg
A14: http://www.wikidata.org/entity/Q5580544 | B14: Adrianus Bogaers | C14: relevant persoon | D14: Guido naar Persoon | E14: https://www.wikidata.org/wiki/Q5580544 | G14: https://commons.wikimedia.org/wiki/Category:Adrianus Bogaers | H14: http://commons.wikimedia.org/wiki/Special:FilePath/Adrianus%20Bogaers.jpg | J14: https://viaf.org/viaf/282197539
A15: http://www.wikidata.org/entity/Q136793932 | B15: Adèle Serweytens | C15: relevant persoon | D15: Guido naar Persoon | E15: https://www.wikidata.org/wiki/Q136793932
A16: http://www.wikidata.org/entity/Q123051567 | B16: Agnes Cecilia Young | C16: relevant persoon | D16: Guido naar Persoon | E16: https://www.wikidata.org/wiki/Q123051567
A17: http://www.wikidata.org/entity/Q115814290 | B17: Aimé Erneste Marie Dierick | C17: relevant persoon | D17: Guido naar Persoon | E17: https://www.wikidata.org/wiki/Q115814290
A18: http://www.wikidata.org/entity/Q115834690 | B18: Aimé Lagae | C18: relevant persoon | D18: Guido naar Persoon | E18: https://www.wikidata.org/wiki/Q115834690
A19: http://www.wikidata.org/entity/Q15627098 | B19: Albany James Christie | C19: relevant persoon | D19: Guido naar Persoon | E19: https://www.wikidata.org/wiki/Q15627098 | J19: https://viaf.org/viaf/199151458
A20: http://www.wikidata.org/entity/Q118772822 | B20: Albert Aimé Marie Vandewalle | C20: relevant persoon | D20: Guido naar Persoon | E20: https://www.wikidata.org/wiki/Q118772822
A21: http://www.wikidata.org/entity/Q586323 | B21: Albert Verwey | C21: relevant persoon | D21: Guido naar Persoon | E21: https://www.wikidata.org/wiki/Q586323 | F21: https://nl.wikipedia.org/wiki/Albert_Verwey | G21: https://commons.wikimedia.org/wiki/Category:Albert Verwey | H21: http://commons.wikimedia.org/wiki/Special:FilePath/Portret%20van%20Albert%20Verwey%20Rijksmuseum%20SK-C-1680.jpeg | J21: https://viaf.org/viaf/49275816
A22: http://www.wikidata.org/entity/Q2129415 | B22: Albéric Goethals | C22: relevant persoon | D22: Guido naar Persoon | E22: https://www.wikidata.org/wiki/Q2129415 | F22: https://nl.wikipedia.org/wiki/Alb%C3%A9ric_Goethals
A23: http://www.wikidata.org/entity/Q115811921 | B23: Alexandre Berghman | C23: relevant persoon | D23: Guido naar Persoon | E23: https://www.wikidata.org/wiki/Q115811921
A24: http://www.wikidata.org/entity/Q56036018 | B24: Alexandre Bonvarlet | C24: relevant persoon | D24: Guido naar Persoon | E24: https://www.wikidata.org/wiki/Q56036018 | G24: https://commons.wikimedia.org/wiki/Category:Alexandre Bonvarlet | H24: http://commons.wikimedia.org/wiki/Special:FilePath/Alexandre%20Bonvarlet%20by%20Michel%20Berthaud.jpg | J24: https://viaf.org/viaf/7516908
A25: http://www.wikidata.org/entity/Q125490771 | B25: Alexandre Marie Ghislain Gillès de Pélichy | C25: relevant persoon | D25: Guido naar Persoon | E25: https://www.wikidata.org/wiki/Q125490771 | J25: https://viaf.org/viaf/192623448
A26: http://www.wikidata.org/entity/Q2332586 | B26: Alexis De Carne | C26: relevant persoon | D26: Guido naar Persoon | E26: https://www.wikidata.org/wiki/Q2332586 | F26: https://nl.wikipedia.org/wiki/Alexis_De_Carne
A27: http://www.wikidata.org/entity/Q119729450 | B27: Alfons Algoet | C27: relevant persoon | D27: Guido naar Persoon | E27: https://www.wikidata.org/wiki/Q119729450
A28: http://www.wikidata.org/entity/Q118142378 | B28: Alfons Bouckaert | C28: relevant persoon | D28: Guido naar Persoon | E28: https://www.wikidata.org/wiki/Q118142378
A29: http://www.wikidata.org/entity/Q110039191 | B29: Alfons Dassonville | C29: relevant persoon | D29: Guido naar Persoon | E29: https://www.wikidata.org/wiki/Q110039191
A30: http://www.wikidata.org/entity/Q2100582 | B30: Alfons De Cock | C30: relevant persoon | D30: Guido naar Persoon | E30: https://www.wikidata.org/wiki/Q2100582 | F30: https://nl.wikipedia.org/wiki/Alfons_de_Cock | G30: https://commons.wikimedia.org/wiki/Category:Alfons De Cock | H30: http://commons.wikimedia.org/wiki/Special:FilePath/Alfons%20de%20Cock%2C%20PA05233.jpg | J30: https://viaf.org/viaf/34816409
A31: http://www.wikidata.org/entity/Q2638823 | B31: Alfons Janssens | C31: relevant persoon | D31: Guido naar Persoon | E31: https://www.wikidata.org/wiki/Q2638823 | F31: https://nl.wikipedia.org/wiki/Alfons_Janssens_(politicus) | G31: https://commons.wikimedia.org/wiki/Category:Alfons Janssens | H31: http://commons.wikimedia.org/wiki/Special:FilePath/Alfons%20Janssens.jpg
A32: http://www.wikidata.org/entity/Q56036059 | B32: Alfons Maria Napoleon Prayon-van Zuylen van Nyevelt | C32: relevant persoon | D32: Guido naar Persoon | E32: https://www.wikidata.org/wiki/Q56036059 | J32: https://viaf.org/viaf/89687993
A33: http://www.wikidata.org/entity/Q2675588 | B33: Alfons Mervillie | C33: relevant persoon | D33: Guido naar Persoon | E33: https://www.wikidata.org/wiki/Q2675588 | F33: https://nl.wikipedia.org/wiki/Alfons_Mervillie | G33: https://commons.wikimedia.org/wiki/Category:Alfons Mervillie | J33: https://viaf.org/viaf/306134590
A34: http://www.wikidata.org/entity/Q2539969 | B34: Alfons Siffer | C34: relevant persoon | D34: Guido naar Persoon | E34: https://www.wikidata.org/wiki/Q2539969 | F34: https://nl.wikipedia.org/wiki/Alfons_Siffer | H34: http://commons.wikimedia.org/wiki/Special:FilePath/Alfons%20Siffer%201850-1941.jpg | J34: https://viaf.org/viaf/193449593
A35: http://www.wikidata.org/entity/Q119621396 | B35: Alfons Steinmetz | C35: relevant persoon | D35: Guido naar Persoon | E35: https://www.wikidata.org/wiki/Q119621396
A36: http://www.wikidata.org/entity/Q120973166 | B36: Alfons Van Doorne | C36: relevant persoon | D36: Guido naar Persoon | E36: https://www.wikidata.org/wiki/Q120973166
A37: http://www.wikidata.org/entity/Q2050293 | B37: Alfons Van Hee | C37: relevant persoon | D37: Guido naar Persoon | E37: https://www.wikidata.org/wiki/Q2050293 | F37: https://nl.wikipedia.org/wiki/Alfons_Van_Hee
A38: http://www.wikidata.org/entity/Q26845752 | B38: Alfred Guichon de Grandpont | C38: relevant persoon | D38: Guido naar Persoon | E38: https://www.wikidata.org/wiki/Q26845752 | J38: https://viaf.org/viaf/88981493
A39: http://www.wikidata.org/entity/Q115820635 | B39: Alfred Neut | C39: relevant persoon | D39: Guido naar Persoon | E39: https://www.wikidata.org/wiki/Q115820635
A40: http://www.wikidata.org/entity/Q115815697 | B40: Aloysius De Visschere | C40: relevant persoon | D40: Guido naar Persoon | E40: https://www.wikidata.org/wiki/Q115815697
...

Sheet RawQ1BV1
A1: person | B1: personLabel | C1: relatieItemLabel | D1: richting | E1: wikidataLink | F1: wikipediaLink | G1: commonsLink | H1: image | I1: bioPortaalLink | J1: viafLink
A2: http://www.wikidata.org/entity/Q115818424 | B2: Achiel Piepers | C2: relevant persoon | D2: Persoon naar Guido | E2: https://www.wikidata.org/wiki/Q115818424
A3: http://www.wikidata.org/entity/Q119013873 | B3: Achiel Van de Putte | C3: relevant persoon | D3: Persoon naar Guido | E3: https://www.wikidata.org/wiki/Q119013873
A4: http://www.wikidata.org/entity/Q119217729 | B4: Achille Croquison | C4: relevant persoon | D4: Persoon naar Guido | E4: https://www.wikidata.org/wiki/Q119217729
A5: http://www.wikidata.org/entity/Q113754119 | B5: Adolf De Wolf | C5: relevant persoon | D5: Persoon naar Guido | E5: https://www.wikidata.org/wiki/Q113754119 | F5: https://nl.wikipedia.org/wiki/Adolf_De_Wolf
A6: http://www.wikidata.org/entity/Q113754119 | B6: Adolf De Wolf | C6: student van | D6: Persoon naar Guido | E6: https://www.wikidata.org/wiki/Q113754119 | F6: https://nl.wikipedia.org/wiki/Adolf_De_Wolf
A7: http://www.wikidata.org/entity/Q2524668 | B7: Adolf Duclos | C7: relevant persoon | D7: Persoon naar Guido | E7: https://www.wikidata.org/wiki/Q2524668 | F7: https://nl.wikipedia.org/wiki/Adolf_Duclos | G7: https://commons.wikimedia.org/wiki/Category:Adolf Duclos | H7: http://commons.wikimedia.org/wiki/Special:FilePath/Adolf%20Duclos001.jpg | J7: https://viaf.org/viaf/89293479
A8: http://www.wikidata.org/entity/Q43140929 | B8: Adolf Pauwels | C8: relevant persoon | D8: Persoon naar Guido | E8: https://www.wikidata.org/wiki/Q43140929 | J8: https://viaf.org/viaf/27812240
A9: http://www.wikidata.org/entity/Q100534520 | B9: Adolf Verriest | C9: relevant persoon | D9: Persoon naar Guido | E9: https://www.wikidata.org/wiki/Q100534520 | F9: https://nl.wikipedia.org/wiki/Adolf_Verriest | H9: http://commons.wikimedia.org/wiki/Special:FilePath/Adolf%20Karel%20vader%20Petrus%20moeder%20Carolina%20Verriest%20in%201861.jpg
A10: http://www.wikidata.org/entity/Q136793932 | B10: Adèle Serweytens | C10: relevant persoon | D10: Persoon naar Guido | E10: https://www.wikidata.org/wiki/Q136793932
A11: http://www.wikidata.org/entity/Q116687284 | B11: Agnes Mary Christophers | C11: relevant persoon | D11: Persoon naar Guido | E11: https://www.wikidata.org/wiki/Q116687284
A12: http://www.wikidata.org/entity/Q118772822 | B12: Albert Aimé Marie Vandewalle | C12: relevant persoon | D12: Persoon naar Guido | E12: https://www.wikidata.org/wiki/Q118772822
A13: http://www.wikidata.org/entity/Q586323 | B13: Albert Verwey | C13: relevant persoon | D13: Persoon naar Guido | E13: https://www.wikidata.org/wiki/Q586323 | F13: https://nl.wikipedia.org/wiki/Albert_Verwey | G13: https://commons.wikimedia.org/wiki/Category:Albert Verwey | H13: http://commons.wikimedia.org/wiki/Special:FilePath/Portret%20van%20Albert%20Verwey%20Rijksmuseum%20SK-C-1680.jpeg | J13: https://viaf.org/viaf/49275816
A14: http://www.wikidata.org/entity/Q2832059 | B14: Albéric Emmanuel Henri Marie Ghislain Ruzette | C14: relevant persoon | D14: Persoon naar Guido | E14: https://www.wikidata.org/wiki/Q2832059 | F14: https://nl.wikipedia.org/wiki/Alb%C3%A9ric_Ruzette | G14: https://commons.wikimedia.org/wiki/Category:Albéric Ruzette | H14: http://commons.wikimedia.org/wiki/Special:FilePath/Weekblad%20Pallieter%20-%20voorpagina%201924%2023%20baron%20ruzette.jpg
A15: http://www.wikidata.org/entity/Q115811921 | B15: Alexandre Berghman | C15: relevant persoon | D15: Persoon naar Guido | E15: https://www.wikidata.org/wiki/Q115811921
A16: http://www.wikidata.org/entity/Q56036018 | B16: Alexandre Bonvarlet | C16: relevant persoon | D16: Persoon naar Guido | E16: https://www.wikidata.org/wiki/Q56036018 | G16: https://commons.wikimedia.org/wiki/Category:Alexandre Bonvarlet | H16: http://commons.wikimedia.org/wiki/Special:FilePath/Alexandre%20Bonvarlet%20by%20Michel%20Berthaud.jpg | J16: https://viaf.org/viaf/7516908
A17: http://www.wikidata.org/entity/Q118142378 | B17: Alfons Bouckaert | C17: relevant persoon | D17: Persoon naar Guido | E17: https://www.wikidata.org/wiki/Q118142378
A18: http://www.wikidata.org/entity/Q110039191 | B18: Alfons Dassonville | C18: relevant persoon | D18: Persoon naar Guido | E18: https://www.wikidata.org/wiki/Q110039191
A19: http://www.wikidata.org/entity/Q2100582 | B19: Alfons De Cock | C19: relevant persoon | D19: Persoon naar Guido | E19: https://www.wikidata.org/wiki/Q2100582 | F19: https://nl.wikipedia.org/wiki/Alfons_de_Cock | G19: https://commons.wikimedia.org/wiki/Category:Alfons De Cock | H19: http://commons.wikimedia.org/wiki/Special:FilePath/Alfons%20de%20Cock%2C%20PA05233.jpg | J19: https://viaf.org/viaf/34816409
A20: http://www.wikidata.org/entity/Q2638823 | B20: Alfons Janssens | C20: relevant persoon | D20: Persoon naar Guido | E20: https://www.wikidata.org/wiki/Q2638823 | F20: https://nl.wikipedia.org/wiki/Alfons_Janssens_(politicus) | G20: https://commons.wikimedia.org/wiki/Category:Alfons Janssens | H20: http://commons.wikimedia.org/wiki/Special:FilePath/Alfons%20Janssens.jpg
A21: http://www.wikidata.org/entity/Q56036059 | B21: Alfons Maria Napoleon Prayon-van Zuylen van Nyevelt | C21: relevant persoon | D21: Persoon naar Guido | E21: https://www.wikidata.org/wiki/Q56036059 | J21: https://viaf.org/viaf/89687993
A22: http://www.wikidata.org/entity/Q2539969 | B22: Alfons Siffer | C22: relevant persoon | D22: Persoon naar Guido | E22: https://www.wikidata.org/wiki/Q2539969 | F22: https://nl.wikipedia.org/wiki/Alfons_Siffer | H22: http://commons.wikimedia.org/wiki/Special:FilePath/Alfons%20Siffer%201850-1941.jpg | J22: https://viaf.org/viaf/193449593
A23: http://www.wikidata.org/entity/Q119621396 | B23: Alfons Steinmetz | C23: relevant persoon | D23: Persoon naar Guido | E23: https://www.wikidata.org/wiki/Q119621396
A24: http://www.wikidata.org/entity/Q2050293 | B24: Alfons Van Hee | C24: relevant persoon | D24: Persoon naar Guido | E24: https://www.wikidata.org/wiki/Q2050293 | F24: https://nl.wikipedia.org/wiki/Alfons_Van_Hee
A25: http://www.wikidata.org/entity/Q26845752 | B25: Alfred Guichon de Grandpont | C25: relevant persoon | D25: Persoon naar Guido | E25: https://www.wikidata.org/wiki/Q26845752 | J25: https://viaf.org/viaf/88981493
A26: http://www.wikidata.org/entity/Q115979418 | B26: Aloysius Vandemaele | C26: relevant persoon | D26: Persoon naar Guido | E26: https://www.wikidata.org/wiki/Q115979418
A27: http://www.wikidata.org/entity/Q115979418 | B27: Aloysius Vandemaele | C27: student van | D27: Persoon naar Guido | E27: https://www.wikidata.org/wiki/Q115979418
A28: http://www.wikidata.org/entity/Q2580620 | B28: Aloïs Nelis | C28: relevant persoon | D28: Persoon naar Guido | E28: https://www.wikidata.org/wiki/Q2580620 | F28: https://nl.wikipedia.org/wiki/Alo%C3%AFs_Nelis
A29: http://www.wikidata.org/entity/Q2298746 | B29: Aloïs Walgrave | C29: relevant persoon | D29: Persoon naar Guido | E29: https://www.wikidata.org/wiki/Q2298746 | F29: https://nl.wikipedia.org/wiki/Alo%C3%AFs_Walgrave | G29: https://commons.wikimedia.org/wiki/Category:Aloïs Walgrave | J29: https://viaf.org/viaf/61918346
A30: http://www.wikidata.org/entity/Q2450554 | B30: Alphonse De Leyn | C30: relevant persoon | D30: Persoon naar Guido | E30: https://www.wikidata.org/wiki/Q2450554 | F30: https://nl.wikipedia.org/wiki/Alphonse_De_Leyn | J30: https://viaf.org/viaf/4993145857103622920901
A31: http://www.wikidata.org/entity/Q11071766 | B31: Alphonse de Voss | C31: student van | D31: Persoon naar Guido | E31: https://www.wikidata.org/wiki/Q11071766
A32: http://www.wikidata.org/entity/Q2099446 | B32: Amaat Joos | C32: relevant persoon | D32: Persoon naar Guido | E32: https://www.wikidata.org/wiki/Q2099446 | F32: https://nl.wikipedia.org/wiki/Amaat_Joos | H32: http://commons.wikimedia.org/wiki/Special:FilePath/Amaat%20Joos.jpg | J32: https://viaf.org/viaf/290811985
A33: http://www.wikidata.org/entity/Q3421496 | B33: Amaat Vyncke | C33: relevant persoon | D33: Persoon naar Guido | E33: https://www.wikidata.org/wiki/Q3421496 | F33: https://nl.wikipedia.org/wiki/Amaat_Vyncke | G33: https://commons.wikimedia.org/wiki/Category:Amaat Vyncke | H33: http://commons.wikimedia.org/wiki/Special:FilePath/Amaat%20Vyncke.jpg | J33: https://viaf.org/viaf/286791405
A34: http://www.wikidata.org/entity/Q970036 | B34: Amand Neut | C34: relevant persoon | D34: Persoon naar Guido | E34: https://www.wikidata.org/wiki/Q970036
A35: http://www.wikidata.org/entity/Q2481707 | B35: Amand de Vos | C35: relevant persoon | D35: Persoon naar Guido | E35: https://www.wikidata.org/wiki/Q2481707 | F35: https://nl.wikipedia.org/wiki/Amand_de_Vos | H35: http://commons.wikimedia.org/wiki/Special:FilePath/Wazenaar%20Amand%20de%20Vos.jpg | J35: https://viaf.org/viaf/74219351
A36: http://www.wikidata.org/entity/Q2481707 | B36: Amand de Vos | C36: relevant persoon | D36: Persoon naar Guido | E36: https://www.wikidata.org/wiki/Q2481707 | F36: https://nl.wikipedia.org/wiki/Amand_de_Vos | H36: http://commons.wikimedia.org/wiki/Special:FilePath/Wazenaar%20Amand%20de%20Vos.jpg | J36: https://viaf.org/viaf/286212977
A37: http://www.wikidata.org/entity/Q115811033 | B37: Amandus Dambre | C37: student van | D37: Persoon naar Guido | E37: https://www.wikidata.org/wiki/Q115811033
A38: http://www.wikidata.org/entity/Q119349594 | B38: Amelia De Vriese | C38: familielid | D38: Persoon naar Guido | E38: https://www.wikidata.org/wiki/Q119349594
A39: http://www.wikidata.org/entity/Q124619468 | B39: Amelia Vander Stichele | C39: relevant persoon | D39: Persoon naar Guido | E39: https://www.wikidata.org/wiki/Q124619468 | F39: https://nl.wikipedia.org/wiki/Amelia_Van_der_Stichele | H39: http://commons.wikimedia.org/wiki/Special:FilePath/Schilderij%20Henri%20Dobbelaere%20Engelendale.jpg
A40: http://www.wikidata.org/entity/Q1280942 | B40: Amédée Visart de Bocarmé | C40: relevant persoon | D40: Persoon naar Guido | E40: https://www.wikidata.org/wiki/Q1280942 | F40: https://nl.wikipedia.org/wiki/Amed%C3%A9e_Visart_de_Bocarm%C3%A9 | G40: https://commons.wikimedia.org/wiki/Category:Amedée Visart de Bocarmé | H40: http://commons.wikimedia.org/wiki/Special:FilePath/Portret%20van%20burgemeester%20Am%C3%A9d%C3%A9e%20Visart%20de%20Bocarm%C3%A9%2C%20circa%201837%20-%20circa%201924%2C%20Groeningemuseum%2C%200041286000.jpg | J40: https://viaf.org/viaf/90713808
...

Sheet RawDataQ1
A1: person | B1: personLabel | C1: relatieItemLabel | D1: richting | E1: wikidataLink | F1: wikipediaLink | G1: commonsLink | H1: image | I1: bioPortaalLink | J1: viafLink
A2: http://www.wikidata.org/entity/Q115818424 | B2: Achiel Piepers | C2: relevant persoon | D2: Guido naar Persoon | E2: https://www.wikidata.org/wiki/Q115818424
A3: http://www.wikidata.org/entity/Q119013873 | B3: Achiel Van de Putte | C3: relevant persoon | D3: Guido naar Persoon | E3: https://www.wikidata.org/wiki/Q119013873
A4: http://www.wikidata.org/entity/Q119217729 | B4: Achille Croquison | C4: relevant persoon | D4: Guido naar Persoon | E4: https://www.wikidata.org/wiki/Q119217729
A5: http://www.wikidata.org/entity/Q115834468 | B5: Achilles Bohyn | C5: relevant persoon | D5: Guido naar Persoon | E5: https://www.wikidata.org/wiki/Q115834468
A6: http://www.wikidata.org/entity/Q123417058 | B6: Adela Pauline Courtens | C6: relevant persoon | D6: Guido naar Persoon | E6: https://www.wikidata.org/wiki/Q123417058
A7: http://www.wikidata.org/entity/Q125306156 | B7: Adelaida Antonia Vuylsteke | C7: relevant persoon | D7: Guido naar Persoon | E7: https://www.wikidata.org/wiki/Q125306156
A8: http://www.wikidata.org/entity/Q113754119 | B8: Adolf De Wolf | C8: relevant persoon | D8: Guido naar Persoon | E8: https://www.wikidata.org/wiki/Q113754119 | F8: https://nl.wikipedia.org/wiki/Adolf_De_Wolf
A9: http://www.wikidata.org/entity/Q113754119 | B9: Adolf De Wolf | C9: student | D9: Guido naar Persoon | E9: https://www.wikidata.org/wiki/Q113754119 | F9: https://nl.wikipedia.org/wiki/Adolf_De_Wolf
A10: http://www.wikidata.org/entity/Q2524668 | B10: Adolf Duclos | C10: relevant persoon | D10: Guido naar Persoon | E10: https://www.wikidata.org/wiki/Q2524668 | F10: https://nl.wikipedia.org/wiki/Adolf_Duclos | G10: https://commons.wikimedia.org/wiki/Category:Adolf Duclos | H10: http://commons.wikimedia.org/wiki/Special:FilePath/Adolf%20Duclos001.jpg | J10: https://viaf.org/viaf/89293479
A11: http://www.wikidata.org/entity/Q4722117 | B11: Adolf Lootens | C11: relevant persoon | D11: Guido naar Persoon | E11: https://www.wikidata.org/wiki/Q4722117 | F11: https://nl.wikipedia.org/wiki/Adolf_Lootens | J11: https://viaf.org/viaf/281835917
A12: http://www.wikidata.org/entity/Q43140929 | B12: Adolf Pauwels | C12: relevant persoon | D12: Guido naar Persoon | E12: https://www.wikidata.org/wiki/Q43140929 | J12: https://viaf.org/viaf/27812240
A13: http://www.wikidata.org/entity/Q100534520 | B13: Adolf Verriest | C13: relevant persoon | D13: Guido naar Persoon | E13: https://www.wikidata.org/wiki/Q100534520 | F13: https://nl.wikipedia.org/wiki/Adolf_Verriest | H13: http://commons.wikimedia.org/wiki/Special:FilePath/Adolf%20Karel%20vader%20Petrus%20moeder%20Carolina%20Verriest%20in%201861.jpg
A14: http://www.wikidata.org/entity/Q5580544 | B14: Adrianus Bogaers | C14: relevant persoon | D14: Guido naar Persoon | E14: https://www.wikidata.org/wiki/Q5580544 | G14: https://commons.wikimedia.org/wiki/Category:Adrianus Bogaers | H14: http://commons.wikimedia.org/wiki/Special:FilePath/Adrianus%20Bogaers.jpg | J14: https://viaf.org/viaf/282197539
A15: http://www.wikidata.org/entity/Q136793932 | B15: Adèle Serweytens | C15: relevant persoon | D15: Guido naar Persoon | E15: https://www.wikidata.org/wiki/Q136793932
A16: http://www.wikidata.org/entity/Q123051567 | B16: Agnes Cecilia Young | C16: relevant persoon | D16: Guido naar Persoon | E16: https://www.wikidata.org/wiki/Q123051567
A17: http://www.wikidata.org/entity/Q115814290 | B17: Aimé Erneste Marie Dierick | C17: relevant persoon | D17: Guido naar Persoon | E17: https://www.wikidata.org/wiki/Q115814290
A18: http://www.wikidata.org/entity/Q115834690 | B18: Aimé Lagae | C18: relevant persoon | D18: Guido naar Persoon | E18: https://www.wikidata.org/wiki/Q115834690
A19: http://www.wikidata.org/entity/Q15627098 | B19: Albany James Christie | C19: relevant persoon | D19: Guido naar Persoon | E19: https://www.wikidata.org/wiki/Q15627098 | J19: https://viaf.org/viaf/199151458
A20: http://www.wikidata.org/entity/Q118772822 | B20: Albert Aimé Marie Vandewalle | C20: relevant persoon | D20: Guido naar Persoon | E20: https://www.wikidata.org/wiki/Q118772822
A21: http://www.wikidata.org/entity/Q586323 | B21: Albert Verwey | C21: relevant persoon | D21: Guido naar Persoon | E21: https://www.wikidata.org/wiki/Q586323 | F21: https://nl.wikipedia.org/wiki/Albert_Verwey | G21: https://commons.wikimedia.org/wiki/Category:Albert Verwey | H21: http://commons.wikimedia.org/wiki/Special:FilePath/Portret%20van%20Albert%20Verwey%20Rijksmuseum%20SK-C-1680.jpeg | J21: https://viaf.org/viaf/49275816
A22: http://www.wikidata.org/entity/Q2129415 | B22: Albéric Goethals | C22: relevant persoon | D22: Guido naar Persoon | E22: https://www.wikidata.org/wiki/Q2129415 | F22: https://nl.wikipedia.org/wiki/Alb%C3%A9ric_Goethals
A23: http://www.wikidata.org/entity/Q115811921 | B23: Alexandre Berghman | C23: relevant persoon | D23: Guido naar Persoon | E23: https://www.wikidata.org/wiki/Q115811921
A24: http://www.wikidata.org/entity/Q56036018 | B24: Alexandre Bonvarlet | C24: relevant persoon | D24: Guido naar Persoon | E24: https://www.wikidata.org/wiki/Q56036018 | G24: https://commons.wikimedia.org/wiki/Category:Alexandre Bonvarlet | H24: http://commons.wikimedia.org/wiki/Special:FilePath/Alexandre%20Bonvarlet%20by%20Michel%20Berthaud.jpg | J24: https://viaf.org/viaf/7516908
A25: http://www.wikidata.org/entity/Q125490771 | B25: Alexandre Marie Ghislain Gillès de Pélichy | C25: relevant persoon | D25: Guido naar Persoon | E25: https://www.wikidata.org/wiki/Q125490771 | J25: https://viaf.org/viaf/192623448
A26: http://www.wikidata.org/entity/Q2332586 | B26: Alexis De Carne | C26: relevant persoon | D26: Guido naar Persoon | E26: https://www.wikidata.org/wiki/Q2332586 | F26: https://nl.wikipedia.org/wiki/Alexis_De_Carne
A27: http://www.wikidata.org/entity/Q119729450 | B27: Alfons Algoet | C27: relevant persoon | D27: Guido naar Persoon | E27: https://www.wikidata.org/wiki/Q119729450
A28: http://www.wikidata.org/entity/Q118142378 | B28: Alfons Bouckaert | C28: relevant persoon | D28: Guido naar Persoon | E28: https://www.wikidata.org/wiki/Q118142378
A29: http://www.wikidata.org/entity/Q110039191 | B29: Alfons Dassonville | C29: relevant persoon | D29: Guido naar Persoon | E29: https://www.wikidata.org/wiki/Q110039191
A30: http://www.wikidata.org/entity/Q2100582 | B30: Alfons De Cock | C30: relevant persoon | D30: Guido naar Persoon | E30: https://www.wikidata.org/wiki/Q2100582 | F30: https://nl.wikipedia.org/wiki/Alfons_de_Cock | G30: https://commons.wikimedia.org/wiki/Category:Alfons De Cock | H30: http://commons.wikimedia.org/wiki/Special:FilePath/Alfons%20de%20Cock%2C%20PA05233.jpg | J30: https://viaf.org/viaf/34816409
A31: http://www.wikidata.org/entity/Q2638823 | B31: Alfons Janssens | C31: relevant persoon | D31: Guido naar Persoon | E31: https://www.wikidata.org/wiki/Q2638823 | F31: https://nl.wikipedia.org/wiki/Alfons_Janssens_(politicus) | G31: https://commons.wikimedia.org/wiki/Category:Alfons Janssens | H31: http://commons.wikimedia.org/wiki/Special:FilePath/Alfons%20Janssens.jpg
A32: http://www.wikidata.org/entity/Q56036059 | B32: Alfons Maria Napoleon Prayon-van Zuylen van Nyevelt | C32: relevant persoon | D32: Guido naar Persoon | E32: https://www.wikidata.org/wiki/Q56036059 | J32: https://viaf.org/viaf/89687993
A33: http://www.wikidata.org/entity/Q2675588 | B33: Alfons Mervillie | C33: relevant persoon | D33: Guido naar Persoon | E33: https://www.wikidata.org/wiki/Q2675588 | F33: https://nl.wikipedia.org/wiki/Alfons_Mervillie | G33: https://commons.wikimedia.org/wiki/Category:Alfons Mervillie | J33: https://viaf.org/viaf/306134590
A34: http://www.wikidata.org/entity/Q2539969 | B34: Alfons Siffer | C34: relevant persoon | D34: Guido naar Persoon | E34: https://www.wikidata.org/wiki/Q2539969 | F34: https://nl.wikipedia.org/wiki/Alfons_Siffer | H34: http://commons.wikimedia.org/wiki/Special:FilePath/Alfons%20Siffer%201850-1941.jpg | J34: https://viaf.org/viaf/193449593
A35: http://www.wikidata.org/entity/Q119621396 | B35: Alfons Steinmetz | C35: relevant persoon | D35: Guido naar Persoon | E35: https://www.wikidata.org/wiki/Q119621396
A36: http://www.wikidata.org/entity/Q120973166 | B36: Alfons Van Doorne | C36: relevant persoon | D36: Guido naar Persoon | E36: https://www.wikidata.org/wiki/Q120973166
A37: http://www.wikidata.org/entity/Q2050293 | B37: Alfons Van Hee | C37: relevant persoon | D37: Guido naar Persoon | E37: https://www.wikidata.org/wiki/Q2050293 | F37: https://nl.wikipedia.org/wiki/Alfons_Van_Hee
A38: http://www.wikidata.org/entity/Q26845752 | B38: Alfred Guichon de Grandpont | C38: relevant persoon | D38: Guido naar Persoon | E38: https://www.wikidata.org/wiki/Q26845752 | J38: https://viaf.org/viaf/88981493
A39: http://www.wikidata.org/entity/Q115820635 | B39: Alfred Neut | C39: relevant persoon | D39: Guido naar Persoon | E39: https://www.wikidata.org/wiki/Q115820635
A40: http://www.wikidata.org/entity/Q115815697 | B40: Aloysius De Visschere | C40: relevant persoon | D40: Guido naar Persoon | E40: https://www.wikidata.org/wiki/Q115815697
...

Sheet RawQ2AV1
A1: person | B1: personLabel | C1: rolItem | D1: rolLabel | E1: richting | F1: wikidataLink | G1: wikipediaLink | H1: commonsLink | I1: image | J1: bioPortaalLink | K1: viafLink
A2: http://www.wikidata.org/entity/Q136793932 | B2: Adèle Serweytens | C2: http://www.wikidata.org/entity/Q28008277 | D2: bekende | E2: Persoon naar Guido | F2: https://www.wikidata.org/wiki/Q136793932
A3: http://www.wikidata.org/entity/Q115811921 | B3: Alexandre Berghman | C3: http://www.wikidata.org/entity/Q28008277 | D3: bekende | E3: Persoon naar Guido | F3: https://www.wikidata.org/wiki/Q115811921
A4: http://www.wikidata.org/entity/Q129255433 | B4: Ann Mary Eyre | C4: http://www.wikidata.org/entity/Q28008277 | D4: bekende | E4: Persoon naar Guido | F4: https://www.wikidata.org/wiki/Q129255433
A5: http://www.wikidata.org/entity/Q117263671 | B5: Caroline Janssens | C5: http://www.wikidata.org/entity/Q28008277 | D5: bekende | E5: Persoon naar Guido | F5: https://www.wikidata.org/wiki/Q117263671
A6: http://www.wikidata.org/entity/Q136805616 | B6: Charles François Joseph Soudan | C6: http://www.wikidata.org/entity/Q28008277 | D6: bekende | E6: Persoon naar Guido | F6: https://www.wikidata.org/wiki/Q136805616
A7: http://www.wikidata.org/entity/Q122791372 | B7: Franciscus Leopoldus De Backere | C7: http://www.wikidata.org/entity/Q28008277 | D7: bekende | E7: Persoon naar Guido | F7: https://www.wikidata.org/wiki/Q122791372
A8: http://www.wikidata.org/entity/Q119794240 | B8: Hendrik Berghman | C8: http://www.wikidata.org/entity/Q28008277 | D8: bekende | E8: Persoon naar Guido | F8: https://www.wikidata.org/wiki/Q119794240
A9: http://www.wikidata.org/entity/Q126648476 | B9: Joseph Antonius Maria Ghislenus Anastasius Johannes Nepomucenus de Pélichy | C9: http://www.wikidata.org/entity/Q28008277 | D9: bekende | E9: Persoon naar Guido | F9: https://www.wikidata.org/wiki/Q126648476 | I9: http://commons.wikimedia.org/wiki/Special:FilePath/Joseph%20de%20Pelichy.jpg
A10: http://www.wikidata.org/entity/Q136814371 | B10: Louis Jean Van den Bilcke | C10: http://www.wikidata.org/entity/Q28008277 | D10: bekende | E10: Persoon naar Guido | F10: https://www.wikidata.org/wiki/Q136814371
A11: http://www.wikidata.org/entity/Q128053464 | B11: Marie Thérèse Courtens | C11: http://www.wikidata.org/entity/Q28008277 | D11: bekende | E11: Persoon naar Guido | F11: https://www.wikidata.org/wiki/Q128053464
A12: http://www.wikidata.org/entity/Q126913566 | B12: Valeer Alfons Vansteenhuyse | C12: http://www.wikidata.org/entity/Q28008277 | D12: bekende | E12: Persoon naar Guido | F12: https://www.wikidata.org/wiki/Q126913566
A13: http://www.wikidata.org/entity/Q129256307 | B13: Vincent William Eyre | C13: http://www.wikidata.org/entity/Q28008277 | D13: bekende | E13: Persoon naar Guido | F13: https://www.wikidata.org/wiki/Q129256307
A14: http://www.wikidata.org/entity/Q129256364 | B14: William Henry Eyre | C14: http://www.wikidata.org/entity/Q28008277 | D14: bekende | E14: Persoon naar Guido | F14: https://www.wikidata.org/wiki/Q129256364
A15: http://www.wikidata.org/entity/Q117226377 | B15: Emma Crombet | C15: http://www.wikidata.org/entity/Q16827718 | D15: biechtvader | E15: Persoon naar Guido | F15: https://www.wikidata.org/wiki/Q117226377
A16: http://www.wikidata.org/entity/Q116508871 | B16: Helena Amelia Walton | C16: http://www.wikidata.org/entity/Q16827718 | D16: biechtvader | E16: Persoon naar Guido | F16: https://www.wikidata.org/wiki/Q116508871
A17: http://www.wikidata.org/entity/Q129159907 | B17: Marie Louise Philomène Devrome | C17: http://www.wikidata.org/entity/Q16827718 | D17: biechtvader | E17: Persoon naar Guido | F17: https://www.wikidata.org/wiki/Q129159907
A18: http://www.wikidata.org/entity/Q122842204 | B18: Mary Louisa Farbrother | C18: http://www.wikidata.org/entity/Q16827718 | D18: biechtvader | E18: Persoon naar Guido | F18: https://www.wikidata.org/wiki/Q122842204
A19: http://www.wikidata.org/entity/Q115817390 | B19: Victor Lanssen | C19: http://www.wikidata.org/entity/Q16827718 | D19: biechtvader | E19: Persoon naar Guido | F19: https://www.wikidata.org/wiki/Q115817390
A20: http://www.wikidata.org/entity/Q115818424 | B20: Achiel Piepers | C20: http://www.wikidata.org/entity/Q3589290 | D20: briefschrijver | E20: Persoon naar Guido | F20: https://www.wikidata.org/wiki/Q115818424
A21: http://www.wikidata.org/entity/Q119013873 | B21: Achiel Van de Putte | C21: http://www.wikidata.org/entity/Q3589290 | D21: briefschrijver | E21: Persoon naar Guido | F21: https://www.wikidata.org/wiki/Q119013873
A22: http://www.wikidata.org/entity/Q119217729 | B22: Achille Croquison | C22: http://www.wikidata.org/entity/Q3589290 | D22: briefschrijver | E22: Persoon naar Guido | F22: https://www.wikidata.org/wiki/Q119217729
A23: http://www.wikidata.org/entity/Q113754119 | B23: Adolf De Wolf | C23: http://www.wikidata.org/entity/Q3589290 | D23: briefschrijver | E23: Persoon naar Guido | F23: https://www.wikidata.org/wiki/Q113754119 | G23: https://nl.wikipedia.org/wiki/Adolf_De_Wolf
A24: http://www.wikidata.org/entity/Q2524668 | B24: Adolf Duclos | C24: http://www.wikidata.org/entity/Q3589290 | D24: briefschrijver | E24: Persoon naar Guido | F24: https://www.wikidata.org/wiki/Q2524668 | G24: https://nl.wikipedia.org/wiki/Adolf_Duclos | H24: https://commons.wikimedia.org/wiki/Category:Adolf Duclos | I24: http://commons.wikimedia.org/wiki/Special:FilePath/Adolf%20Duclos001.jpg | K24: https://viaf.org/viaf/89293479
A25: http://www.wikidata.org/entity/Q43140929 | B25: Adolf Pauwels | C25: http://www.wikidata.org/entity/Q3589290 | D25: briefschrijver | E25: Persoon naar Guido | F25: https://www.wikidata.org/wiki/Q43140929 | K25: https://viaf.org/viaf/27812240
A26: http://www.wikidata.org/entity/Q100534520 | B26: Adolf Verriest | C26: http://www.wikidata.org/entity/Q3589290 | D26: briefschrijver | E26: Persoon naar Guido | F26: https://www.wikidata.org/wiki/Q100534520 | G26: https://nl.wikipedia.org/wiki/Adolf_Verriest | I26: http://commons.wikimedia.org/wiki/Special:FilePath/Adolf%20Karel%20vader%20Petrus%20moeder%20Carolina%20Verriest%20in%201861.jpg
A27: http://www.wikidata.org/entity/Q116687284 | B27: Agnes Mary Christophers | C27: http://www.wikidata.org/entity/Q3589290 | D27: briefschrijver | E27: Persoon naar Guido | F27: https://www.wikidata.org/wiki/Q116687284
A28: http://www.wikidata.org/entity/Q118772822 | B28: Albert Aimé Marie Vandewalle | C28: http://www.wikidata.org/entity/Q3589290 | D28: briefschrijver | E28: Persoon naar Guido | F28: https://www.wikidata.org/wiki/Q118772822
A29: http://www.wikidata.org/entity/Q586323 | B29: Albert Verwey | C29: http://www.wikidata.org/entity/Q3589290 | D29: briefschrijver | E29: Persoon naar Guido | F29: https://www.wikidata.org/wiki/Q586323 | G29: https://nl.wikipedia.org/wiki/Albert_Verwey | H29: https://commons.wikimedia.org/wiki/Category:Albert Verwey | I29: http://commons.wikimedia.org/wiki/Special:FilePath/Portret%20van%20Albert%20Verwey%20Rijksmuseum%20SK-C-1680.jpeg | K29: https://viaf.org/viaf/49275816
A30: http://www.wikidata.org/entity/Q2832059 | B30: Albéric Emmanuel Henri Marie Ghislain Ruzette | C30: http://www.wikidata.org/entity/Q3589290 | D30: briefschrijver | E30: Persoon naar Guido | F30: https://www.wikidata.org/wiki/Q2832059 | G30: https://nl.wikipedia.org/wiki/Alb%C3%A9ric_Ruzette | H30: https://commons.wikimedia.org/wiki/Category:Albéric Ruzette | I30: http://commons.wikimedia.org/wiki/Special:FilePath/Weekblad%20Pallieter%20-%20voorpagina%201924%2023%20baron%20ruzette.jpg
A31: http://www.wikidata.org/entity/Q56036018 | B31: Alexandre Bonvarlet | C31: http://www.wikidata.org/entity/Q3589290 | D31: briefschrijver | E31: Persoon naar Guido | F31: https://www.wikidata.org/wiki/Q56036018 | H31: https://commons.wikimedia.org/wiki/Category:Alexandre Bonvarlet | I31: http://commons.wikimedia.org/wiki/Special:FilePath/Alexandre%20Bonvarlet%20by%20Michel%20Berthaud.jpg | K31: https://viaf.org/viaf/7516908
A32: http://www.wikidata.org/entity/Q118142378 | B32: Alfons Bouckaert | C32: http://www.wikidata.org/entity/Q3589290 | D32: briefschrijver | E32: Persoon naar Guido | F32: https://www.wikidata.org/wiki/Q118142378
A33: http://www.wikidata.org/entity/Q110039191 | B33: Alfons Dassonville | C33: http://www.wikidata.org/entity/Q3589290 | D33: briefschrijver | E33: Persoon naar Guido | F33: https://www.wikidata.org/wiki/Q110039191
A34: http://www.wikidata.org/entity/Q2100582 | B34: Alfons De Cock | C34: http://www.wikidata.org/entity/Q3589290 | D34: briefschrijver | E34: Persoon naar Guido | F34: https://www.wikidata.org/wiki/Q2100582 | G34: https://nl.wikipedia.org/wiki/Alfons_de_Cock | H34: https://commons.wikimedia.org/wiki/Category:Alfons De Cock | I34: http://commons.wikimedia.org/wiki/Special:FilePath/Alfons%20de%20Cock%2C%20PA05233.jpg | K34: https://viaf.org/viaf/34816409
A35: http://www.wikidata.org/entity/Q2638823 | B35: Alfons Janssens | C35: http://www.wikidata.org/entity/Q3589290 | D35: briefschrijver | E35: Persoon naar Guido | F35: https://www.wikidata.org/wiki/Q2638823 | G35: https://nl.wikipedia.org/wiki/Alfons_Janssens_(politicus) | H35: https://commons.wikimedia.org/wiki/Category:Alfons Janssens | I35: http://commons.wikimedia.org/wiki/Special:FilePath/Alfons%20Janssens.jpg
A36: http://www.wikidata.org/entity/Q56036059 | B36: Alfons Maria Napoleon Prayon-van Zuylen van Nyevelt | C36: http://www.wikidata.org/entity/Q3589290 | D36: briefschrijver | E36: Persoon naar Guido | F36: https://www.wikidata.org/wiki/Q56036059 | K36: https://viaf.org/viaf/89687993
A37: http://www.wikidata.org/entity/Q2539969 | B37: Alfons Siffer | C37: http://www.wikidata.org/entity/Q3589290 | D37: briefschrijver | E37: Persoon naar Guido | F37: https://www.wikidata.org/wiki/Q2539969 | G37: https://nl.wikipedia.org/wiki/Alfons_Siffer | I37: http://commons.wikimedia.org/wiki/Special:FilePath/Alfons%20Siffer%201850-1941.jpg | K37: https://viaf.org/viaf/193449593
A38: http://www.wikidata.org/entity/Q2050293 | B38: Alfons Van Hee | C38: http://www.wikidata.org/entity/Q3589290 | D38: briefschrijver | E38: Persoon naar Guido | F38: https://www.wikidata.org/wiki/Q2050293 | G38: https://nl.wikipedia.org/wiki/Alfons_Van_Hee
A39: http://www.wikidata.org/entity/Q26845752 | B39: Alfred Guichon de Grandpont | C39: http://www.wikidata.org/entity/Q3589290 | D39: briefschrijver | E39: Persoon naar Guido | F39: https://www.wikidata.org/wiki/Q26845752 | K39: https://viaf.org/viaf/88981493
A40: http://www.wikidata.org/entity/Q115979418 | B40: Aloysius Vandemaele | C40: http://www.wikidata.org/entity/Q3589290 | D40: briefschrijver | E40: Persoon naar Guido | F40: https://www.wikidata.org/wiki/Q115979418
...

Sheet RawQ2BV1
A1: person | B1: personLabel | C1: rolItem | D1: rolLabel | E1: richting | F1: wikidataLink | G1: wikipediaLink | H1: commonsLink | I1: image | J1: bioPortaalLink | K1: viafLink
A2: http://www.wikidata.org/entity/Q126687489 | B2: Romain Joseph Lagae | C2: http://www.wikidata.org/entity/Q39631 | D2: arts | E2: Guido naar Persoon | F2: https://www.wikidata.org/wiki/Q126687489
A3: http://www.wikidata.org/entity/Q136793932 | B3: Adèle Serweytens | C3: http://www.wikidata.org/entity/Q28008277 | D3: bekende | E3: Guido naar Persoon | F3: https://www.wikidata.org/wiki/Q136793932
A4: http://www.wikidata.org/entity/Q115811921 | B4: Alexandre Berghman | C4: http://www.wikidata.org/entity/Q28008277 | D4: bekende | E4: Guido naar Persoon | F4: https://www.wikidata.org/wiki/Q115811921
A5: http://www.wikidata.org/entity/Q136793801 | B5: Alphonse Marie Joseph Ghislain Antoine Maus | C5: http://www.wikidata.org/entity/Q28008277 | D5: bekende | E5: Guido naar Persoon | F5: https://www.wikidata.org/wiki/Q136793801
A6: http://www.wikidata.org/entity/Q129255433 | B6: Ann Mary Eyre | C6: http://www.wikidata.org/entity/Q28008277 | D6: bekende | E6: Guido naar Persoon | F6: https://www.wikidata.org/wiki/Q129255433
A7: http://www.wikidata.org/entity/Q117263671 | B7: Caroline Janssens | C7: http://www.wikidata.org/entity/Q28008277 | D7: bekende | E7: Guido naar Persoon | F7: https://www.wikidata.org/wiki/Q117263671
A8: http://www.wikidata.org/entity/Q122791372 | B8: Franciscus Leopoldus De Backere | C8: http://www.wikidata.org/entity/Q28008277 | D8: bekende | E8: Guido naar Persoon | F8: https://www.wikidata.org/wiki/Q122791372
A9: http://www.wikidata.org/entity/Q126648476 | B9: Joseph Antonius Maria Ghislenus Anastasius Johannes Nepomucenus de Pélichy | C9: http://www.wikidata.org/entity/Q28008277 | D9: bekende | E9: Guido naar Persoon | F9: https://www.wikidata.org/wiki/Q126648476 | I9: http://commons.wikimedia.org/wiki/Special:FilePath/Joseph%20de%20Pelichy.jpg
A10: http://www.wikidata.org/entity/Q128053464 | B10: Marie Thérèse Courtens | C10: http://www.wikidata.org/entity/Q28008277 | D10: bekende | E10: Guido naar Persoon | F10: https://www.wikidata.org/wiki/Q128053464
A11: http://www.wikidata.org/entity/Q126913566 | B11: Valeer Alfons Vansteenhuyse | C11: http://www.wikidata.org/entity/Q28008277 | D11: bekende | E11: Guido naar Persoon | F11: https://www.wikidata.org/wiki/Q126913566
A12: http://www.wikidata.org/entity/Q129256307 | B12: Vincent William Eyre | C12: http://www.wikidata.org/entity/Q28008277 | D12: bekende | E12: Guido naar Persoon | F12: https://www.wikidata.org/wiki/Q129256307
A13: http://www.wikidata.org/entity/Q129256364 | B13: William Henry Eyre | C13: http://www.wikidata.org/entity/Q28008277 | D13: bekende | E13: Guido naar Persoon | F13: https://www.wikidata.org/wiki/Q129256364
A14: http://www.wikidata.org/entity/Q115829742 | B14: Bernardus Nachtergaele | C14: http://www.wikidata.org/entity/Q16827718 | D14: biechtvader | E14: Guido naar Persoon | F14: https://www.wikidata.org/wiki/Q115829742 | I14: http://commons.wikimedia.org/wiki/Special:FilePath/Bernard%20Nachtergaele%2C%20PA03099.jpg
A15: http://www.wikidata.org/entity/Q115818424 | B15: Achiel Piepers | C15: http://www.wikidata.org/entity/Q3589290 | D15: briefschrijver | E15: Guido naar Persoon | F15: https://www.wikidata.org/wiki/Q115818424
A16: http://www.wikidata.org/entity/Q119013873 | B16: Achiel Van de Putte | C16: http://www.wikidata.org/entity/Q3589290 | D16: briefschrijver | E16: Guido naar Persoon | F16: https://www.wikidata.org/wiki/Q119013873
A17: http://www.wikidata.org/entity/Q119217729 | B17: Achille Croquison | C17: http://www.wikidata.org/entity/Q3589290 | D17: briefschrijver | E17: Guido naar Persoon | F17: https://www.wikidata.org/wiki/Q119217729
A18: http://www.wikidata.org/entity/Q115834468 | B18: Achilles Bohyn | C18: http://www.wikidata.org/entity/Q3589290 | D18: briefschrijver | E18: Guido naar Persoon | F18: https://www.wikidata.org/wiki/Q115834468
A19: http://www.wikidata.org/entity/Q123417058 | B19: Adela Pauline Courtens | C19: http://www.wikidata.org/entity/Q3589290 | D19: briefschrijver | E19: Guido naar Persoon | F19: https://www.wikidata.org/wiki/Q123417058
A20: http://www.wikidata.org/entity/Q125306156 | B20: Adelaida Antonia Vuylsteke | C20: http://www.wikidata.org/entity/Q3589290 | D20: briefschrijver | E20: Guido naar Persoon | F20: https://www.wikidata.org/wiki/Q125306156
A21: http://www.wikidata.org/entity/Q113754119 | B21: Adolf De Wolf | C21: http://www.wikidata.org/entity/Q3589290 | D21: briefschrijver | E21: Guido naar Persoon | F21: https://www.wikidata.org/wiki/Q113754119 | G21: https://nl.wikipedia.org/wiki/Adolf_De_Wolf
A22: http://www.wikidata.org/entity/Q2524668 | B22: Adolf Duclos | C22: http://www.wikidata.org/entity/Q3589290 | D22: briefschrijver | E22: Guido naar Persoon | F22: https://www.wikidata.org/wiki/Q2524668 | G22: https://nl.wikipedia.org/wiki/Adolf_Duclos | H22: https://commons.wikimedia.org/wiki/Category:Adolf Duclos | I22: http://commons.wikimedia.org/wiki/Special:FilePath/Adolf%20Duclos001.jpg | K22: https://viaf.org/viaf/89293479
A23: http://www.wikidata.org/entity/Q4722117 | B23: Adolf Lootens | C23: http://www.wikidata.org/entity/Q3589290 | D23: briefschrijver | E23: Guido naar Persoon | F23: https://www.wikidata.org/wiki/Q4722117 | G23: https://nl.wikipedia.org/wiki/Adolf_Lootens | K23: https://viaf.org/viaf/281835917
A24: http://www.wikidata.org/entity/Q43140929 | B24: Adolf Pauwels | C24: http://www.wikidata.org/entity/Q3589290 | D24: briefschrijver | E24: Guido naar Persoon | F24: https://www.wikidata.org/wiki/Q43140929 | K24: https://viaf.org/viaf/27812240
A25: http://www.wikidata.org/entity/Q100534520 | B25: Adolf Verriest | C25: http://www.wikidata.org/entity/Q3589290 | D25: briefschrijver | E25: Guido naar Persoon | F25: https://www.wikidata.org/wiki/Q100534520 | G25: https://nl.wikipedia.org/wiki/Adolf_Verriest | I25: http://commons.wikimedia.org/wiki/Special:FilePath/Adolf%20Karel%20vader%20Petrus%20moeder%20Carolina%20Verriest%20in%201861.jpg
A26: http://www.wikidata.org/entity/Q5580544 | B26: Adrianus Bogaers | C26: http://www.wikidata.org/entity/Q3589290 | D26: briefschrijver | E26: Guido naar Persoon | F26: https://www.wikidata.org/wiki/Q5580544 | H26: https://commons.wikimedia.org/wiki/Category:Adrianus Bogaers | I26: http://commons.wikimedia.org/wiki/Special:FilePath/Adrianus%20Bogaers.jpg | K26: https://viaf.org/viaf/282197539
A27: http://www.wikidata.org/entity/Q123051567 | B27: Agnes Cecilia Young | C27: http://www.wikidata.org/entity/Q3589290 | D27: briefschrijver | E27: Guido naar Persoon | F27: https://www.wikidata.org/wiki/Q123051567
A28: http://www.wikidata.org/entity/Q115814290 | B28: Aimé Erneste Marie Dierick | C28: http://www.wikidata.org/entity/Q3589290 | D28: briefschrijver | E28: Guido naar Persoon | F28: https://www.wikidata.org/wiki/Q115814290
A29: http://www.wikidata.org/entity/Q115834690 | B29: Aimé Lagae | C29: http://www.wikidata.org/entity/Q3589290 | D29: briefschrijver | E29: Guido naar Persoon | F29: https://www.wikidata.org/wiki/Q115834690
A30: http://www.wikidata.org/entity/Q15627098 | B30: Albany James Christie | C30: http://www.wikidata.org/entity/Q3589290 | D30: briefschrijver | E30: Guido naar Persoon | F30: https://www.wikidata.org/wiki/Q15627098 | K30: https://viaf.org/viaf/199151458
A31: http://www.wikidata.org/entity/Q118772822 | B31: Albert Aimé Marie Vandewalle | C31: http://www.wikidata.org/entity/Q3589290 | D31: briefschrijver | E31: Guido naar Persoon | F31: https://www.wikidata.org/wiki/Q118772822
A32: http://www.wikidata.org/entity/Q586323 | B32: Albert Verwey | C32: http://www.wikidata.org/entity/Q3589290 | D32: briefschrijver | E32: Guido naar Persoon | F32: https://www.wikidata.org/wiki/Q586323 | G32: https://nl.wikipedia.org/wiki/Albert_Verwey | H32: https://commons.wikimedia.org/wiki/Category:Albert Verwey | I32: http://commons.wikimedia.org/wiki/Special:FilePath/Portret%20van%20Albert%20Verwey%20Rijksmuseum%20SK-C-1680.jpeg | K32: https://viaf.org/viaf/49275816
A33: http://www.wikidata.org/entity/Q56036018 | B33: Alexandre Bonvarlet | C33: http://www.wikidata.org/entity/Q3589290 | D33: briefschrijver | E33: Guido naar Persoon | F33: https://www.wikidata.org/wiki/Q56036018 | H33: https://commons.wikimedia.org/wiki/Category:Alexandre Bonvarlet | I33: http://commons.wikimedia.org/wiki/Special:FilePath/Alexandre%20Bonvarlet%20by%20Michel%20Berthaud.jpg | K33: https://viaf.org/viaf/7516908
A34: http://www.wikidata.org/entity/Q125490771 | B34: Alexandre Marie Ghislain Gillès de Pélichy | C34: http://www.wikidata.org/entity/Q3589290 | D34: briefschrijver | E34: Guido naar Persoon | F34: https://www.wikidata.org/wiki/Q125490771 | K34: https://viaf.org/viaf/192623448
A35: http://www.wikidata.org/entity/Q2332586 | B35: Alexis De Carne | C35: http://www.wikidata.org/entity/Q3589290 | D35: briefschrijver | E35: Guido naar Persoon | F35: https://www.wikidata.org/wiki/Q2332586 | G35: https://nl.wikipedia.org/wiki/Alexis_De_Carne
A36: http://www.wikidata.org/entity/Q119729450 | B36: Alfons Algoet | C36: http://www.wikidata.org/entity/Q3589290 | D36: briefschrijver | E36: Guido naar Persoon | F36: https://www.wikidata.org/wiki/Q119729450
A37: http://www.wikidata.org/entity/Q118142378 | B37: Alfons Bouckaert | C37: http://www.wikidata.org/entity/Q3589290 | D37: briefschrijver | E37: Guido naar Persoon | F37: https://www.wikidata.org/wiki/Q118142378
A38: http://www.wikidata.org/entity/Q110039191 | B38: Alfons Dassonville | C38: http://www.wikidata.org/entity/Q3589290 | D38: briefschrijver | E38: Guido naar Persoon | F38: https://www.wikidata.org/wiki/Q110039191
A39: http://www.wikidata.org/entity/Q2100582 | B39: Alfons De Cock | C39: http://www.wikidata.org/entity/Q3589290 | D39: briefschrijver | E39: Guido naar Persoon | F39: https://www.wikidata.org/wiki/Q2100582 | G39: https://nl.wikipedia.org/wiki/Alfons_de_Cock | H39: https://commons.wikimedia.org/wiki/Category:Alfons De Cock | I39: http://commons.wikimedia.org/wiki/Special:FilePath/Alfons%20de%20Cock%2C%20PA05233.jpg | K39: https://viaf.org/viaf/34816409
A40: http://www.wikidata.org/entity/Q2638823 | B40: Alfons Janssens | C40: http://www.wikidata.org/entity/Q3589290 | D40: briefschrijver | E40: Guido naar Persoon | F40: https://www.wikidata.org/wiki/Q2638823 | G40: https://nl.wikipedia.org/wiki/Alfons_Janssens_(politicus) | H40: https://commons.wikimedia.org/wiki/Category:Alfons Janssens | I40: http://commons.wikimedia.org/wiki/Special:FilePath/Alfons%20Janssens.jpg
...

Sheet RawDataQ2
A1: person | B1: personLabel | C1: rolItem | D1: rolLabel | E1: richting | F1: wikidataLink | G1: wikipediaLink | H1: commonsLink | I1: image | J1: bioPortaalLink | K1: viafLink
A2: http://www.wikidata.org/entity/Q136793932 | B2: Adèle Serweytens | C2: http://www.wikidata.org/entity/Q28008277 | D2: bekende | E2: Persoon naar Guido | F2: https://www.wikidata.org/wiki/Q136793932
A3: http://www.wikidata.org/entity/Q115811921 | B3: Alexandre Berghman | C3: http://www.wikidata.org/entity/Q28008277 | D3: bekende | E3: Persoon naar Guido | F3: https://www.wikidata.org/wiki/Q115811921
A4: http://www.wikidata.org/entity/Q129255433 | B4: Ann Mary Eyre | C4: http://www.wikidata.org/entity/Q28008277 | D4: bekende | E4: Persoon naar Guido | F4: https://www.wikidata.org/wiki/Q129255433
A5: http://www.wikidata.org/entity/Q117263671 | B5: Caroline Janssens | C5: http://www.wikidata.org/entity/Q28008277 | D5: bekende | E5: Persoon naar Guido | F5: https://www.wikidata.org/wiki/Q117263671
A6: http://www.wikidata.org/entity/Q136805616 | B6: Charles François Joseph Soudan | C6: http://www.wikidata.org/entity/Q28008277 | D6: bekende | E6: Persoon naar Guido | F6: https://www.wikidata.org/wiki/Q136805616
A7: http://www.wikidata.org/entity/Q122791372 | B7: Franciscus Leopoldus De Backere | C7: http://www.wikidata.org/entity/Q28008277 | D7: bekende | E7: Persoon naar Guido | F7: https://www.wikidata.org/wiki/Q122791372
A8: http://www.wikidata.org/entity/Q119794240 | B8: Hendrik Berghman | C8: http://www.wikidata.org/entity/Q28008277 | D8: bekende | E8: Persoon naar Guido | F8: https://www.wikidata.org/wiki/Q119794240
A9: http://www.wikidata.org/entity/Q126648476 | B9: Joseph Antonius Maria Ghislenus Anastasius Johannes Nepomucenus de Pélichy | C9: http://www.wikidata.org/entity/Q28008277 | D9: bekende | E9: Persoon naar Guido | F9: https://www.wikidata.org/wiki/Q126648476 | I9: http://commons.wikimedia.org/wiki/Special:FilePath/Joseph%20de%20Pelichy.jpg
A10: http://www.wikidata.org/entity/Q136814371 | B10: Louis Jean Van den Bilcke | C10: http://www.wikidata.org/entity/Q28008277 | D10: bekende | E10: Persoon naar Guido | F10: https://www.wikidata.org/wiki/Q136814371
A11: http://www.wikidata.org/entity/Q128053464 | B11: Marie Thérèse Courtens | C11: http://www.wikidata.org/entity/Q28008277 | D11: bekende | E11: Persoon naar Guido | F11: https://www.wikidata.org/wiki/Q128053464
A12: http://www.wikidata.org/entity/Q126913566 | B12: Valeer Alfons Vansteenhuyse | C12: http://www.wikidata.org/entity/Q28008277 | D12: bekende | E12: Persoon naar Guido | F12: https://www.wikidata.org/wiki/Q126913566
A13: http://www.wikidata.org/entity/Q129256307 | B13: Vincent William Eyre | C13: http://www.wikidata.org/entity/Q28008277 | D13: bekende | E13: Persoon naar Guido | F13: https://www.wikidata.org/wiki/Q129256307
A14: http://www.wikidata.org/entity/Q129256364 | B14: William Henry Eyre | C14: http://www.wikidata.org/entity/Q28008277 | D14: bekende | E14: Persoon naar Guido | F14: https://www.wikidata.org/wiki/Q129256364
A15: http://www.wikidata.org/entity/Q117226377 | B15: Emma Crombet | C15: http://www.wikidata.org/entity/Q16827718 | D15: biechtvader | E15: Persoon naar Guido | F15: https://www.wikidata.org/wiki/Q117226377
A16: http://www.wikidata.org/entity/Q116508871 | B16: Helena Amelia Walton | C16: http://www.wikidata.org/entity/Q16827718 | D16: biechtvader | E16: Persoon naar Guido | F16: https://www.wikidata.org/wiki/Q116508871
A17: http://www.wikidata.org/entity/Q129159907 | B17: Marie Louise Philomène Devrome | C17: http://www.wikidata.org/entity/Q16827718 | D17: biechtvader | E17: Persoon naar Guido | F17: https://www.wikidata.org/wiki/Q129159907
A18: http://www.wikidata.org/entity/Q122842204 | B18: Mary Louisa Farbrother | C18: http://www.wikidata.org/entity/Q16827718 | D18: biechtvader | E18: Persoon naar Guido | F18: https://www.wikidata.org/wiki/Q122842204
A19: http://www.wikidata.org/entity/Q115817390 | B19: Victor Lanssen | C19: http://www.wikidata.org/entity/Q16827718 | D19: biechtvader | E19: Persoon naar Guido | F19: https://www.wikidata.org/wiki/Q115817390
A20: http://www.wikidata.org/entity/Q115818424 | B20: Achiel Piepers | C20: http://www.wikidata.org/entity/Q3589290 | D20: briefschrijver | E20: Persoon naar Guido | F20: https://www.wikidata.org/wiki/Q115818424
A21: http://www.wikidata.org/entity/Q119013873 | B21: Achiel Van de Putte | C21: http://www.wikidata.org/entity/Q3589290 | D21: briefschrijver | E21: Persoon naar Guido | F21: https://www.wikidata.org/wiki/Q119013873
A22: http://www.wikidata.org/entity/Q119217729 | B22: Achille Croquison | C22: http://www.wikidata.org/entity/Q3589290 | D22: briefschrijver | E22: Persoon naar Guido | F22: https://www.wikidata.org/wiki/Q119217729
A23: http://www.wikidata.org/entity/Q113754119 | B23: Adolf De Wolf | C23: http://www.wikidata.org/entity/Q3589290 | D23: briefschrijver | E23: Persoon naar Guido | F23: https://www.wikidata.org/wiki/Q113754119 | G23: https://nl.wikipedia.org/wiki/Adolf_De_Wolf
A24: http://www.wikidata.org/entity/Q2524668 | B24: Adolf Duclos | C24: http://www.wikidata.org/entity/Q3589290 | D24: briefschrijver | E24: Persoon naar Guido | F24: https://www.wikidata.org/wiki/Q2524668 | G24: https://nl.wikipedia.org/wiki/Adolf_Duclos | H24: https://commons.wikimedia.org/wiki/Category:Adolf Duclos | I24: http://commons.wikimedia.org/wiki/Special:FilePath/Adolf%20Duclos001.jpg | K24: https://viaf.org/viaf/89293479
A25: http://www.wikidata.org/entity/Q43140929 | B25: Adolf Pauwels | C25: http://www.wikidata.org/entity/Q3589290 | D25: briefschrijver | E25: Persoon naar Guido | F25: https://www.wikidata.org/wiki/Q43140929 | K25: https://viaf.org/viaf/27812240
A26: http://www.wikidata.org/entity/Q100534520 | B26: Adolf Verriest | C26: http://www.wikidata.org/entity/Q3589290 | D26: briefschrijver | E26: Persoon naar Guido | F26: https://www.wikidata.org/wiki/Q100534520 | G26: https://nl.wikipedia.org/wiki/Adolf_Verriest | I26: http://commons.wikimedia.org/wiki/Special:FilePath/Adolf%20Karel%20vader%20Petrus%20moeder%20Carolina%20Verriest%20in%201861.jpg
A27: http://www.wikidata.org/entity/Q116687284 | B27: Agnes Mary Christophers | C27: http://www.wikidata.org/entity/Q3589290 | D27: briefschrijver | E27: Persoon naar Guido | F27: https://www.wikidata.org/wiki/Q116687284
A28: http://www.wikidata.org/entity/Q118772822 | B28: Albert Aimé Marie Vandewalle | C28: http://www.wikidata.org/entity/Q3589290 | D28: briefschrijver | E28: Persoon naar Guido | F28: https://www.wikidata.org/wiki/Q118772822
A29: http://www.wikidata.org/entity/Q586323 | B29: Albert Verwey | C29: http://www.wikidata.org/entity/Q3589290 | D29: briefschrijver | E29: Persoon naar Guido | F29: https://www.wikidata.org/wiki/Q586323 | G29: https://nl.wikipedia.org/wiki/Albert_Verwey | H29: https://commons.wikimedia.org/wiki/Category:Albert Verwey | I29: http://commons.wikimedia.org/wiki/Special:FilePath/Portret%20van%20Albert%20Verwey%20Rijksmuseum%20SK-C-1680.jpeg | K29: https://viaf.org/viaf/49275816
A30: http://www.wikidata.org/entity/Q2832059 | B30: Albéric Emmanuel Henri Marie Ghislain Ruzette | C30: http://www.wikidata.org/entity/Q3589290 | D30: briefschrijver | E30: Persoon naar Guido | F30: https://www.wikidata.org/wiki/Q2832059 | G30: https://nl.wikipedia.org/wiki/Alb%C3%A9ric_Ruzette | H30: https://commons.wikimedia.org/wiki/Category:Albéric Ruzette | I30: http://commons.wikimedia.org/wiki/Special:FilePath/Weekblad%20Pallieter%20-%20voorpagina%201924%2023%20baron%20ruzette.jpg
A31: http://www.wikidata.org/entity/Q56036018 | B31: Alexandre Bonvarlet | C31: http://www.wikidata.org/entity/Q3589290 | D31: briefschrijver | E31: Persoon naar Guido | F31: https://www.wikidata.org/wiki/Q56036018 | H31: https://commons.wikimedia.org/wiki/Category:Alexandre Bonvarlet | I31: http://commons.wikimedia.org/wiki/Special:FilePath/Alexandre%20Bonvarlet%20by%20Michel%20Berthaud.jpg | K31: https://viaf.org/viaf/7516908
A32: http://www.wikidata.org/entity/Q118142378 | B32: Alfons Bouckaert | C32: http://www.wikidata.org/entity/Q3589290 | D32: briefschrijver | E32: Persoon naar Guido | F32: https://www.wikidata.org/wiki/Q118142378
A33: http://www.wikidata.org/entity/Q110039191 | B33: Alfons Dassonville | C33: http://www.wikidata.org/entity/Q3589290 | D33: briefschrijver | E33: Persoon naar Guido | F33: https://www.wikidata.org/wiki/Q110039191
A34: http://www.wikidata.org/entity/Q2100582 | B34: Alfons De Cock | C34: http://www.wikidata.org/entity/Q3589290 | D34: briefschrijver | E34: Persoon naar Guido | F34: https://www.wikidata.org/wiki/Q2100582 | G34: https://nl.wikipedia.org/wiki/Alfons_de_Cock | H34: https://commons.wikimedia.org/wiki/Category:Alfons De Cock | I34: http://commons.wikimedia.org/wiki/Special:FilePath/Alfons%20de%20Cock%2C%20PA05233.jpg | K34: https://viaf.org/viaf/34816409
A35: http://www.wikidata.org/entity/Q2638823 | B35: Alfons Janssens | C35: http://www.wikidata.org/entity/Q3589290 | D35: briefschrijver | E35: Persoon naar Guido | F35: https://www.wikidata.org/wiki/Q2638823 | G35: https://nl.wikipedia.org/wiki/Alfons_Janssens_(politicus) | H35: https://commons.wikimedia.org/wiki/Category:Alfons Janssens | I35: http://commons.wikimedia.org/wiki/Special:FilePath/Alfons%20Janssens.jpg
A36: http://www.wikidata.org/entity/Q56036059 | B36: Alfons Maria Napoleon Prayon-van Zuylen van Nyevelt | C36: http://www.wikidata.org/entity/Q3589290 | D36: briefschrijver | E36: Persoon naar Guido | F36: https://www.wikidata.org/wiki/Q56036059 | K36: https://viaf.org/viaf/89687993
