Workbook

Sheet RawV3Q1
A1: lid | B1: lidLabel | C1: beroep | D1: beroepLabel | E1: imageLink
A2: http://www.wikidata.org/entity/Q3166510 | B2: Johan Joseph Faict | C2: http://www.wikidata.org/entity/Q1044528 | D2: vicaris-generaal | E2: http://commons.wikimedia.org/wiki/Special:FilePath/Brugge%20-%20Bisschop%20Faict%20%281864-1894%29%20-%20Brugge%20-%20Belgi%C3%AB.jpg
A3: http://www.wikidata.org/entity/Q378133 | B3: Hendrik Conscience | C3: http://www.wikidata.org/entity/Q82955 | D3: politicus | E3: http://commons.wikimedia.org/wiki/Special:FilePath/Hendrik%20Conscience.jpg
A4: http://www.wikidata.org/entity/Q672816 | B4: Nicholas Wiseman | C4: http://www.wikidata.org/entity/Q25393460 | D4: katholieke diaken | E4: http://commons.wikimedia.org/wiki/Special:FilePath/Wiseman.jpg
A5: http://www.wikidata.org/entity/Q1334711 | B5: Emmanuel Hiel | C5: http://www.wikidata.org/entity/Q36180 | D5: schrijver | E5: http://commons.wikimedia.org/wiki/Special:FilePath/Hiel%2C%20Emmanuel%20%281834-1899%29%3B%20dichter%20en%20schrijver%2C%20Nauwens%2C%20Joseph%2C%20Felixarchief%2C%2012%2012840.jpg
A6: http://www.wikidata.org/entity/Q1334711 | B6: Emmanuel Hiel | C6: http://www.wikidata.org/entity/Q49757 | D6: dichter | E6: http://commons.wikimedia.org/wiki/Special:FilePath/Hiel%2C%20Emmanuel%20%281834-1899%29%3B%20dichter%20en%20schrijver%2C%20Nauwens%2C%20Joseph%2C%20Felixarchief%2C%2012%2012840.jpg
A7: http://www.wikidata.org/entity/Q175669 | B7: Stijn Streuvels | C7: http://www.wikidata.org/entity/Q28389 | D7: scenarioschrijver | E7: http://commons.wikimedia.org/wiki/Special:FilePath/Stijn%20Streuvels%20by%20Modest%20Huys.jpg
A8: http://www.wikidata.org/entity/Q175669 | B8: Stijn Streuvels | C8: http://www.wikidata.org/entity/Q28389 | D8: scenarioschrijver | E8: http://commons.wikimedia.org/wiki/Special:FilePath/Stijn%20Streuvels%20by%20Modest%20Huys%20%28cropped%29.jpg
A9: http://www.wikidata.org/entity/Q4902927 | B9: Edmond Van Hee | C9: http://www.wikidata.org/entity/Q82955 | D9: politicus
A10: http://www.wikidata.org/entity/Q4902927 | B10: Edmond Van Hee | C10: http://www.wikidata.org/entity/Q333634 | D10: vertaler
A11: http://www.wikidata.org/entity/Q175669 | B11: Stijn Streuvels | C11: http://www.wikidata.org/entity/Q33231 | D11: fotograaf | E11: http://commons.wikimedia.org/wiki/Special:FilePath/Stijn%20Streuvels%20by%20Modest%20Huys.jpg
A12: http://www.wikidata.org/entity/Q175669 | B12: Stijn Streuvels | C12: http://www.wikidata.org/entity/Q33231 | D12: fotograaf | E12: http://commons.wikimedia.org/wiki/Special:FilePath/Stijn%20Streuvels%20by%20Modest%20Huys%20%28cropped%29.jpg
A13: http://www.wikidata.org/entity/Q2619202 | B13: Leopold Slosse | C13: http://www.wikidata.org/entity/Q955464 | D13: pastoor
A14: http://www.wikidata.org/entity/Q2619202 | B14: Leopold Slosse | C14: http://www.wikidata.org/entity/Q250867 | D14: katholiek priester
A15: http://www.wikidata.org/entity/Q2298746 | B15: Aloïs Walgrave | C15: http://www.wikidata.org/entity/Q955464 | D15: pastoor
A16: http://www.wikidata.org/entity/Q2619202 | B16: Leopold Slosse | C16: http://www.wikidata.org/entity/Q3243461 | D16: verzamelaar
A17: http://www.wikidata.org/entity/Q2619202 | B17: Leopold Slosse | C17: http://www.wikidata.org/entity/Q2251335 | D17: leerkracht
A18: http://www.wikidata.org/entity/Q2191260 | B18: Gustave Waffelaert | C18: http://www.wikidata.org/entity/Q114371470 | D18: coadjutor | E18: http://commons.wikimedia.org/wiki/Special:FilePath/Gustaaf%20Jozef%20Waffelaert%20-%2022ste%20bisschop%20van%20Brugge%20-%20Belgi%C3%AB.jpg
A19: http://www.wikidata.org/entity/Q2298746 | B19: Aloïs Walgrave | C19: http://www.wikidata.org/entity/Q2251335 | D19: leerkracht
A20: http://www.wikidata.org/entity/Q672816 | B20: Nicholas Wiseman | C20: http://www.wikidata.org/entity/Q611644 | D20: katholiek bisschop | E20: http://commons.wikimedia.org/wiki/Special:FilePath/Wiseman.jpg
A21: http://www.wikidata.org/entity/Q6242432 | B21: Pieter Willems | C21: http://www.wikidata.org/entity/Q13418253 | D21: filoloog | E21: http://commons.wikimedia.org/wiki/Special:FilePath/PieterWillems.png
A22: http://www.wikidata.org/entity/Q175669 | B22: Stijn Streuvels | C22: http://www.wikidata.org/entity/Q107212688 | D22: exlibrist | E22: http://commons.wikimedia.org/wiki/Special:FilePath/Stijn%20Streuvels%20by%20Modest%20Huys.jpg
A23: http://www.wikidata.org/entity/Q175669 | B23: Stijn Streuvels | C23: http://www.wikidata.org/entity/Q107212688 | D23: exlibrist | E23: http://commons.wikimedia.org/wiki/Special:FilePath/Stijn%20Streuvels%20by%20Modest%20Huys%20%28cropped%29.jpg
A24: http://www.wikidata.org/entity/Q2619202 | B24: Leopold Slosse | C24: http://www.wikidata.org/entity/Q1595570 | D24: heemkundige
A25: http://www.wikidata.org/entity/Q2087117 | B25: René Vermandere | C25: http://www.wikidata.org/entity/Q36180 | D25: schrijver
A26: http://www.wikidata.org/entity/Q2087117 | B26: René Vermandere | C26: http://www.wikidata.org/entity/Q49757 | D26: dichter
A27: http://www.wikidata.org/entity/Q672816 | B27: Nicholas Wiseman | C27: http://www.wikidata.org/entity/Q250867 | D27: katholiek priester | E27: http://commons.wikimedia.org/wiki/Special:FilePath/Wiseman.jpg
A28: http://www.wikidata.org/entity/Q2619202 | B28: Leopold Slosse | C28: http://www.wikidata.org/entity/Q1753370 | D28: parochievicaris
A29: http://www.wikidata.org/entity/Q3163681 | B29: Jean-Aloys Van Steenkiste | C29: http://www.wikidata.org/entity/Q955464 | D29: pastoor
A30: http://www.wikidata.org/entity/Q378133 | B30: Hendrik Conscience | C30: http://www.wikidata.org/entity/Q36180 | D30: schrijver | E30: http://commons.wikimedia.org/wiki/Special:FilePath/Hendrik%20Conscience.jpg
A31: http://www.wikidata.org/entity/Q6242432 | B31: Pieter Willems | C31: http://www.wikidata.org/entity/Q16267607 | D31: klassiek filoloog | E31: http://commons.wikimedia.org/wiki/Special:FilePath/PieterWillems.png
A32: http://www.wikidata.org/entity/Q378133 | B32: Hendrik Conscience | C32: http://www.wikidata.org/entity/Q49757 | D32: dichter | E32: http://commons.wikimedia.org/wiki/Special:FilePath/Hendrik%20Conscience.jpg
A33: http://www.wikidata.org/entity/Q378133 | B33: Hendrik Conscience | C33: http://www.wikidata.org/entity/Q47064 | D33: militair | E33: http://commons.wikimedia.org/wiki/Special:FilePath/Hendrik%20Conscience.jpg
A34: http://www.wikidata.org/entity/Q3163681 | B34: Jean-Aloys Van Steenkiste | C34: http://www.wikidata.org/entity/Q250867 | D34: katholiek priester
A35: http://www.wikidata.org/entity/Q6242432 | B35: Pieter Willems | C35: http://www.wikidata.org/entity/Q201788 | D35: historicus | E35: http://commons.wikimedia.org/wiki/Special:FilePath/PieterWillems.png
A36: http://www.wikidata.org/entity/Q3163681 | B36: Jean-Aloys Van Steenkiste | C36: http://www.wikidata.org/entity/Q1622272 | D36: academisch docent
A37: http://www.wikidata.org/entity/Q1796639 | B37: Rafaël Verhulst | C37: http://www.wikidata.org/entity/Q82955 | D37: politicus | E37: http://commons.wikimedia.org/wiki/Special:FilePath/Raf%20Verhulst.jpg
A38: http://www.wikidata.org/entity/Q672816 | B38: Nicholas Wiseman | C38: http://www.wikidata.org/entity/Q36180 | D38: schrijver | E38: http://commons.wikimedia.org/wiki/Special:FilePath/Wiseman.jpg
A39: http://www.wikidata.org/entity/Q2191260 | B39: Gustave Waffelaert | C39: http://www.wikidata.org/entity/Q1162163 | D39: directeur | E39: http://commons.wikimedia.org/wiki/Special:FilePath/Gustaaf%20Jozef%20Waffelaert%20-%2022ste%20bisschop%20van%20Brugge%20-%20Belgi%C3%AB.jpg
A40: http://www.wikidata.org/entity/Q3163681 | B40: Jean-Aloys Van Steenkiste | C40: http://www.wikidata.org/entity/Q4958876 | D40: deken
...

Sheet Kopie van RawV3Q1
A1: lid | B1: lidLabel | C1: beroep | D1: beroepLabel | E1: imageLink | F1: Unieke namen | G1: Samengevoegde Jobs
A2: http://www.wikidata.org/entity/Q3166510 | B2: Johan Joseph Faict | C2: http://www.wikidata.org/entity/Q1044528 | D2: vicaris-generaal | E2: http://commons.wikimedia.org/wiki/Special:FilePath/Brugge%20-%20Bisschop%20Faict%20%281864-1894%29%20-%20Brugge%20-%20Belgi%C3%AB.jpg | F2: {=UNIQUE(B:B)} -> lidLabel | G2: nvt
A3: http://www.wikidata.org/entity/Q378133 | B3: Hendrik Conscience | C3: http://www.wikidata.org/entity/Q82955 | D3: politicus | E3: http://commons.wikimedia.org/wiki/Special:FilePath/Hendrik%20Conscience.jpg | F3: Johan Joseph Faict | G3: =IFERROR(__xludf.DUMMYFUNCTION("JOIN("", "", FILTER($D2:D1989, $B2:B1989 = F3))"),"vicaris-generaal, katholieke diaken, kanunnik, katholiek bisschop, rector, katholiek priester, geestelijk leidsman, academisch docent, theoloog") -> vicaris-generaal, katholieke diaken, kanunnik, katholiek bisschop, rector, katholiek priester, geestelijk leidsman, academisch docent, theoloog
A4: http://www.wikidata.org/entity/Q672816 | B4: Nicholas Wiseman | C4: http://www.wikidata.org/entity/Q25393460 | D4: katholieke diaken | E4: http://commons.wikimedia.org/wiki/Special:FilePath/Wiseman.jpg | F4: Hendrik Conscience | G4: =IFERROR(__xludf.DUMMYFUNCTION("JOIN("", "", FILTER($D3:D1989, $B3:B1989 = F4))"),"politicus, schrijver, dichter, militair") -> politicus, schrijver, dichter, militair
A5: http://www.wikidata.org/entity/Q1334711 | B5: Emmanuel Hiel | C5: http://www.wikidata.org/entity/Q36180 | D5: schrijver | E5: http://commons.wikimedia.org/wiki/Special:FilePath/Hiel%2C%20Emmanuel%20%281834-1899%29%3B%20dichter%20en%20schrijver%2C%20Nauwens%2C%20Joseph%2C%20Felixarchief%2C%2012%2012840.jpg | F5: Nicholas Wiseman | G5: =IFERROR(__xludf.DUMMYFUNCTION("JOIN("", "", FILTER($D4:D1989, $B4:B1989 = F5))"),"katholieke diaken, katholiek bisschop, katholiek priester, schrijver, romanschrijver") -> katholieke diaken, katholiek bisschop, katholiek priester, schrijver, romanschrijver
A6: http://www.wikidata.org/entity/Q1334711 | B6: Emmanuel Hiel | C6: http://www.wikidata.org/entity/Q49757 | D6: dichter | E6: http://commons.wikimedia.org/wiki/Special:FilePath/Hiel%2C%20Emmanuel%20%281834-1899%29%3B%20dichter%20en%20schrijver%2C%20Nauwens%2C%20Joseph%2C%20Felixarchief%2C%2012%2012840.jpg | F6: Emmanuel Hiel | G6: =IFERROR(__xludf.DUMMYFUNCTION("JOIN("", "", FILTER($D5:D1989, $B5:B1989 = F6))"),"schrijver, dichter, ambtenaar, douanebeambte, politicus") -> schrijver, dichter, ambtenaar, douanebeambte, politicus
A7: http://www.wikidata.org/entity/Q175669 | B7: Stijn Streuvels | C7: http://www.wikidata.org/entity/Q28389 | D7: scenarioschrijver | E7: http://commons.wikimedia.org/wiki/Special:FilePath/Stijn%20Streuvels%20by%20Modest%20Huys.jpg | F7: Stijn Streuvels | G7: =IFERROR(__xludf.DUMMYFUNCTION("JOIN("", "", FILTER($D6:D1989, $B6:B1989 = F7))"),"scenarioschrijver, fotograaf, exlibrist, bakker, vertaler, schrijver") -> scenarioschrijver, fotograaf, exlibrist, bakker, vertaler, schrijver
A8: http://www.wikidata.org/entity/Q4902927 | B8: Edmond Van Hee | C8: http://www.wikidata.org/entity/Q82955 | D8: politicus | F8: Edmond Van Hee | G8: =IFERROR(__xludf.DUMMYFUNCTION("JOIN("", "", FILTER($D7:D1989, $B7:B1989 = F8))"),"politicus, vertaler, advocaat, dichter") -> politicus, vertaler, advocaat, dichter
A9: http://www.wikidata.org/entity/Q4902927 | B9: Edmond Van Hee | C9: http://www.wikidata.org/entity/Q333634 | D9: vertaler | F9: Leopold Slosse | G9: =IFERROR(__xludf.DUMMYFUNCTION("JOIN("", "", FILTER($D8:D1989, $B8:B1989 = F9))"),"pastoor, katholiek priester, verzamelaar, leerkracht, heemkundige, parochievicaris") -> pastoor, katholiek priester, verzamelaar, leerkracht, heemkundige, parochievicaris
A10: http://www.wikidata.org/entity/Q175669 | B10: Stijn Streuvels | C10: http://www.wikidata.org/entity/Q33231 | D10: fotograaf | E10: http://commons.wikimedia.org/wiki/Special:FilePath/Stijn%20Streuvels%20by%20Modest%20Huys.jpg | F10: Aloïs Walgrave | G10: =IFERROR(__xludf.DUMMYFUNCTION("JOIN("", "", FILTER($D9:D1989, $B9:B1989 = F10))"),"pastoor, leerkracht, schrijver, dichter, priester") -> pastoor, leerkracht, schrijver, dichter, priester
A11: http://www.wikidata.org/entity/Q2619202 | B11: Leopold Slosse | C11: http://www.wikidata.org/entity/Q955464 | D11: pastoor | F11: Gustave Waffelaert | G11: =IFERROR(__xludf.DUMMYFUNCTION("JOIN("", "", FILTER($D10:D1989, $B10:B1989 = F11))"),"coadjutor, directeur, kanunnik, katholiek bisschop, parochievicaris, katholiek priester, schrijver, academisch docent, theoloog, vicaris-generaal") -> coadjutor, directeur, kanunnik, katholiek bisschop, parochievicaris, katholiek priester, schrijver, academisch docent, theoloog, vicaris-generaal
A12: http://www.wikidata.org/entity/Q2619202 | B12: Leopold Slosse | C12: http://www.wikidata.org/entity/Q250867 | D12: katholiek priester | F12: Pieter Willems | G12: =IFERROR(__xludf.DUMMYFUNCTION("JOIN("", "", FILTER($D11:D1989, $B11:B1989 = F12))"),"filoloog, klassiek filoloog, historicus, dialectoloog") -> filoloog, klassiek filoloog, historicus, dialectoloog
A13: http://www.wikidata.org/entity/Q2298746 | B13: Aloïs Walgrave | C13: http://www.wikidata.org/entity/Q955464 | D13: pastoor | F13: René Vermandere | G13: =IFERROR(__xludf.DUMMYFUNCTION("JOIN("", "", FILTER($D12:D1989, $B12:B1989 = F13))"),"schrijver, dichter, toneelschrijver, verkoper, uitgever, boekhandelaar, verzekeringsmakelaar") -> schrijver, dichter, toneelschrijver, verkoper, uitgever, boekhandelaar, verzekeringsmakelaar
A14: http://www.wikidata.org/entity/Q2619202 | B14: Leopold Slosse | C14: http://www.wikidata.org/entity/Q3243461 | D14: verzamelaar | F14: Jean-Aloys Van Steenkiste | G14: =IFERROR(__xludf.DUMMYFUNCTION("JOIN("", "", FILTER($D13:D1989, $B13:B1989 = F14))"),"pastoor, katholiek priester, academisch docent, deken, aalmoezenier, parochievicaris") -> pastoor, katholiek priester, academisch docent, deken, aalmoezenier, parochievicaris
A15: http://www.wikidata.org/entity/Q2619202 | B15: Leopold Slosse | C15: http://www.wikidata.org/entity/Q2251335 | D15: leerkracht | F15: Rafaël Verhulst | G15: =IFERROR(__xludf.DUMMYFUNCTION("JOIN("", "", FILTER($D14:D1989, $B14:B1989 = F15))"),"politicus, schrijver") -> politicus, schrijver
A16: http://www.wikidata.org/entity/Q2191260 | B16: Gustave Waffelaert | C16: http://www.wikidata.org/entity/Q114371470 | D16: coadjutor | E16: http://commons.wikimedia.org/wiki/Special:FilePath/Gustaaf%20Jozef%20Waffelaert%20-%2022ste%20bisschop%20van%20Brugge%20-%20Belgi%C3%AB.jpg | F16: Albert Verwey | G16: =IFERROR(__xludf.DUMMYFUNCTION("JOIN("", "", FILTER($D15:D1989, $B15:B1989 = F16))"),"vertaler, literatuurcriticus, schrijver, dichter, academisch docent") -> vertaler, literatuurcriticus, schrijver, dichter, academisch docent
A17: http://www.wikidata.org/entity/Q2298746 | B17: Aloïs Walgrave | C17: http://www.wikidata.org/entity/Q2251335 | D17: leerkracht | F17: Edward Van Even | G17: =IFERROR(__xludf.DUMMYFUNCTION("JOIN("", "", FILTER($D16:D1989, $B16:B1989 = F17))"),"bibliothecaris, historicus, kunstverzamelaar, letterkundige, archivaris") -> bibliothecaris, historicus, kunstverzamelaar, letterkundige, archivaris
A18: http://www.wikidata.org/entity/Q672816 | B18: Nicholas Wiseman | C18: http://www.wikidata.org/entity/Q611644 | D18: katholiek bisschop | E18: http://commons.wikimedia.org/wiki/Special:FilePath/Wiseman.jpg | F18: Constant Hansen | G18: =IFERROR(__xludf.DUMMYFUNCTION("JOIN("", "", FILTER($D17:D1989, $B17:B1989 = F18))"),"politicus, bibliothecaris, leerkracht, vertaler, archivaris, boekhouder, journalist, schrijver") -> politicus, bibliothecaris, leerkracht, vertaler, archivaris, boekhouder, journalist, schrijver
A19: http://www.wikidata.org/entity/Q6242432 | B19: Pieter Willems | C19: http://www.wikidata.org/entity/Q13418253 | D19: filoloog | E19: http://commons.wikimedia.org/wiki/Special:FilePath/PieterWillems.png | F19: Charles Carton | G19: =IFERROR(__xludf.DUMMYFUNCTION("JOIN("", "", FILTER($D18:D1989, $B18:B1989 = F19))"),"coadjutor, directeur, historicus, kapelaan, katholiek priester") -> coadjutor, directeur, historicus, kapelaan, katholiek priester
A20: http://www.wikidata.org/entity/Q175669 | B20: Stijn Streuvels | C20: http://www.wikidata.org/entity/Q107212688 | D20: exlibrist | E20: http://commons.wikimedia.org/wiki/Special:FilePath/Stijn%20Streuvels%20by%20Modest%20Huys.jpg | F20: Charles van Caloen | G20: =IFERROR(__xludf.DUMMYFUNCTION("JOIN("", "", FILTER($D19:D1989, $B19:B1989 = F20))"),"politicus") -> politicus
A21: http://www.wikidata.org/entity/Q2619202 | B21: Leopold Slosse | C21: http://www.wikidata.org/entity/Q1595570 | D21: heemkundige | F21: William Henry James Weale | G21: =IFERROR(__xludf.DUMMYFUNCTION("JOIN("", "", FILTER($D20:D1989, $B20:B1989 = F21))"),"onderwijzer, kunsthistoricus, vertegenwoordiger, museummedewerker, ambtenaar, importeur, conservator, curator") -> onderwijzer, kunsthistoricus, vertegenwoordiger, museummedewerker, ambtenaar, importeur, conservator, curator
A22: http://www.wikidata.org/entity/Q2087117 | B22: René Vermandere | C22: http://www.wikidata.org/entity/Q36180 | D22: schrijver | F22: Joaquim Rubió i Ors | G22: =IFERROR(__xludf.DUMMYFUNCTION("JOIN("", "", FILTER($D21:D1989, $B21:B1989 = F22))"),"schrijver, dichter, academisch docent, historicus, senior lecturer") -> schrijver, dichter, academisch docent, historicus, senior lecturer
A23: http://www.wikidata.org/entity/Q2087117 | B23: René Vermandere | C23: http://www.wikidata.org/entity/Q49757 | D23: dichter | F23: Ferdinand Van de Putte | G23: =IFERROR(__xludf.DUMMYFUNCTION("JOIN("", "", FILTER($D22:D1989, $B22:B1989 = F23))"),"pastoor, historicus, leerkracht, rector, katholiek priester, pastoor-deken, schrijver") -> pastoor, historicus, leerkracht, rector, katholiek priester, pastoor-deken, schrijver
A24: http://www.wikidata.org/entity/Q672816 | B24: Nicholas Wiseman | C24: http://www.wikidata.org/entity/Q250867 | D24: katholiek priester | E24: http://commons.wikimedia.org/wiki/Special:FilePath/Wiseman.jpg | F24: Hendrik Kern | G24: =IFERROR(__xludf.DUMMYFUNCTION("JOIN("", "", FILTER($D23:D1989, $B23:B1989 = F24))"),"professor, archeoloog, leerkracht, vertaler, taalkundige, academisch docent, oriëntalist") -> professor, archeoloog, leerkracht, vertaler, taalkundige, academisch docent, oriëntalist
A25: http://www.wikidata.org/entity/Q2619202 | B25: Leopold Slosse | C25: http://www.wikidata.org/entity/Q1753370 | D25: parochievicaris | F25: Philippe Van der Haeghen | G25: =IFERROR(__xludf.DUMMYFUNCTION("JOIN("", "", FILTER($D24:D1989, $B24:B1989 = F25))"),"filoloog, commentator, ambtenaar, bibliothecaris, historicus") -> filoloog, commentator, ambtenaar, bibliothecaris, historicus
A26: http://www.wikidata.org/entity/Q3163681 | B26: Jean-Aloys Van Steenkiste | C26: http://www.wikidata.org/entity/Q955464 | D26: pastoor | F26: Karel de Gheldere | G26: =IFERROR(__xludf.DUMMYFUNCTION("JOIN("", "", FILTER($D25:D1989, $B25:B1989 = F26))"),"arts, dichter") -> arts, dichter
A27: http://www.wikidata.org/entity/Q378133 | B27: Hendrik Conscience | C27: http://www.wikidata.org/entity/Q36180 | D27: schrijver | E27: http://commons.wikimedia.org/wiki/Special:FilePath/Hendrik%20Conscience.jpg | F27: Pieter Lansens | G27: =IFERROR(__xludf.DUMMYFUNCTION("JOIN("", "", FILTER($D26:D1989, $B26:B1989 = F27))"),"rector, schrijver, onderwijzer, historicus") -> rector, schrijver, onderwijzer, historicus
A28: http://www.wikidata.org/entity/Q6242432 | B28: Pieter Willems | C28: http://www.wikidata.org/entity/Q16267607 | D28: klassiek filoloog | E28: http://commons.wikimedia.org/wiki/Special:FilePath/PieterWillems.png | F28: François Van den Abeele | G28: =IFERROR(__xludf.DUMMYFUNCTION("JOIN("", "", FILTER($D27:D1989, $B27:B1989 = F28))"),"politicus, arts") -> politicus, arts
A29: http://www.wikidata.org/entity/Q378133 | B29: Hendrik Conscience | C29: http://www.wikidata.org/entity/Q49757 | D29: dichter | E29: http://commons.wikimedia.org/wiki/Special:FilePath/Hendrik%20Conscience.jpg | F29: Edmond Van der Straeten | G29: =IFERROR(__xludf.DUMMYFUNCTION("JOIN("", "", FILTER($D28:D1989, $B28:B1989 = F29))"),"jurist, schrijver, musicoloog, restaurator, ambtenaar") -> jurist, schrijver, musicoloog, restaurator, ambtenaar
A30: http://www.wikidata.org/entity/Q378133 | B30: Hendrik Conscience | C30: http://www.wikidata.org/entity/Q47064 | D30: militair | E30: http://commons.wikimedia.org/wiki/Special:FilePath/Hendrik%20Conscience.jpg | F30: Hendrik Sermon | G30: =IFERROR(__xludf.DUMMYFUNCTION("JOIN("", "", FILTER($D29:D1989, $B29:B1989 = F30))"),"schrijver, politicus, leerkracht, boekhandelaar") -> schrijver, politicus, leerkracht, boekhandelaar
A31: http://www.wikidata.org/entity/Q3163681 | B31: Jean-Aloys Van Steenkiste | C31: http://www.wikidata.org/entity/Q250867 | D31: katholiek priester | F31: Joseph Van den Gheyn | G31: =IFERROR(__xludf.DUMMYFUNCTION("JOIN("", "", FILTER($D30:D1989, $B30:B1989 = F31))"),"hagiograaf, bibliothecaris, pater, antropoloog") -> hagiograaf, bibliothecaris, pater, antropoloog
A32: http://www.wikidata.org/entity/Q6242432 | B32: Pieter Willems | C32: http://www.wikidata.org/entity/Q201788 | D32: historicus | E32: http://commons.wikimedia.org/wiki/Special:FilePath/PieterWillems.png | F32: Johannes Franck | G32: =IFERROR(__xludf.DUMMYFUNCTION("JOIN("", "", FILTER($D31:D1989, $B31:B1989 = F32))"),"schrijver, germanist, privaatdocent, filoloog") -> schrijver, germanist, privaatdocent, filoloog
A33: http://www.wikidata.org/entity/Q3163681 | B33: Jean-Aloys Van Steenkiste | C33: http://www.wikidata.org/entity/Q1622272 | D33: academisch docent | F33: Aloïs Nelis | G33: =IFERROR(__xludf.DUMMYFUNCTION("JOIN("", "", FILTER($D32:D1989, $B32:B1989 = F33))"),"schrijver, bibliothecaris, historicus, rector, leerkracht, letterkundige") -> schrijver, bibliothecaris, historicus, rector, leerkracht, letterkundige
A34: http://www.wikidata.org/entity/Q1796639 | B34: Rafaël Verhulst | C34: http://www.wikidata.org/entity/Q82955 | D34: politicus | E34: http://commons.wikimedia.org/wiki/Special:FilePath/Raf%20Verhulst.jpg | F34: Alphonse De Leyn | G34: =IFERROR(__xludf.DUMMYFUNCTION("JOIN("", "", FILTER($D33:D1989, $B33:B1989 = F34))"),"directeur, historicus, rector, katholiek priester, leerkracht, inspecteur") -> directeur, historicus, rector, katholiek priester, leerkracht, inspecteur
A35: http://www.wikidata.org/entity/Q672816 | B35: Nicholas Wiseman | C35: http://www.wikidata.org/entity/Q36180 | D35: schrijver | E35: http://commons.wikimedia.org/wiki/Special:FilePath/Wiseman.jpg | F35: Edward De Gryse | G35: =IFERROR(__xludf.DUMMYFUNCTION("JOIN("", "", FILTER($D34:D1989, $B34:B1989 = F35))"),"deken, leerkracht, katholiek priester, pastoor-deken, academisch docent") -> deken, leerkracht, katholiek priester, pastoor-deken, academisch docent
A36: http://www.wikidata.org/entity/Q2191260 | B36: Gustave Waffelaert | C36: http://www.wikidata.org/entity/Q1162163 | D36: directeur | E36: http://commons.wikimedia.org/wiki/Special:FilePath/Gustaaf%20Jozef%20Waffelaert%20-%2022ste%20bisschop%20van%20Brugge%20-%20Belgi%C3%AB.jpg | F36: Pieter Génard | G36: =IFERROR(__xludf.DUMMYFUNCTION("JOIN("", "", FILTER($D35:D1989, $B35:B1989 = F36))"),"biograaf, ambtenaar, politicus, bibliothecaris, historicus, archivaris") -> biograaf, ambtenaar, politicus, bibliothecaris, historicus, archivaris
A37: http://www.wikidata.org/entity/Q3163681 | B37: Jean-Aloys Van Steenkiste | C37: http://www.wikidata.org/entity/Q4958876 | D37: deken | F37: Jeroom Noterdaeme | G37: =IFERROR(__xludf.DUMMYFUNCTION("JOIN("", "", FILTER($D36:D1989, $B36:B1989 = F37))"),"ambtenaar, directeur, dichter") -> ambtenaar, directeur, dichter
A38: http://www.wikidata.org/entity/Q6242432 | B38: Pieter Willems | C38: http://www.wikidata.org/entity/Q16880249 | D38: dialectoloog | E38: http://commons.wikimedia.org/wiki/Special:FilePath/PieterWillems.png | F38: Alphonse de Voss | G38: =IFERROR(__xludf.DUMMYFUNCTION("JOIN("", "", FILTER($D37:D1989, $B37:B1989 = F38))"),"pastoor, katholiek bisschop, missionaris, katholiek priester, pater") -> pastoor, katholiek bisschop, missionaris, katholiek priester, pater
A39: http://www.wikidata.org/entity/Q2191260 | B39: Gustave Waffelaert | C39: http://www.wikidata.org/entity/Q1104153 | D39: kanunnik | E39: http://commons.wikimedia.org/wiki/Special:FilePath/Gustaaf%20Jozef%20Waffelaert%20-%2022ste%20bisschop%20van%20Brugge%20-%20Belgi%C3%AB.jpg | F39: Willem Lodewijk van Helten | G39: =IFERROR(__xludf.DUMMYFUNCTION("JOIN("", "", FILTER($D38:D1989, $B38:B1989 = F39))"),"filoloog, leerkracht, taalkundige, academisch docent") -> filoloog, leerkracht, taalkundige, academisch docent
A40: http://www.wikidata.org/entity/Q3163681 | B40: Jean-Aloys Van Steenkiste | C40: http://www.wikidata.org/entity/Q1657500 | D40: aalmoezenier | F40: Lodewijk Van Haecke | G40: =IFERROR(__xludf.DUMMYFUNCTION("JOIN("", "", FILTER($D39:D1989, $B39:B1989 = F40))"),"leerkracht, kapelaan, katholiek priester, schrijver") -> leerkracht, kapelaan, katholiek priester, schrijver
...

Sheet RawV3Q2
A1: person | B1: personLabel | C1: institution | D1: institutionLabel | E1: institutionTypeLabel
A2: http://www.wikidata.org/entity/Q115821474 | B2: Juliaan Fové | C2: http://www.wikidata.org/entity/Q118369334 | D2: Sint-Jozefscollege Tielt | E2: Werkgever
A3: http://www.wikidata.org/entity/Q115821474 | B3: Juliaan Fové | C3: http://www.wikidata.org/entity/Q118388831 | D3: Bisschoppelijk college Sint-Joseph | E3: Werkgever
A4: http://www.wikidata.org/entity/Q115820195 | B4: Joseph Axters | C4: http://www.wikidata.org/entity/Q1867263 | D4: Klein Seminarie Roeselare | E4: Werkgever
A5: http://www.wikidata.org/entity/Q115818849 | B5: Isidoor Hemeryck | C5: http://www.wikidata.org/entity/Q644789 | D5: Katholieke Universiteit te Leuven | E5: Werkgever
A6: http://www.wikidata.org/entity/Q115981938 | B6: Felix Degrendel | C6: http://www.wikidata.org/entity/Q1867263 | D6: Klein Seminarie Roeselare | E6: Onderwijsinstelling
A7: http://www.wikidata.org/entity/Q115818849 | B7: Isidoor Hemeryck | C7: http://www.wikidata.org/entity/Q120693890 | D7: Congregatie van de Zusters van Liefde, Leuven | E7: Werkgever
A8: http://www.wikidata.org/entity/Q115839088 | B8: August Laporta | C8: http://www.wikidata.org/entity/Q13744144 | D8: Klein Seminarie | E8: Onderwijsinstelling
A9: http://www.wikidata.org/entity/Q115821479 | B9: Honoré Cardoen | C9: http://www.wikidata.org/entity/Q1807289 | D9: Sint-Leocollege | E9: Werkgever
A10: http://www.wikidata.org/entity/Q115981938 | B10: Felix Degrendel | C10: http://www.wikidata.org/entity/Q119702334 | D10: Confraternity of the Blessed Sacrament | E10: Lid van
A11: http://www.wikidata.org/entity/Q115979140 | B11: Arsenius Dehulster | C11: http://www.wikidata.org/entity/Q118369361 | D11: Bisschoppelijk Sint-Bernarduscollege Nieuwpoort | E11: Werkgever
A12: http://www.wikidata.org/entity/Q115818849 | B12: Isidoor Hemeryck | C12: http://www.wikidata.org/entity/Q2124530 | D12: Justus Lipsiuscollege | E12: Werkgever
... A977: http://www.wikidata.org/entity/Q115836962 | B977: Edmond Soenen | C977: http://www.wikidata.org/entity/Q118369084 | D977: Gilde van Sinte Luitgaarde | E977: Lid van

Sheet Nodes
A1: ID | B1: Label | C1: Type | D1: Beroep | E1: Afbeelding
A2: Q2424814 | B2: Jan Baptist David | C2: Persoon | D2: =VLOOKUP(B2,'Kopie van RawV3Q1'!F:G,2,false) -> academisch docent, politicus, directeur, historicus, leerkracht, kanunnik, studiemeester, rector, taalkundige, katholiek priester | E2: http://commons.wikimedia.org/wiki/Special:FilePath/Jan%20Baptist%20David%20-%20lithograph%20by%20Louis%20Tuerlinckx.jpg
A3: Q55232762 | B3: Julius Obrie | C3: Persoon | D3: =VLOOKUP(B3,'Kopie van RawV3Q1'!F:G,2,false) -> academisch docent, magistraat, schrijver | E3: Geen afbeelding beschikbaar
A4: Q28973666 | B4: Lodewijk Roersch | C4: Persoon | D4: =VLOOKUP(B4,'Kopie van RawV3Q1'!F:G,2,false) -> academisch docent, leerkracht, filoloog | E4: Geen afbeelding beschikbaar
A5: Q13769746 | B5: Lodewijk Scharpé | C5: Persoon | D5: =VLOOKUP(B5,'Kopie van RawV3Q1'!F:G,2,false) -> academisch docent, professor, ambtenaar, politicus | E5: http://commons.wikimedia.org/wiki/Special:FilePath/GlasraamLodewijkScharpe.jpg
A6: Q51168899 | B6: Victor Lambrecht | C6: Persoon | D6: =VLOOKUP(B6,'Kopie van RawV3Q1'!F:G,2,false) -> activist, advocaat | E6: Geen afbeelding beschikbaar
A7: Q5580544 | B7: Adrianus Bogaers | C7: Persoon | D7: =VLOOKUP(B7,'Kopie van RawV3Q1'!F:G,2,false) -> advocaat, rechter, schrijver, dichter | E7: http://commons.wikimedia.org/wiki/Special:FilePath/Adrianus%20Bogaers.jpg
A8: Q115813025 | B8: Auguste de Laage de Bellefaye | C8: Persoon | D8: =VLOOKUP(B8,'Kopie van RawV3Q1'!F:G,2,false) -> advocaat | E8: Geen afbeelding beschikbaar
A9: Q56036023 | B9: Eugène Cortyl | C9: Persoon | D9: =VLOOKUP(B9,'Kopie van RawV3Q1'!F:G,2,false) -> advocaat | E9: Geen afbeelding beschikbaar
A10: Q15956 | B10: Frans Schollaert | C10: Persoon | D10: =VLOOKUP(B10,'Kopie van RawV3Q1'!F:G,2,false) -> advocaat, politicus | E10: http://commons.wikimedia.org/wiki/Special:FilePath/Frans%20Schollaert.jpg
A11: Q61506427 | B11: Joseph Herreboudt | C11: Persoon | D11: =VLOOKUP(B11,'Kopie van RawV3Q1'!F:G,2,false) -> advocaat, politicus | E11: Geen afbeelding beschikbaar
A12: Q721772 | B12: Jules Vandenpeereboom | C12: Persoon | D12: =VLOOKUP(B12,'Kopie van RawV3Q1'!F:G,2,false) -> advocaat, politicus | E12: http://commons.wikimedia.org/wiki/Special:FilePath/Jules%20van%20den%20Peereboom.jpg
A13: Q115818781 | B13: Leon Verwilghen | C13: Persoon | D13: =VLOOKUP(B13,'Kopie van RawV3Q1'!F:G,2,false) -> advocaat | E13: Geen afbeelding beschikbaar
... A615: Q116620896 | B615: Zulma De Bo | C615: Persoon | D615: =VLOOKUP(B615,'Kopie van RawV3Q1'!F:G,2,false) | E615: Geen afbeelding beschikbaar
A616: Q118369334 | B616: Sint-Jozefscollege Tielt | C616: Instituut | D616: Niet van toepassing
A617: Q118388831 | B617: Bisschoppelijk college Sint-Joseph | C617: Instituut | D617: Niet van toepassing
A618: Q1867263 | B618: Klein Seminarie Roeselare | C618: Instituut | D618: Niet van toepassing
A619: Q644789 | B619: Katholieke Universiteit te Leuven | C619: Instituut | D619: Niet van toepassing
A620: Q120693890 | B620: Congregatie van de Zusters van Liefde, Leuven | C620: Instituut | D620: Niet van toepassing
A621: Q13744144 | B621: Klein Seminarie | C621: Instituut | D621: Niet van toepassing
A622: Q1807289 | B622: Sint-Leocollege | C622: Instituut | D622: Niet van toepassing
A623: Q119702334 | B623: Confraternity of the Blessed Sacrament | C623: Instituut | D623: Niet van toepassing
A624: Q118369361 | B624: Bisschoppelijk Sint-Bernarduscollege Nieuwpoort | C624: Instituut | D624: Niet van toepassing
A625: Q2124530 | B625: Justus Lipsiuscollege | C625: Instituut | D625: Niet van toepassing
A626: Q15882061 | B626: Sint-Vincentiuscollege (Ieper) | C626: Instituut | D626: Niet van toepassing
A627: Q118369334 | B627: Sint-Jozefscollege Tielt | C627: Instituut | D627: Niet van toepassing
... A897: Q120330461 | B897: Congregatie van de Zusters van de Heilige Jozef, Oostende | C897: Instituut | D897: Niet van toepassing

Sheet Edges
A1: Source | B1: Target | C1: Type | D1: Weight | E1: Relatie Type
A2: Q100534520 | B2: Q1867263 | C2: Undirected | D2: 1 | E2: Onderwijsinstelling
A3: Q100534520 | B3: Q644789 | C3: Undirected | D3: 1 | E3: Onderwijsinstelling
A4: Q101627274 | B4: Q2985460 | C4: Undirected | D4: 1 | E4: Lid van
A5: Q101627274 | B5: Q119853947 | C5: Undirected | D5: 1 | E5: Werkgever
A6: Q101627274 | B6: Q118369334 | C6: Undirected | D6: 1 | E6: Werkgever
A7: Q110039159 | B7: Q118369334 | C7: Undirected | D7: 1 | E7: Onderwijsinstelling
A8: Q110039159 | B8: Q1867263 | C8: Undirected | D8: 1 | E8: Onderwijsinstelling
A9: Q110039159 | B9: Q2663876 | C9: Undirected | D9: 1 | E9: Werkgever
A10: Q110039159 | B10: Q2479554 | C10: Undirected | D10: 1 | E10: Onderwijsinstelling
A11: Q110039159 | B11: Q113951185 | C11: Undirected | D11: 1 | E11: Lid van
A12: Q110039159 | B12: Q644789 | C12: Undirected | D12: 1 | E12: Onderwijsinstelling
A13: Q110039159 | B13: Q50492927 | C13: Undirected | D13: 1 | E13: Lid van
... A977: Q98322098 | B977: Q2663876 | C977: Undirected | D977: 1 | E977: Werkgever
