Workbook

Sheet V5Q1
A1: source | B1: sourceLabel | C1: target | D1: targetLabel | E1: richtingBeschrijving | F1: rolLabel | G1: start | H1: eind | I1: punt
A2: http://www.wikidata.org/entity/Q119454376 | B2: t Daghet in den Oosten | C2: http://www.wikidata.org/entity/Q336977 | D2: Guido Gezelle | E2: Correspondent (Zender) → Guido (Ontvanger) | F2: medewerker
A3: http://www.wikidata.org/entity/Q115818424 | B3: Achiel Piepers | C3: http://www.wikidata.org/entity/Q336977 | D3: Guido Gezelle | E3: Correspondent (Zender) → Guido (Ontvanger) | F3: correspondent | I3: 1889-11-06T00:00:00Z
A4: http://www.wikidata.org/entity/Q119013873 | B4: Achiel Van de Putte | C4: http://www.wikidata.org/entity/Q336977 | D4: Guido Gezelle | E4: Correspondent (Zender) → Guido (Ontvanger) | F4: correspondent | I4: 1892-05-15T00:00:00Z
A5: http://www.wikidata.org/entity/Q119217729 | B5: Achille Croquison | C5: http://www.wikidata.org/entity/Q336977 | D5: Guido Gezelle | E5: Correspondent (Zender) → Guido (Ontvanger) | F5: correspondent | I5: 1893-10-13T00:00:00Z
A6: http://www.wikidata.org/entity/Q113754119 | B6: Adolf De Wolf | C6: http://www.wikidata.org/entity/Q336977 | D6: Guido Gezelle | E6: Correspondent (Zender) → Guido (Ontvanger) | F6: correspondent | G6: 1886-06-01T00:00:00Z | H6: 1898-01-01T00:00:00Z
A7: http://www.wikidata.org/entity/Q2524668 | B7: Adolf Duclos | C7: http://www.wikidata.org/entity/Q2491266 | D7: Johan Winkler | E7: Onderlinge Correspondentie (Source → Target) | F7: correspondent
A8: http://www.wikidata.org/entity/Q2524668 | B8: Adolf Duclos | C8: http://www.wikidata.org/entity/Q120729190 | D8: Camiel-Hector Marichal | E8: Onderlinge Correspondentie (Source → Target) | F8: correspondent
A9: http://www.wikidata.org/entity/Q2524668 | B9: Adolf Duclos | C9: http://www.wikidata.org/entity/Q115820195 | D9: Joseph Axters | E9: Onderlinge Correspondentie (Source → Target) | F9: correspondent | I9: 1889-12-02T00:00:00Z
A10: http://www.wikidata.org/entity/Q2524668 | B10: Adolf Duclos | C10: http://www.wikidata.org/entity/Q110039178 | D10: Pieter Baes | E10: Onderlinge Correspondentie (Source → Target) | F10: correspondent | G10: 1879-05-01T00:00:00Z
A11: http://www.wikidata.org/entity/Q2524668 | B11: Adolf Duclos | C11: http://www.wikidata.org/entity/Q2298746 | D11: Aloïs Walgrave | E11: Onderlinge Correspondentie (Source → Target) | F11: correspondent
A12: http://www.wikidata.org/entity/Q2524668 | B12: Adolf Duclos | C12: http://www.wikidata.org/entity/Q2361397 | D12: Frans De Cort | E12: Onderlinge Correspondentie (Source → Target) | F12: correspondent
A13: http://www.wikidata.org/entity/Q2524668 | B13: Adolf Duclos | C13: http://www.wikidata.org/entity/Q120900509 | D13: Emile Florimond Herman Van Biervliet | E13: Onderlinge Correspondentie (Source → Target) | F13: correspondent
A14: http://www.wikidata.org/entity/Q2524668 | B14: Adolf Duclos | C14: http://www.wikidata.org/entity/Q120733873 | D14: Johannes-Désiré Minnaert | E14: Onderlinge Correspondentie (Source → Target) | F14: correspondent
A15: http://www.wikidata.org/entity/Q2524668 | B15: Adolf Duclos | C15: http://www.wikidata.org/entity/Q115815004 | D15: Hendrik Mortier | E15: Onderlinge Correspondentie (Source → Target) | F15: correspondent
A16: http://www.wikidata.org/entity/Q2524668 | B16: Adolf Duclos | C16: http://www.wikidata.org/entity/Q2546317 | D16: Eugeen van Oye | E16: Onderlinge Correspondentie (Source → Target) | F16: correspondent
A17: http://www.wikidata.org/entity/Q2524668 | B17: Adolf Duclos | C17: http://www.wikidata.org/entity/Q336977 | D17: Guido Gezelle | E17: Correspondent (Zender) → Guido (Ontvanger) | F17: correspondent | G17: 1867-12-01T00:00:00Z | H17: 1885-11-27T00:00:00Z
A18: http://www.wikidata.org/entity/Q2524668 | B18: Adolf Duclos | C18: http://www.wikidata.org/entity/Q13575404 | D18: Edward Van Even | E18: Onderlinge Correspondentie (Source → Target) | F18: correspondent
A19: http://www.wikidata.org/entity/Q2524668 | B19: Adolf Duclos | C19: http://www.wikidata.org/entity/Q115811334 | D19: Joseph Samyn | E19: Onderlinge Correspondentie (Source → Target) | F19: correspondent
A20: http://www.wikidata.org/entity/Q2524668 | B20: Adolf Duclos | C20: http://www.wikidata.org/entity/Q2542423 | D20: Karel de Gheldere | E20: Onderlinge Correspondentie (Source → Target) | F20: correspondent
A21: http://www.wikidata.org/entity/Q2524668 | B21: Adolf Duclos | C21: http://www.wikidata.org/entity/Q1978794 | D21: Joseph Alberdingk Thijm | E21: Onderlinge Correspondentie (Source → Target) | F21: correspondent
A22: http://www.wikidata.org/entity/Q2524668 | B22: Adolf Duclos | C22: http://www.wikidata.org/entity/Q2099446 | D22: Amaat Joos | E22: Onderlinge Correspondentie (Source → Target) | F22: correspondent
A23: http://www.wikidata.org/entity/Q2524668 | B23: Adolf Duclos | C23: http://www.wikidata.org/entity/Q110039361 | D23: Polydoor Dionysius Daniëls | E23: Onderlinge Correspondentie (Source → Target) | F23: correspondent
A24: http://www.wikidata.org/entity/Q2524668 | B24: Adolf Duclos | C24: http://www.wikidata.org/entity/Q62080181 | D24: Ernest Rembry | E24: Onderlinge Correspondentie (Source → Target) | F24: correspondent
A25: http://www.wikidata.org/entity/Q2524668 | B25: Adolf Duclos | C25: http://www.wikidata.org/entity/Q2617184 | D25: Karel De Flou | E25: Onderlinge Correspondentie (Source → Target) | F25: correspondent
A26: http://www.wikidata.org/entity/Q2524668 | B26: Adolf Duclos | C26: http://www.wikidata.org/entity/Q329468 | D26: Jan Nolet de Brauwere van Steeland | E26: Onderlinge Correspondentie (Source → Target) | F26: correspondent | G26: 1884-03-10T00:00:00Z | H26: 1884-08-20T00:00:00Z
A27: http://www.wikidata.org/entity/Q2524668 | B27: Adolf Duclos | C27: http://www.wikidata.org/entity/Q1920135 | D27: Jan Bols | E27: Onderlinge Correspondentie (Source → Target) | F27: correspondent
A28: http://www.wikidata.org/entity/Q2524668 | B28: Adolf Duclos | C28: http://www.wikidata.org/entity/Q56036067 | D28: Lodewijk Willem Schuermans | E28: Onderlinge Correspondentie (Source → Target) | F28: correspondent
A29: http://www.wikidata.org/entity/Q2524668 | B29: Adolf Duclos | C29: http://www.wikidata.org/entity/Q784390 | D29: Paul Alberdingk Thijm | E29: Onderlinge Correspondentie (Source → Target) | F29: correspondent | G29: 1889-02-08T00:00:00Z | H29: 1891-01-29T00:00:00Z
A30: http://www.wikidata.org/entity/Q2524668 | B30: Adolf Duclos | C30: http://www.wikidata.org/entity/Q2496044 | D30: Gustave Henri Flamen | E30: Onderlinge Correspondentie (Source → Target) | F30: correspondent
A31: http://www.wikidata.org/entity/Q43140929 | B31: Adolf Pauwels | C31: http://www.wikidata.org/entity/Q336977 | D31: Guido Gezelle | E31: Correspondent (Zender) → Guido (Ontvanger) | F31: correspondent | I31: 1884-05-24T00:00:00Z
A32: http://www.wikidata.org/entity/Q100534520 | B32: Adolf Verriest | C32: http://www.wikidata.org/entity/Q336977 | D32: Guido Gezelle | E32: Correspondent (Zender) → Guido (Ontvanger) | F32: correspondent | H32: 1872-11-09T00:00:00Z
A33: http://www.wikidata.org/entity/Q100534520 | B33: Adolf Verriest | C33: http://www.wikidata.org/entity/Q784390 | D33: Paul Alberdingk Thijm | E33: Onderlinge Correspondentie (Source → Target) | F33: correspondent | I33: 1886-09-30T00:00:00Z
A34: http://www.wikidata.org/entity/Q100534520 | B34: Adolf Verriest | C34: http://www.wikidata.org/entity/Q336977 | D34: Guido Gezelle | E34: Correspondent (Zender) → Guido (Ontvanger) | F34: vriend
A35: http://www.wikidata.org/entity/Q136793932 | B35: Adèle Serweytens | C35: http://www.wikidata.org/entity/Q336977 | D35: Guido Gezelle | E35: Correspondent (Zender) → Guido (Ontvanger) | F35: bekende
A36: http://www.wikidata.org/entity/Q116687284 | B36: Agnes Mary Christophers | C36: http://www.wikidata.org/entity/Q336977 | D36: Guido Gezelle | E36: Correspondent (Zender) → Guido (Ontvanger) | F36: correspondent | I36: 1857-09-01T00:00:00Z
A37: http://www.wikidata.org/entity/Q118772822 | B37: Albert Aimé Marie Vandewalle | C37: http://www.wikidata.org/entity/Q336977 | D37: Guido Gezelle | E37: Correspondent (Zender) → Guido (Ontvanger) | F37: correspondent | I37: 1895-01-01T00:00:00Z
A38: http://www.wikidata.org/entity/Q586323 | B38: Albert Verwey | C38: http://www.wikidata.org/entity/Q981444 | D38: Hugo Verriest | E38: Onderlinge Correspondentie (Source → Target) | F38: correspondent
A39: http://www.wikidata.org/entity/Q586323 | B39: Albert Verwey | C39: http://www.wikidata.org/entity/Q336977 | D39: Guido Gezelle | E39: Correspondent (Zender) → Guido (Ontvanger) | F39: correspondent | I39: 1899-01-05T00:00:00Z
A40: http://www.wikidata.org/entity/Q2832059 | B40: Albéric Emmanuel Henri Marie Ghislain Ruzette | C40: http://www.wikidata.org/entity/Q336977 | D40: Guido Gezelle | E40: Correspondent (Zender) → Guido (Ontvanger) | F40: correspondent
...

Sheet Kopie van V5Q1
A1: source | B1: sourceLabel | C1: target | D1: targetLabel | E1: richtingBeschrijving | F1: rolLabel | G1: start | H1: Startyear | I1: startYearValue | J1: eind | K1: Endyear | L1: EndyearValue | M1: punt | N1: Pointyear | O1: PointYearValue | P1: FinalStartyear | Q1: FinalEndYear
A2: http://www.wikidata.org/entity/Q119454376 | B2: t Daghet in den Oosten | C2: http://www.wikidata.org/entity/Q336977 | D2: Guido Gezelle | E2: Correspondent (Zender) → Guido (Ontvanger) | F2: medewerker | H2: =IFERROR(LEFT(G2, 4), "") | K2: =IFERROR(LEFT(J2, 4), "") | N2: =IFERROR(LEFT(M2, 4), "") | P2: =IF(I2="", O2, I2) | Q2: =IF(L2="", O2, L2)
A3: http://www.wikidata.org/entity/Q115818424 | B3: Achiel Piepers | C3: http://www.wikidata.org/entity/Q336977 | D3: Guido Gezelle | E3: Correspondent (Zender) → Guido (Ontvanger) | F3: correspondent | H3: =IFERROR(LEFT(G3, 4), "") | K3: =IFERROR(LEFT(J3, 4), "") | M3: 1889-11-06T00:00:00Z | N3: =IFERROR(LEFT(M3, 4), "") -> 1889 | O3: 1889 | P3: =IF(I3="", O3, I3) -> 1889 | Q3: =IF(L3="", O3, L3) -> 1889
A4: http://www.wikidata.org/entity/Q119013873 | B4: Achiel Van de Putte | C4: http://www.wikidata.org/entity/Q336977 | D4: Guido Gezelle | E4: Correspondent (Zender) → Guido (Ontvanger) | F4: correspondent | H4: =IFERROR(LEFT(G4, 4), "") | K4: =IFERROR(LEFT(J4, 4), "") | M4: 1892-05-15T00:00:00Z | N4: =IFERROR(LEFT(M4, 4), "") -> 1892 | O4: 1892 | P4: =IF(I4="", O4, I4) -> 1892 | Q4: =IF(L4="", O4, L4) -> 1892
A5: http://www.wikidata.org/entity/Q119217729 | B5: Achille Croquison | C5: http://www.wikidata.org/entity/Q336977 | D5: Guido Gezelle | E5: Correspondent (Zender) → Guido (Ontvanger) | F5: correspondent | H5: =IFERROR(LEFT(G5, 4), "") | K5: =IFERROR(LEFT(J5, 4), "") | M5: 1893-10-13T00:00:00Z | N5: =IFERROR(LEFT(M5, 4), "") -> 1893 | O5: 1893 | P5: =IF(I5="", O5, I5) -> 1893 | Q5: =IF(L5="", O5, L5) -> 1893
A6: http://www.wikidata.org/entity/Q113754119 | B6: Adolf De Wolf | C6: http://www.wikidata.org/entity/Q336977 | D6: Guido Gezelle | E6: Correspondent (Zender) → Guido (Ontvanger) | F6: correspondent | G6: 1886-06-01T00:00:00Z | H6: =IFERROR(LEFT(G6, 4), "") -> 1886 | I6: 1886 | J6: 1898-01-01T00:00:00Z | K6: =IFERROR(LEFT(J6, 4), "") -> 1898 | L6: 1898 | N6: =IFERROR(LEFT(M6, 4), "") | P6: =IF(I6="", O6, I6) -> 1886 | Q6: =IF(L6="", O6, L6) -> 1898
A7: http://www.wikidata.org/entity/Q2524668 | B7: Adolf Duclos | C7: http://www.wikidata.org/entity/Q2491266 | D7: Johan Winkler | E7: Onderlinge Correspondentie (Source → Target) | F7: correspondent | H7: =IFERROR(LEFT(G7, 4), "") | K7: =IFERROR(LEFT(J7, 4), "") | N7: =IFERROR(LEFT(M7, 4), "") | P7: =IF(I7="", O7, I7) | Q7: =IF(L7="", O7, L7)
A8: http://www.wikidata.org/entity/Q2524668 | B8: Adolf Duclos | C8: http://www.wikidata.org/entity/Q120729190 | D8: Camiel-Hector Marichal | E8: Onderlinge Correspondentie (Source → Target) | F8: correspondent | H8: =IFERROR(LEFT(G8, 4), "") | K8: =IFERROR(LEFT(J8, 4), "") | N8: =IFERROR(LEFT(M8, 4), "") | P8: =IF(I8="", O8, I8) | Q8: =IF(L8="", O8, L8)
A9: http://www.wikidata.org/entity/Q2524668 | B9: Adolf Duclos | C9: http://www.wikidata.org/entity/Q115820195 | D9: Joseph Axters | E9: Onderlinge Correspondentie (Source → Target) | F9: correspondent | H9: =IFERROR(LEFT(G9, 4), "") | K9: =IFERROR(LEFT(J9, 4), "") | M9: 1889-12-02T00:00:00Z | N9: =IFERROR(LEFT(M9, 4), "") -> 1889 | O9: 1889 | P9: =IF(I9="", O9, I9) -> 1889 | Q9: =IF(L9="", O9, L9) -> 1889
A10: http://www.wikidata.org/entity/Q2524668 | B10: Adolf Duclos | C10: http://www.wikidata.org/entity/Q110039178 | D10: Pieter Baes | E10: Onderlinge Correspondentie (Source → Target) | F10: correspondent | G10: 1879-05-01T00:00:00Z | H10: =IFERROR(LEFT(G10, 4), "") -> 1879 | I10: 1879 | K10: =IFERROR(LEFT(J10, 4), "") | N10: =IFERROR(LEFT(M10, 4), "") | P10: =IF(I10="", O10, I10) -> 1879 | Q10: =IF(L10="", O10, L10)
A11: http://www.wikidata.org/entity/Q2524668 | B11: Adolf Duclos | C11: http://www.wikidata.org/entity/Q2298746 | D11: Aloïs Walgrave | E11: Onderlinge Correspondentie (Source → Target) | F11: correspondent | H11: =IFERROR(LEFT(G11, 4), "") | K11: =IFERROR(LEFT(J11, 4), "") | N11: =IFERROR(LEFT(M11, 4), "") | P11: =IF(I11="", O11, I11) | Q11: =IF(L11="", O11, L11)
A12: http://www.wikidata.org/entity/Q2524668 | B12: Adolf Duclos | C12: http://www.wikidata.org/entity/Q2361397 | D12: Frans De Cort | E12: Onderlinge Correspondentie (Source → Target) | F12: correspondent | H12: =IFERROR(LEFT(G12, 4), "") | K12: =IFERROR(LEFT(J12, 4), "") | N12: =IFERROR(LEFT(M12, 4), "") | P12: =IF(I12="", O12, I12) | Q12: =IF(L12="", O12, L12)
A13: http://www.wikidata.org/entity/Q2524668 | B13: Adolf Duclos | C13: http://www.wikidata.org/entity/Q120900509 | D13: Emile Florimond Herman Van Biervliet | E13: Onderlinge Correspondentie (Source → Target) | F13: correspondent | H13: =IFERROR(LEFT(G13, 4), "") | K13: =IFERROR(LEFT(J13, 4), "") | N13: =IFERROR(LEFT(M13, 4), "") | P13: =IF(I13="", O13, I13) | Q13: =IF(L13="", O13, L13)
A14: http://www.wikidata.org/entity/Q2524668 | B14: Adolf Duclos | C14: http://www.wikidata.org/entity/Q120733873 | D14: Johannes-Désiré Minnaert | E14: Onderlinge Correspondentie (Source → Target) | F14: correspondent | H14: =IFERROR(LEFT(G14, 4), "") | K14: =IFERROR(LEFT(J14, 4), "") | N14: =IFERROR(LEFT(M14, 4), "") | P14: =IF(I14="", O14, I14) | Q14: =IF(L14="", O14, L14)
A15: http://www.wikidata.org/entity/Q2524668 | B15: Adolf Duclos | C15: http://www.wikidata.org/entity/Q115815004 | D15: Hendrik Mortier | E15: Onderlinge Correspondentie (Source → Target) | F15: correspondent | H15: =IFERROR(LEFT(G15, 4), "") | K15: =IFERROR(LEFT(J15, 4), "") | N15: =IFERROR(LEFT(M15, 4), "") | P15: =IF(I15="", O15, I15) | Q15: =IF(L15="", O15, L15)
A16: http://www.wikidata.org/entity/Q2524668 | B16: Adolf Duclos | C16: http://www.wikidata.org/entity/Q2546317 | D16: Eugeen van Oye | E16: Onderlinge Correspondentie (Source → Target) | F16: correspondent | H16: =IFERROR(LEFT(G16, 4), "") | K16: =IFERROR(LEFT(J16, 4), "") | N16: =IFERROR(LEFT(M16, 4), "") | P16: =IF(I16="", O16, I16) | Q16: =IF(L16="", O16, L16)
A17: http://www.wikidata.org/entity/Q2524668 | B17: Adolf Duclos | C17: http://www.wikidata.org/entity/Q336977 | D17: Guido Gezelle | E17: Correspondent (Zender) → Guido (Ontvanger) | F17: correspondent | G17: 1867-12-01T00:00:00Z | H17: =IFERROR(LEFT(G17, 4), "") -> 1867 | I17: 1867 | J17: 1885-11-27T00:00:00Z | K17: =IFERROR(LEFT(J17, 4), "") -> 1885 | L17: 1885 | N17: =IFERROR(LEFT(M17, 4), "") | P17: =IF(I17="", O17, I17) -> 1867 | Q17: =IF(L17="", O17, L17) -> 1885
A18: http://www.wikidata.org/entity/Q2524668 | B18: Adolf Duclos | C18: http://www.wikidata.org/entity/Q13575404 | D18: Edward Van Even | E18: Onderlinge Correspondentie (Source → Target) | F18: correspondent | H18: =IFERROR(LEFT(G18, 4), "") | K18: =IFERROR(LEFT(J18, 4), "") | N18: =IFERROR(LEFT(M18, 4), "") | P18: =IF(I18="", O18, I18) | Q18: =IF(L18="", O18, L18)
A19: http://www.wikidata.org/entity/Q2524668 | B19: Adolf Duclos | C19: http://www.wikidata.org/entity/Q115811334 | D19: Joseph Samyn | E19: Onderlinge Correspondentie (Source → Target) | F19: correspondent | H19: =IFERROR(LEFT(G19, 4), "") | K19: =IFERROR(LEFT(J19, 4), "") | N19: =IFERROR(LEFT(M19, 4), "") | P19: =IF(I19="", O19, I19) | Q19: =IF(L19="", O19, L19)
A20: http://www.wikidata.org/entity/Q2524668 | B20: Adolf Duclos | C20: http://www.wikidata.org/entity/Q2542423 | D20: Karel de Gheldere | E20: Onderlinge Correspondentie (Source → Target) | F20: correspondent | H20: =IFERROR(LEFT(G20, 4), "") | K20: =IFERROR(LEFT(J20, 4), "") | N20: =IFERROR(LEFT(M20, 4), "") | P20: =IF(I20="", O20, I20) | Q20: =IF(L20="", O20, L20)
A21: http://www.wikidata.org/entity/Q2524668 | B21: Adolf Duclos | C21: http://www.wikidata.org/entity/Q1978794 | D21: Joseph Alberdingk Thijm | E21: Onderlinge Correspondentie (Source → Target) | F21: correspondent | H21: =IFERROR(LEFT(G21, 4), "") | K21: =IFERROR(LEFT(J21, 4), "") | N21: =IFERROR(LEFT(M21, 4), "") | P21: =IF(I21="", O21, I21) | Q21: =IF(L21="", O21, L21)
A22: http://www.wikidata.org/entity/Q2524668 | B22: Adolf Duclos | C22: http://www.wikidata.org/entity/Q2099446 | D22: Amaat Joos | E22: Onderlinge Correspondentie (Source → Target) | F22: correspondent | H22: =IFERROR(LEFT(G22, 4), "") | K22: =IFERROR(LEFT(J22, 4), "") | N22: =IFERROR(LEFT(M22, 4), "") | P22: =IF(I22="", O22, I22) | Q22: =IF(L22="", O22, L22)
A23: http://www.wikidata.org/entity/Q2524668 | B23: Adolf Duclos | C23: http://www.wikidata.org/entity/Q110039361 | D23: Polydoor Dionysius Daniëls | E23: Onderlinge Correspondentie (Source → Target) | F23: correspondent | H23: =IFERROR(LEFT(G23, 4), "") | K23: =IFERROR(LEFT(J23, 4), "") | N23: =IFERROR(LEFT(M23, 4), "") | P23: =IF(I23="", O23, I23) | Q23: =IF(L23="", O23, L23)
A24: http://www.wikidata.org/entity/Q2524668 | B24: Adolf Duclos | C24: http://www.wikidata.org/entity/Q62080181 | D24: Ernest Rembry | E24: Onderlinge Correspondentie (Source → Target) | F24: correspondent | H24: =IFERROR(LEFT(G24, 4), "") | K24: =IFERROR(LEFT(J24, 4), "") | N24: =IFERROR(LEFT(M24, 4), "") | P24: =IF(I24="", O24, I24) | Q24: =IF(L24="", O24, L24)
A25: http://www.wikidata.org/entity/Q2524668 | B25: Adolf Duclos | C25: http://www.wikidata.org/entity/Q2617184 | D25: Karel De Flou | E25: Onderlinge Correspondentie (Source → Target) | F25: correspondent | H25: =IFERROR(LEFT(G25, 4), "") | K25: =IFERROR(LEFT(J25, 4), "") | N25: =IFERROR(LEFT(M25, 4), "") | P25: =IF(I25="", O25, I25) | Q25: =IF(L25="", O25, L25)
A26: http://www.wikidata.org/entity/Q2524668 | B26: Adolf Duclos | C26: http://www.wikidata.org/entity/Q329468 | D26: Jan Nolet de Brauwere van Steeland | E26: Onderlinge Correspondentie (Source → Target) | F26: correspondent | G26: 1884-03-10T00:00:00Z | H26: =IFERROR(LEFT(G26, 4), "") -> 1884 | I26: 1884 | J26: 1884-08-20T00:00:00Z | K26: =IFERROR(LEFT(J26, 4), "") -> 1884 | L26: 1884 | N26: =IFERROR(LEFT(M26, 4), "") | P26: =IF(I26="", O26, I26) -> 1884 | Q26: =IF(L26="", O26, L26) -> 1884
A27: http://www.wikidata.org/entity/Q2524668 | B27: Adolf Duclos | C27: http://www.wikidata.org/entity/Q1920135 | D27: Jan Bols | E27: Onderlinge Correspondentie (Source → Target) | F27: correspondent | H27: =IFERROR(LEFT(G27, 4), "") | K27: =IFERROR(LEFT(J27, 4), "") | N27: =IFERROR(LEFT(M27, 4), "") | P27: =IF(I27="", O27, I27) | Q27: =IF(L27="", O27, L27)
A28: http://www.wikidata.org/entity/Q2524668 | B28: Adolf Duclos | C28: http://www.wikidata.org/entity/Q56036067 | D28: Lodewijk Willem Schuermans | E28: Onderlinge Correspondentie (Source → Target) | F28: correspondent | H28: =IFERROR(LEFT(G28, 4), "") | K28: =IFERROR(LEFT(J28, 4), "") | N28: =IFERROR(LEFT(M28, 4), "") | P28: =IF(I28="", O28, I28) | Q28: =IF(L28="", O28, L28)
A29: http://www.wikidata.org/entity/Q2524668 | B29: Adolf Duclos | C29: http://www.wikidata.org/entity/Q784390 | D29: Paul Alberdingk Thijm | E29: Onderlinge Correspondentie (Source → Target) | F29: correspondent | G29: 1889-02-08T00:00:00Z | H29: =IFERROR(LEFT(G29, 4), "") -> 1889 | I29: 1889 | J29: 1891-01-29T00:00:00Z | K29: =IFERROR(LEFT(J29, 4), "") -> 1891 | L29: 1891 | N29: =IFERROR(LEFT(M29, 4), "") | P29: =IF(I29="", O29, I29) -> 1889 | Q29: =IF(L29="", O29, L29) -> 1891
A30: http://www.wikidata.org/entity/Q2524668 | B30: Adolf Duclos | C30: http://www.wikidata.org/entity/Q2496044 | D30: Gustave Henri Flamen | E30: Onderlinge Correspondentie (Source → Target) | F30: correspondent | H30: =IFERROR(LEFT(G30, 4), "") | K30: =IFERROR(LEFT(J30, 4), "") | N30: =IFERROR(LEFT(M30, 4), "") | P30: =IF(I30="", O30, I30) | Q30: =IF(L30="", O30, L30)
A31: http://www.wikidata.org/entity/Q43140929 | B31: Adolf Pauwels | C31: http://www.wikidata.org/entity/Q336977 | D31: Guido Gezelle | E31: Correspondent (Zender) → Guido (Ontvanger) | F31: correspondent | H31: =IFERROR(LEFT(G31, 4), "") | K31: =IFERROR(LEFT(J31, 4), "") | M31: 1884-05-24T00:00:00Z | N31: =IFERROR(LEFT(M31, 4), "") -> 1884 | O31: 1884 | P31: =IF(I31="", O31, I31) -> 1884 | Q31: =IF(L31="", O31, L31) -> 1884
A32: http://www.wikidata.org/entity/Q100534520 | B32: Adolf Verriest | C32: http://www.wikidata.org/entity/Q336977 | D32: Guido Gezelle | E32: Correspondent (Zender) → Guido (Ontvanger) | F32: correspondent | H32: =IFERROR(LEFT(G32, 4), "") | J32: 1872-11-09T00:00:00Z | K32: =IFERROR(LEFT(J32, 4), "") -> 1872 | L32: 1872 | N32: =IFERROR(LEFT(M32, 4), "") | P32: =IF(I32="", O32, I32) | Q32: =IF(L32="", O32, L32) -> 1872
A33: http://www.wikidata.org/entity/Q100534520 | B33: Adolf Verriest | C33: http://www.wikidata.org/entity/Q784390 | D33: Paul Alberdingk Thijm | E33: Onderlinge Correspondentie (Source → Target) | F33: correspondent | H33: =IFERROR(LEFT(G33, 4), "") | K33: =IFERROR(LEFT(J33, 4), "") | M33: 1886-09-30T00:00:00Z | N33: =IFERROR(LEFT(M33, 4), "") -> 1886 | O33: 1886 | P33: =IF(I33="", O33, I33) -> 1886 | Q33: =IF(L33="", O33, L33) -> 1886
A34: http://www.wikidata.org/entity/Q100534520 | B34: Adolf Verriest | C34: http://www.wikidata.org/entity/Q336977 | D34: Guido Gezelle | E34: Correspondent (Zender) → Guido (Ontvanger) | F34: vriend | H34: =IFERROR(LEFT(G34, 4), "") | K34: =IFERROR(LEFT(J34, 4), "") | N34: =IFERROR(LEFT(M34, 4), "") | P34: =IF(I34="", O34, I34) | Q34: =IF(L34="", O34, L34)
A35: http://www.wikidata.org/entity/Q136793932 | B35: Adèle Serweytens | C35: http://www.wikidata.org/entity/Q336977 | D35: Guido Gezelle | E35: Correspondent (Zender) → Guido (Ontvanger) | F35: bekende | H35: =IFERROR(LEFT(G35, 4), "") | K35: =IFERROR(LEFT(J35, 4), "") | N35: =IFERROR(LEFT(M35, 4), "") | P35: =IF(I35="", O35, I35) | Q35: =IF(L35="", O35, L35)
A36: http://www.wikidata.org/entity/Q116687284 | B36: Agnes Mary Christophers | C36: http://www.wikidata.org/entity/Q336977 | D36: Guido Gezelle | E36: Correspondent (Zender) → Guido (Ontvanger) | F36: correspondent | H36: =IFERROR(LEFT(G36, 4), "") | K36: =IFERROR(LEFT(J36, 4), "") | M36: 1857-09-01T00:00:00Z | N36: =IFERROR(LEFT(M36, 4), "") -> 1857 | O36: 1857 | P36: =IF(I36="", O36, I36) -> 1857 | Q36: =IF(L36="", O36, L36) -> 1857
A37: http://www.wikidata.org/entity/Q118772822 | B37: Albert Aimé Marie Vandewalle | C37: http://www.wikidata.org/entity/Q336977 | D37: Guido Gezelle | E37: Correspondent (Zender) → Guido (Ontvanger) | F37: correspondent | H37: =IFERROR(LEFT(G37, 4), "") | K37: =IFERROR(LEFT(J37, 4), "") | M37: 1895-01-01T00:00:00Z | N37: =IFERROR(LEFT(M37, 4), "") -> 1895 | O37: 1895 | P37: =IF(I37="", O37, I37) -> 1895 | Q37: =IF(L37="", O37, L37) -> 1895
A38: http://www.wikidata.org/entity/Q586323 | B38: Albert Verwey | C38: http://www.wikidata.org/entity/Q981444 | D38: Hugo Verriest | E38: Onderlinge Correspondentie (Source → Target) | F38: correspondent | H38: =IFERROR(LEFT(G38, 4), "") | K38: =IFERROR(LEFT(J38, 4), "") | N38: =IFERROR(LEFT(M38, 4), "") | P38: =IF(I38="", O38, I38) | Q38: =IF(L38="", O38, L38)
A39: http://www.wikidata.org/entity/Q586323 | B39: Albert Verwey | C39: http://www.wikidata.org/entity/Q336977 | D39: Guido Gezelle | E39: Correspondent (Zender) → Guido (Ontvanger) | F39: correspondent | H39: =IFERROR(LEFT(G39, 4), "") | K39: =IFERROR(LEFT(J39, 4), "") | M39: 1899-01-05T00:00:00Z | N39: =IFERROR(LEFT(M39, 4), "") -> 1899 | O39: 1899 | P39: =IF(I39="", O39, I39) -> 1899 | Q39: =IF(L39="", O39, L39) -> 1899
A40: http://www.wikidata.org/entity/Q2832059 | B40: Albéric Emmanuel Henri Marie Ghislain Ruzette | C40: http://www.wikidata.org/entity/Q336977 | D40: Guido Gezelle | E40: Correspondent (Zender) → Guido (Ontvanger) | F40: correspondent | H40: =IFERROR(LEFT(G40, 4), "") | K40: =IFERROR(LEFT(J40, 4), "") | N40: =IFERROR(LEFT(M40, 4), "") | P40: =IF(I40="", O40, I40) | Q40: =IF(L40="", O40, L40)
...

Sheet V5Q2
A1: person | B1: personLabel | C1: relatieLabel | D1: value | E1: valueLabel | F1: start | G1: eind | H1: punt
A2: http://www.wikidata.org/entity/Q100534520 | B2: Adolf Verriest | C2: Beroep | D2: http://www.wikidata.org/entity/Q36834 | E2: componist
A3: http://www.wikidata.org/entity/Q100534520 | B3: Adolf Verriest | C3: Beroep | D3: http://www.wikidata.org/entity/Q40348 | E3: advocaat
A4: http://www.wikidata.org/entity/Q100534520 | B4: Adolf Verriest | C4: Beroep | D4: http://www.wikidata.org/entity/Q82955 | E4: politicus
A5: http://www.wikidata.org/entity/Q100534520 | B5: Adolf Verriest | C5: Beroep | D5: http://www.wikidata.org/entity/Q49757 | E5: dichter
A6: http://www.wikidata.org/entity/Q100534520 | B6: Adolf Verriest | C6: Werklocatie | D6: http://www.wikidata.org/entity/Q12995 | E6: Kortrijk
A7: http://www.wikidata.org/entity/Q101627274 | B7: Juliaan Claerhout | C7: Beroep | D7: http://www.wikidata.org/entity/Q3621491 | E7: archeoloog
A8: http://www.wikidata.org/entity/Q101627274 | B8: Juliaan Claerhout | C8: Beroep | D8: http://www.wikidata.org/entity/Q1753370 | E8: parochievicaris | F8: 1889-09-23T00:00:00Z
A9: http://www.wikidata.org/entity/Q101627274 | B9: Juliaan Claerhout | C9: Beroep | D9: http://www.wikidata.org/entity/Q1469535 | E9: rooms-katholiek priester | F9: 1883-12-22T00:00:00Z
A10: http://www.wikidata.org/entity/Q101627274 | B10: Juliaan Claerhout | C10: Beroep | D10: http://www.wikidata.org/entity/Q2251335 | E10: leerkracht | F10: 1884-09-18T00:00:00Z
A11: http://www.wikidata.org/entity/Q101627274 | B11: Juliaan Claerhout | C11: Beroep | D11: http://www.wikidata.org/entity/Q1056391 | E11: rector
A12: http://www.wikidata.org/entity/Q101627274 | B12: Juliaan Claerhout | C12: Beroep | D12: http://www.wikidata.org/entity/Q955464 | E12: pastoor
A13: http://www.wikidata.org/entity/Q101627274 | B13: Juliaan Claerhout | C13: Werkgever | D13: http://www.wikidata.org/entity/Q119853947 | E13: Normaalschool Torhout | F13: 1887-09-10T00:00:00Z
A14: http://www.wikidata.org/entity/Q101627274 | B14: Juliaan Claerhout | C14: Werkgever | D14: http://www.wikidata.org/entity/Q118369334 | E14: Sint-Jozefscollege Tielt | F14: 1884-09-18T00:00:00Z
A15: http://www.wikidata.org/entity/Q101627274 | B15: Juliaan Claerhout | C15: Werklocatie | D15: http://www.wikidata.org/entity/Q651724 | E15: Pittem | F15: 1894-11-24T00:00:00Z
A16: http://www.wikidata.org/entity/Q101627274 | B16: Juliaan Claerhout | C16: Werklocatie | D16: http://www.wikidata.org/entity/Q651811 | E16: Tielt | F16: 1884-09-18T00:00:00Z
A17: http://www.wikidata.org/entity/Q101627274 | B17: Juliaan Claerhout | C17: Werklocatie | D17: http://www.wikidata.org/entity/Q705020 | E17: Kaster | F17: 1911-02-17T00:00:00Z
A18: http://www.wikidata.org/entity/Q101627274 | B18: Juliaan Claerhout | C18: Werklocatie | D18: http://www.wikidata.org/entity/Q270633 | E18: Torhout | F18: 1887-09-10T00:00:00Z
A19: http://www.wikidata.org/entity/Q101627274 | B19: Juliaan Claerhout | C19: Werklocatie | D19: http://www.wikidata.org/entity/Q2354846 | E19: Sint-Denijs | F19: 1889-09-23T00:00:00Z
A20: http://www.wikidata.org/entity/Q110039159 | B20: Jan Craeynest | C20: Beroep | D20: http://www.wikidata.org/entity/Q1657500 | E20: aalmoezenier | F20: 1900-01-01T00:00:00Z
A21: http://www.wikidata.org/entity/Q110039159 | B21: Jan Craeynest | C21: Beroep | D21: http://www.wikidata.org/entity/Q955464 | E21: pastoor | F21: 1904-01-01T00:00:00Z
A22: http://www.wikidata.org/entity/Q110039159 | B22: Jan Craeynest | C22: Beroep | D22: http://www.wikidata.org/entity/Q42603 | E22: priester | F22: 1882-01-01T00:00:00Z
A23: http://www.wikidata.org/entity/Q110039159 | B23: Jan Craeynest | C23: Beroep | D23: http://www.wikidata.org/entity/Q36180 | E23: schrijver
A24: http://www.wikidata.org/entity/Q110039159 | B24: Jan Craeynest | C24: Beroep | D24: http://www.wikidata.org/entity/Q2251335 | E24: leerkracht | F24: 1883-09-01T00:00:00Z | G24: 1892-08-12T00:00:00Z
A25: http://www.wikidata.org/entity/Q110039159 | B25: Jan Craeynest | C25: Werkgever | D25: http://www.wikidata.org/entity/Q2663876 | E25: Sint-Lodewijkscollege | F25: 1883-09-01T00:00:00Z | G25: 1892-08-12T00:00:00Z
A26: http://www.wikidata.org/entity/Q110039159 | B26: Jan Craeynest | C26: Werklocatie | D26: http://www.wikidata.org/entity/Q12994 | E26: Brugge | F26: 1883-09-01T00:00:00Z
A27: http://www.wikidata.org/entity/Q110039170 | B27: Leonardus Nuttin | C27: Beroep | D27: http://www.wikidata.org/entity/Q250867 | E27: katholiek priester | F27: 1849-03-03T00:00:00Z
A28: http://www.wikidata.org/entity/Q110039170 | B28: Leonardus Nuttin | C28: Beroep | D28: http://www.wikidata.org/entity/Q1753370 | E28: parochievicaris
A29: http://www.wikidata.org/entity/Q110039170 | B29: Leonardus Nuttin | C29: Beroep | D29: http://www.wikidata.org/entity/Q11977377 | E29: inspecteur
A30: http://www.wikidata.org/entity/Q110039170 | B30: Leonardus Nuttin | C30: Beroep | D30: http://www.wikidata.org/entity/Q955464 | E30: pastoor | F30: 1870-06-22T00:00:00Z
A31: http://www.wikidata.org/entity/Q110039170 | B31: Leonardus Nuttin | C31: Beroep | D31: http://www.wikidata.org/entity/Q2251335 | E31: leerkracht | F31: 1850-01-01T00:00:00Z
A32: http://www.wikidata.org/entity/Q110039170 | B32: Leonardus Nuttin | C32: Werkgever | D32: http://www.wikidata.org/entity/Q2663876 | E32: Sint-Lodewijkscollege | F32: 1850-01-01T00:00:00Z
A33: http://www.wikidata.org/entity/Q110039170 | B33: Leonardus Nuttin | C33: Werkgever | D33: http://www.wikidata.org/entity/Q15882061 | E33: Sint-Vincentiuscollege (Ieper) | F33: 1852-01-01T00:00:00Z | G33: 1863-01-01T00:00:00Z
A34: http://www.wikidata.org/entity/Q110039170 | B34: Leonardus Nuttin | C34: Werkgever | D34: http://www.wikidata.org/entity/Q118369334 | E34: Sint-Jozefscollege Tielt | F34: 1851-01-01T00:00:00Z
A35: http://www.wikidata.org/entity/Q110039170 | B35: Leonardus Nuttin | C35: Werklocatie | D35: http://www.wikidata.org/entity/Q2316093 | E35: Zarren | F35: 1876-09-14T00:00:00Z
A36: http://www.wikidata.org/entity/Q110039170 | B36: Leonardus Nuttin | C36: Werklocatie | D36: http://www.wikidata.org/entity/Q102728 | E36: Ieper | F36: 1852-01-01T00:00:00Z | G36: 1863-01-01T00:00:00Z
A37: http://www.wikidata.org/entity/Q110039170 | B37: Leonardus Nuttin | C37: Werklocatie | D37: http://www.wikidata.org/entity/Q12994 | E37: Brugge | F37: 1850-01-01T00:00:00Z
A38: http://www.wikidata.org/entity/Q110039170 | B38: Leonardus Nuttin | C38: Werklocatie | D38: http://www.wikidata.org/entity/Q215244 | E38: Diksmuide
A39: http://www.wikidata.org/entity/Q110039170 | B39: Leonardus Nuttin | C39: Werklocatie | D39: http://www.wikidata.org/entity/Q651811 | E39: Tielt | F39: 1851-01-01T00:00:00Z
A40: http://www.wikidata.org/entity/Q110039170 | B40: Leonardus Nuttin | C40: Werklocatie | D40: http://www.wikidata.org/entity/Q1021461 | E40: Bossuit | F40: 1870-06-22T00:00:00Z
...

Sheet Kopie van V5Q2
A1: person | B1: personLabel | C1: relatieLabel | D1: value | E1: valueLabel | F1: start | G1: StartYear | H1: eind | I1: EndYear | J1: punt | K1: PointYear | L1: FinalStartYear | M1: FinalEndYear
A2: http://www.wikidata.org/entity/Q100534520 | B2: Adolf Verriest | C2: Beroep | D2: http://www.wikidata.org/entity/Q36834 | E2: componist | G2: =IFERROR(LEFT(F2, 4), "") | I2: =IFERROR(LEFT(H2, 4), "") | K2: =IFERROR(LEFT(H2, 4), "") | L2: =IF(G2="", K2, G2) | M2: =IF(I2="", K2, I2)
A3: http://www.wikidata.org/entity/Q100534520 | B3: Adolf Verriest | C3: Beroep | D3: http://www.wikidata.org/entity/Q40348 | E3: advocaat | G3: =IFERROR(LEFT(F3, 4), "") | I3: =IFERROR(LEFT(H3, 4), "") | K3: =IFERROR(LEFT(H3, 4), "") | L3: =IF(G3="", K3, G3) | M3: =IF(I3="", K3, I3)
A4: http://www.wikidata.org/entity/Q100534520 | B4: Adolf Verriest | C4: Beroep | D4: http://www.wikidata.org/entity/Q82955 | E4: politicus | G4: =IFERROR(LEFT(F4, 4), "") | I4: =IFERROR(LEFT(H4, 4), "") | K4: =IFERROR(LEFT(H4, 4), "") | L4: =IF(G4="", K4, G4) | M4: =IF(I4="", K4, I4)
A5: http://www.wikidata.org/entity/Q100534520 | B5: Adolf Verriest | C5: Beroep | D5: http://www.wikidata.org/entity/Q49757 | E5: dichter | G5: =IFERROR(LEFT(F5, 4), "") | I5: =IFERROR(LEFT(H5, 4), "") | K5: =IFERROR(LEFT(H5, 4), "") | L5: =IF(G5="", K5, G5) | M5: =IF(I5="", K5, I5)
A6: http://www.wikidata.org/entity/Q100534520 | B6: Adolf Verriest | C6: Werklocatie | D6: http://www.wikidata.org/entity/Q12995 | E6: Kortrijk | G6: =IFERROR(LEFT(F6, 4), "") | I6: =IFERROR(LEFT(H6, 4), "") | K6: =IFERROR(LEFT(H6, 4), "") | L6: =IF(G6="", K6, G6) | M6: =IF(I6="", K6, I6)
A7: http://www.wikidata.org/entity/Q101627274 | B7: Juliaan Claerhout | C7: Beroep | D7: http://www.wikidata.org/entity/Q3621491 | E7: archeoloog | G7: =IFERROR(LEFT(F7, 4), "") | I7: =IFERROR(LEFT(H7, 4), "") | K7: =IFERROR(LEFT(H7, 4), "") | L7: =IF(G7="", K7, G7) | M7: =IF(I7="", K7, I7)
A8: http://www.wikidata.org/entity/Q101627274 | B8: Juliaan Claerhout | C8: Beroep | D8: http://www.wikidata.org/entity/Q1753370 | E8: parochievicaris | F8: 1889-09-23T00:00:00Z | G8: =IFERROR(LEFT(F8, 4), "") -> 1889 | I8: =IFERROR(LEFT(H8, 4), "") | K8: =IFERROR(LEFT(H8, 4), "") | L8: =IF(G8="", K8, G8) -> 1889 | M8: =IF(I8="", K8, I8)
A9: http://www.wikidata.org/entity/Q101627274 | B9: Juliaan Claerhout | C9: Beroep | D9: http://www.wikidata.org/entity/Q1469535 | E9: rooms-katholiek priester | F9: 1883-12-22T00:00:00Z | G9: =IFERROR(LEFT(F9, 4), "") -> 1883 | I9: =IFERROR(LEFT(H9, 4), "") | K9: =IFERROR(LEFT(H9, 4), "") | L9: =IF(G9="", K9, G9) -> 1883 | M9: =IF(I9="", K9, I9)
A10: http://www.wikidata.org/entity/Q101627274 | B10: Juliaan Claerhout | C10: Beroep | D10: http://www.wikidata.org/entity/Q2251335 | E10: leerkracht | F10: 1884-09-18T00:00:00Z | G10: =IFERROR(LEFT(F10, 4), "") -> 1884 | I10: =IFERROR(LEFT(H10, 4), "") | K10: =IFERROR(LEFT(H10, 4), "") | L10: =IF(G10="", K10, G10) -> 1884 | M10: =IF(I10="", K10, I10)
A11: http://www.wikidata.org/entity/Q101627274 | B11: Juliaan Claerhout | C11: Beroep | D11: http://www.wikidata.org/entity/Q1056391 | E11: rector | G11: =IFERROR(LEFT(F11, 4), "") | I11: =IFERROR(LEFT(H11, 4), "") | K11: =IFERROR(LEFT(H11, 4), "") | L11: =IF(G11="", K11, G11) | M11: =IF(I11="", K11, I11)
A12: http://www.wikidata.org/entity/Q101627274 | B12: Juliaan Claerhout | C12: Beroep | D12: http://www.wikidata.org/entity/Q955464 | E12: pastoor | G12: =IFERROR(LEFT(F12, 4), "") | I12: =IFERROR(LEFT(H12, 4), "") | K12: =IFERROR(LEFT(H12, 4), "") | L12: =IF(G12="", K12, G12) | M12: =IF(I12="", K12, I12)
A13: http://www.wikidata.org/entity/Q101627274 | B13: Juliaan Claerhout | C13: Werkgever | D13: http://www.wikidata.org/entity/Q119853947 | E13: Normaalschool Torhout | F13: 1887-09-10T00:00:00Z | G13: =IFERROR(LEFT(F13, 4), "") -> 1887 | I13: =IFERROR(LEFT(H13, 4), "") | K13: =IFERROR(LEFT(H13, 4), "") | L13: =IF(G13="", K13, G13) -> 1887 | M13: =IF(I13="", K13, I13)
A14: http://www.wikidata.org/entity/Q101627274 | B14: Juliaan Claerhout | C14: Werkgever | D14: http://www.wikidata.org/entity/Q118369334 | E14: Sint-Jozefscollege Tielt | F14: 1884-09-18T00:00:00Z | G14: =IFERROR(LEFT(F14, 4), "") -> 1884 | I14: =IFERROR(LEFT(H14, 4), "") | K14: =IFERROR(LEFT(H14, 4), "") | L14: =IF(G14="", K14, G14) -> 1884 | M14: =IF(I14="", K14, I14)
A15: http://www.wikidata.org/entity/Q101627274 | B15: Juliaan Claerhout | C15: Werklocatie | D15: http://www.wikidata.org/entity/Q651724 | E15: Pittem | F15: 1894-11-24T00:00:00Z | G15: =IFERROR(LEFT(F15, 4), "") -> 1894 | I15: =IFERROR(LEFT(H15, 4), "") | K15: =IFERROR(LEFT(H15, 4), "") | L15: =IF(G15="", K15, G15) -> 1894 | M15: =IF(I15="", K15, I15)
A16: http://www.wikidata.org/entity/Q101627274 | B16: Juliaan Claerhout | C16: Werklocatie | D16: http://www.wikidata.org/entity/Q651811 | E16: Tielt | F16: 1884-09-18T00:00:00Z | G16: =IFERROR(LEFT(F16, 4), "") -> 1884 | I16: =IFERROR(LEFT(H16, 4), "") | K16: =IFERROR(LEFT(H16, 4), "") | L16: =IF(G16="", K16, G16) -> 1884 | M16: =IF(I16="", K16, I16)
A17: http://www.wikidata.org/entity/Q101627274 | B17: Juliaan Claerhout | C17: Werklocatie | D17: http://www.wikidata.org/entity/Q705020 | E17: Kaster | F17: 1911-02-17T00:00:00Z | G17: =IFERROR(LEFT(F17, 4), "") -> 1911 | I17: =IFERROR(LEFT(H17, 4), "") | K17: =IFERROR(LEFT(H17, 4), "") | L17: =IF(G17="", K17, G17) -> 1911 | M17: =IF(I17="", K17, I17)
A18: http://www.wikidata.org/entity/Q101627274 | B18: Juliaan Claerhout | C18: Werklocatie | D18: http://www.wikidata.org/entity/Q270633 | E18: Torhout | F18: 1887-09-10T00:00:00Z | G18: =IFERROR(LEFT(F18, 4), "") -> 1887 | I18: =IFERROR(LEFT(H18, 4), "") | K18: =IFERROR(LEFT(H18, 4), "") | L18: =IF(G18="", K18, G18) -> 1887 | M18: =IF(I18="", K18, I18)
A19: http://www.wikidata.org/entity/Q101627274 | B19: Juliaan Claerhout | C19: Werklocatie | D19: http://www.wikidata.org/entity/Q2354846 | E19: Sint-Denijs | F19: 1889-09-23T00:00:00Z | G19: =IFERROR(LEFT(F19, 4), "") -> 1889 | I19: =IFERROR(LEFT(H19, 4), "") | K19: =IFERROR(LEFT(H19, 4), "") | L19: =IF(G19="", K19, G19) -> 1889 | M19: =IF(I19="", K19, I19)
A20: http://www.wikidata.org/entity/Q110039159 | B20: Jan Craeynest | C20: Beroep | D20: http://www.wikidata.org/entity/Q1657500 | E20: aalmoezenier | F20: 1900-01-01T00:00:00Z | G20: =IFERROR(LEFT(F20, 4), "") -> 1900 | I20: =IFERROR(LEFT(H20, 4), "") | K20: =IFERROR(LEFT(H20, 4), "") | L20: =IF(G20="", K20, G20) -> 1900 | M20: =IF(I20="", K20, I20)
A21: http://www.wikidata.org/entity/Q110039159 | B21: Jan Craeynest | C21: Beroep | D21: http://www.wikidata.org/entity/Q955464 | E21: pastoor | F21: 1904-01-01T00:00:00Z | G21: =IFERROR(LEFT(F21, 4), "") -> 1904 | I21: =IFERROR(LEFT(H21, 4), "") | K21: =IFERROR(LEFT(H21, 4), "") | L21: =IF(G21="", K21, G21) -> 1904 | M21: =IF(I21="", K21, I21)
A22: http://www.wikidata.org/entity/Q110039159 | B22: Jan Craeynest | C22: Beroep | D22: http://www.wikidata.org/entity/Q42603 | E22: priester | F22: 1882-01-01T00:00:00Z | G22: =IFERROR(LEFT(F22, 4), "") -> 1882 | I22: =IFERROR(LEFT(H22, 4), "") | K22: =IFERROR(LEFT(H22, 4), "") | L22: =IF(G22="", K22, G22) -> 1882 | M22: =IF(I22="", K22, I22)
A23: http://www.wikidata.org/entity/Q110039159 | B23: Jan Craeynest | C23: Beroep | D23: http://www.wikidata.org/entity/Q36180 | E23: schrijver | G23: =IFERROR(LEFT(F23, 4), "") | I23: =IFERROR(LEFT(H23, 4), "") | K23: =IFERROR(LEFT(H23, 4), "") | L23: =IF(G23="", K23, G23) | M23: =IF(I23="", K23, I23)
A24: http://www.wikidata.org/entity/Q110039159 | B24: Jan Craeynest | C24: Beroep | D24: http://www.wikidata.org/entity/Q2251335 | E24: leerkracht | F24: 1883-09-01T00:00:00Z | G24: =IFERROR(LEFT(F24, 4), "") -> 1883 | H24: 1892-08-12T00:00:00Z | I24: =IFERROR(LEFT(H24, 4), "") -> 1892 | K24: =IFERROR(LEFT(H24, 4), "") -> 1892 | L24: =IF(G24="", K24, G24) -> 1883 | M24: =IF(I24="", K24, I24) -> 1892
A25: http://www.wikidata.org/entity/Q110039159 | B25: Jan Craeynest | C25: Werkgever | D25: http://www.wikidata.org/entity/Q2663876 | E25: Sint-Lodewijkscollege | F25: 1883-09-01T00:00:00Z | G25: =IFERROR(LEFT(F25, 4), "") -> 1883 | H25: 1892-08-12T00:00:00Z | I25: =IFERROR(LEFT(H25, 4), "") -> 1892 | K25: =IFERROR(LEFT(H25, 4), "") -> 1892 | L25: =IF(G25="", K25, G25) -> 1883 | M25: =IF(I25="", K25, I25) -> 1892
A26: http://www.wikidata.org/entity/Q110039159 | B26: Jan Craeynest | C26: Werklocatie | D26: http://www.wikidata.org/entity/Q12994 | E26: Brugge | F26: 1883-09-01T00:00:00Z | G26: =IFERROR(LEFT(F26, 4), "") -> 1883 | I26: =IFERROR(LEFT(H26, 4), "") | K26: =IFERROR(LEFT(H26, 4), "") | L26: =IF(G26="", K26, G26) -> 1883 | M26: =IF(I26="", K26, I26)
A27: http://www.wikidata.org/entity/Q110039170 | B27: Leonardus Nuttin | C27: Beroep | D27: http://www.wikidata.org/entity/Q250867 | E27: katholiek priester | F27: 1849-03-03T00:00:00Z | G27: =IFERROR(LEFT(F27, 4), "") -> 1849 | I27: =IFERROR(LEFT(H27, 4), "") | K27: =IFERROR(LEFT(H27, 4), "") | L27: =IF(G27="", K27, G27) -> 1849 | M27: =IF(I27="", K27, I27)
A28: http://www.wikidata.org/entity/Q110039170 | B28: Leonardus Nuttin | C28: Beroep | D28: http://www.wikidata.org/entity/Q1753370 | E28: parochievicaris | G28: =IFERROR(LEFT(F28, 4), "") | I28: =IFERROR(LEFT(H28, 4), "") | K28: =IFERROR(LEFT(H28, 4), "") | L28: =IF(G28="", K28, G28) | M28: =IF(I28="", K28, I28)
A29: http://www.wikidata.org/entity/Q110039170 | B29: Leonardus Nuttin | C29: Beroep | D29: http://www.wikidata.org/entity/Q11977377 | E29: inspecteur | G29: =IFERROR(LEFT(F29, 4), "") | I29: =IFERROR(LEFT(H29, 4), "") | K29: =IFERROR(LEFT(H29, 4), "") | L29: =IF(G29="", K29, G29) | M29: =IF(I29="", K29, I29)
A30: http://www.wikidata.org/entity/Q110039170 | B30: Leonardus Nuttin | C30: Beroep | D30: http://www.wikidata.org/entity/Q955464 | E30: pastoor | F30: 1870-06-22T00:00:00Z | G30: =IFERROR(LEFT(F30, 4), "") -> 1870 | I30: =IFERROR(LEFT(H30, 4), "") | K30: =IFERROR(LEFT(H30, 4), "") | L30: =IF(G30="", K30, G30) -> 1870 | M30: =IF(I30="", K30, I30)
A31: http://www.wikidata.org/entity/Q110039170 | B31: Leonardus Nuttin | C31: Beroep | D31: http://www.wikidata.org/entity/Q2251335 | E31: leerkracht | F31: 1850-01-01T00:00:00Z | G31: =IFERROR(LEFT(F31, 4), "") -> 1850 | I31: =IFERROR(LEFT(H31, 4), "") | K31: =IFERROR(LEFT(H31, 4), "") | L31: =IF(G31="", K31, G31) -> 1850 | M31: =IF(I31="", K31, I31)
A32: http://www.wikidata.org/entity/Q110039170 | B32: Leonardus Nuttin | C32: Werkgever | D32: http://www.wikidata.org/entity/Q2663876 | E32: Sint-Lodewijkscollege | F32: 1850-01-01T00:00:00Z | G32: =IFERROR(LEFT(F32, 4), "") -> 1850 | I32: =IFERROR(LEFT(H32, 4), "") | K32: =IFERROR(LEFT(H32, 4), "") | L32: =IF(G32="", K32, G32) -> 1850 | M32: =IF(I32="", K32, I32)
A33: http://www.wikidata.org/entity/Q110039170 | B33: Leonardus Nuttin | C33: Werkgever | D33: http://www.wikidata.org/entity/Q15882061 | E33: Sint-Vincentiuscollege (Ieper) | F33: 1852-01-01T00:00:00Z | G33: =IFERROR(LEFT(F33, 4), "") -> 1852 | H33: 1863-01-01T00:00:00Z | I33: =IFERROR(LEFT(H33, 4), "") -> 1863 | K33: =IFERROR(LEFT(H33, 4), "") -> 1863 | L33: =IF(G33="", K33, G33) -> 1852 | M33: =IF(I33="", K33, I33) -> 1863
A34: http://www.wikidata.org/entity/Q110039170 | B34: Leonardus Nuttin | C34: Werkgever | D34: http://www.wikidata.org/entity/Q118369334 | E34: Sint-Jozefscollege Tielt | F34: 1851-01-01T00:00:00Z | G34: =IFERROR(LEFT(F34, 4), "") -> 1851 | I34: =IFERROR(LEFT(H34, 4), "") | K34: =IFERROR(LEFT(H34, 4), "") | L34: =IF(G34="", K34, G34) -> 1851 | M34: =IF(I34="", K34, I34)
A35: http://www.wikidata.org/entity/Q110039170 | B35: Leonardus Nuttin | C35: Werklocatie | D35: http://www.wikidata.org/entity/Q2316093 | E35: Zarren | F35: 1876-09-14T00:00:00Z | G35: =IFERROR(LEFT(F35, 4), "") -> 1876 | I35: =IFERROR(LEFT(H35, 4), "") | K35: =IFERROR(LEFT(H35, 4), "") | L35: =IF(G35="", K35, G35) -> 1876 | M35: =IF(I35="", K35, I35)
A36: http://www.wikidata.org/entity/Q110039170 | B36: Leonardus Nuttin | C36: Werklocatie | D36: http://www.wikidata.org/entity/Q102728 | E36: Ieper | F36: 1852-01-01T00:00:00Z | G36: =IFERROR(LEFT(F36, 4), "") -> 1852 | H36: 1863-01-01T00:00:00Z | I36: =IFERROR(LEFT(H36, 4), "") -> 1863 | K36: =IFERROR(LEFT(H36, 4), "") -> 1863 | L36: =IF(G36="", K36, G36) -> 1852 | M36: =IF(I36="", K36, I36) -> 1863
A37: http://www.wikidata.org/entity/Q110039170 | B37: Leonardus Nuttin | C37: Werklocatie | D37: http://www.wikidata.org/entity/Q12994 | E37: Brugge | F37: 1850-01-01T00:00:00Z | G37: =IFERROR(LEFT(F37, 4), "") -> 1850 | I37: =IFERROR(LEFT(H37, 4), "") | K37: =IFERROR(LEFT(H37, 4), "") | L37: =IF(G37="", K37, G37) -> 1850 | M37: =IF(I37="", K37, I37)
A38: http://www.wikidata.org/entity/Q110039170 | B38: Leonardus Nuttin | C38: Werklocatie | D38: http://www.wikidata.org/entity/Q215244 | E38: Diksmuide | G38: =IFERROR(LEFT(F38, 4), "") | I38: =IFERROR(LEFT(H38, 4), "") | K38: =IFERROR(LEFT(H38, 4), "") | L38: =IF(G38="", K38, G38) | M38: =IF(I38="", K38, I38)
A39: http://www.wikidata.org/entity/Q110039170 | B39: Leonardus Nuttin | C39: Werklocatie | D39: http://www.wikidata.org/entity/Q651811 | E39: Tielt | F39: 1851-01-01T00:00:00Z | G39: =IFERROR(LEFT(F39, 4), "") -> 1851 | I39: =IFERROR(LEFT(H39, 4), "") | K39: =IFERROR(LEFT(H39, 4), "") | L39: =IF(G39="", K39, G39) -> 1851 | M39: =IF(I39="", K39, I39)
A40: http://www.wikidata.org/entity/Q110039170 | B40: Leonardus Nuttin | C40: Werklocatie | D40: http://www.wikidata.org/entity/Q1021461 | E40: Bossuit | F40: 1870-06-22T00:00:00Z | G40: =IFERROR(LEFT(F40, 4), "") -> 1870 | I40: =IFERROR(LEFT(H40, 4), "") | K40: =IFERROR(LEFT(H40, 4), "") | L40: =IF(G40="", K40, G40) -> 1870 | M40: =IF(I40="", K40, I40)
...

Sheet Nodes
A1: ID | B1: Label | C1: Category | D1: Geboorteplaats | E1: Afbeelding
A2: http://www.wikidata.org/entity/Q119454376 | B2: t Daghet in den Oosten | C2: Person
A3: http://www.wikidata.org/entity/Q115818424 | B3: Achiel Piepers | C3: Person
A4: http://www.wikidata.org/entity/Q119013873 | B4: Achiel Van de Putte | C4: Person
A5: http://www.wikidata.org/entity/Q119217729 | B5: Achille Croquison | C5: Person
A6: http://www.wikidata.org/entity/Q113754119 | B6: Adolf De Wolf | C6: Person
A7: http://www.wikidata.org/entity/Q2524668 | B7: Adolf Duclos | C7: Person
A8: http://www.wikidata.org/entity/Q2524668 | B8: Adolf Duclos | C8: Person
A9: http://www.wikidata.org/entity/Q2524668 | B9: Adolf Duclos | C9: Person
A10: http://www.wikidata.org/entity/Q2524668 | B10: Adolf Duclos | C10: Person
A11: http://www.wikidata.org/entity/Q2524668 | B11: Adolf Duclos | C11: Person
A12: http://www.wikidata.org/entity/Q2524668 | B12: Adolf Duclos | C12: Person
A13: http://www.wikidata.org/entity/Q2524668 | B13: Adolf Duclos | C13: Person
... A6509: http://www.wikidata.org/entity/Q2079 | B6509: Leipzig | C6509: Werklocatie

Sheet NodesNoDup
B1: Label | C1: Category | D1: Startyearcor | E1: StartyearcorFIX | F1: Startyearcorfixvalue | G1: EndYearcor
A2: Q119454376 | B2: t Daghet in den Oosten | C2: Person | D2: 1700 | E2: =IF(D2=1700,G2,D2) -> 1710 | F2: 1710 | G2: 1710
A3: Q115818424 | B3: Achiel Piepers | C3: Person | D3: 1889 | E3: =IF(D3=1700,G3,D3) -> 1889 | F3: 1889 | G3: 1889
A4: Q119013873 | B4: Achiel Van de Putte | C4: Person | D4: 1892 | E4: =IF(D4=1700,G4,D4) -> 1892 | F4: 1892 | G4: 1892
A5: Q119217729 | B5: Achille Croquison | C5: Person | D5: 1893 | E5: =IF(D5=1700,G5,D5) -> 1893 | F5: 1893 | G5: 1893
A6: Q113754119 | B6: Adolf De Wolf | C6: Person | D6: 1886 | E6: =IF(D6=1700,G6,D6) -> 1886 | F6: 1886 | G6: 1898
A7: Q2524668 | B7: Adolf Duclos | C7: Person | D7: 1700 | E7: =IF(D7=1700,G7,D7) -> 1710 | F7: 1710 | G7: 1710
A8: Q43140929 | B8: Adolf Pauwels | C8: Person | D8: 1884 | E8: =IF(D8=1700,G8,D8) -> 1884 | F8: 1884 | G8: 1884
A9: Q100534520 | B9: Adolf Verriest | C9: Person | D9: 1700 | E9: =IF(D9=1700,G9,D9) -> 1872 | F9: 1872 | G9: 1872
A10: Q136793932 | B10: Adèle Serweytens | C10: Person | D10: 1700 | E10: =IF(D10=1700,G10,D10) -> 1710 | F10: 1710 | G10: 1710
A11: Q116687284 | B11: Agnes Mary Christophers | C11: Person | D11: 1857 | E11: =IF(D11=1700,G11,D11) -> 1857 | F11: 1857 | G11: 1857
A12: Q118772822 | B12: Albert Aimé Marie Vandewalle | C12: Person | D12: 1895 | E12: =IF(D12=1700,G12,D12) -> 1895 | F12: 1895 | G12: 1895
A13: Q586323 | B13: Albert Verwey | C13: Person | D13: 1700 | E13: =IF(D13=1700,G13,D13) -> 1710 | F13: 1710 | G13: 1710
A14: Q2832059 | B14: Albéric Emmanuel Henri Marie Ghislain Ruzette | C14: Person | D14: 1700 | E14: =IF(D14=1700,G14,D14) -> 1710 | F14: 1710 | G14: 1710
A15: Q115811921 | B15: Alexandre Berghman | C15: Person | D15: 1700 | E15: =IF(D15=1700,G15,D15) -> 1710 | F15: 1710 | G15: 1710
A16: Q56036018 | B16: Alexandre Bonvarlet | C16: Person | D16: 1885 | E16: =IF(D16=1700,G16,D16) -> 1885 | F16: 1885 | G16: 1891
A17: Q118142378 | B17: Alfons Bouckaert | C17: Person | D17: 1895 | E17: =IF(D17=1700,G17,D17) -> 1895 | F17: 1895 | G17: 1896
A18: Q110039191 | B18: Alfons Dassonville | C18: Person | D18: 1896 | E18: =IF(D18=1700,G18,D18) -> 1896 | F18: 1896 | G18: 1896
A19: Q2100582 | B19: Alfons De Cock | C19: Person | D19: 1895 | E19: =IF(D19=1700,G19,D19) -> 1895 | F19: 1895 | G19: 1897
A20: Q2638823 | B20: Alfons Janssens | C20: Person | D20: 1888 | E20: =IF(D20=1700,G20,D20) -> 1888 | F20: 1888 | G20: 1888
A21: Q56036059 | B21: Alfons Maria Napoleon Prayon-van Zuylen van Nyevelt | C21: Person | D21: 1888 | E21: =IF(D21=1700,G21,D21) -> 1888 | F21: 1888 | G21: 1888
A22: Q2539969 | B22: Alfons Siffer | C22: Person | D22: 1700 | E22: =IF(D22=1700,G22,D22) -> 1710 | F22: 1710 | G22: 1710
A23: Q119621396 | B23: Alfons Steinmetz | C23: Person | D23: 1700 | E23: =IF(D23=1700,G23,D23) -> 1710 | F23: 1710 | G23: 1710
A24: Q2050293 | B24: Alfons Van Hee | C24: Person | D24: 1876 | E24: =IF(D24=1700,G24,D24) -> 1876 | F24: 1876 | G24: 1876
A25: Q26845752 | B25: Alfred Guichon de Grandpont | C25: Person | D25: 1896 | E25: =IF(D25=1700,G25,D25) -> 1896 | F25: 1896 | G25: 1896
A26: Q115979418 | B26: Aloysius Vandemaele | C26: Person | D26: 1850 | E26: =IF(D26=1700,G26,D26) -> 1850 | F26: 1850 | G26: 1890
A27: Q2580620 | B27: Aloïs Nelis | C27: Person | D27: 1889 | E27: =IF(D27=1700,G27,D27) -> 1889 | F27: 1889 | G27: 1889
A28: Q2298746 | B28: Aloïs Walgrave | C28: Person | D28: 1927 | E28: =IF(D28=1700,G28,D28) -> 1927 | F28: 1927 | G28: 1929
A29: Q2450554 | B29: Alphonse De Leyn | C29: Person | D29: 1890 | E29: =IF(D29=1700,G29,D29) -> 1890 | F29: 1890 | G29: 1895
A30: Q2099446 | B30: Amaat Joos | C30: Person | D30: 1897 | E30: =IF(D30=1700,G30,D30) -> 1897 | F30: 1897 | G30: 1897
A31: Q3421496 | B31: Amaat Vyncke | C31: Person | D31: 1880 | E31: =IF(D31=1700,G31,D31) -> 1880 | F31: 1880 | G31: 1883
A32: Q970036 | B32: Amand Neut | C32: Person | D32: 1892 | E32: =IF(D32=1700,G32,D32) -> 1892 | F32: 1892 | G32: 1892
A33: Q2481707 | B33: Amand de Vos | C33: Person | D33: 1886 | E33: =IF(D33=1700,G33,D33) -> 1886 | F33: 1886 | G33: 1889
A34: Q124619468 | B34: Amelia Vander Stichele | C34: Person | D34: 1700 | E34: =IF(D34=1700,G34,D34) -> 1710 | F34: 1710 | G34: 1710
A35: Q1280942 | B35: Amédée Visart de Bocarmé | C35: Person | D35: 1886 | E35: =IF(D35=1700,G35,D35) -> 1886 | F35: 1886 | G35: 1886
A36: Q119039774 | B36: Andries J. Winkler | C36: Person | D36: 1898 | E36: =IF(D36=1700,G36,D36) -> 1898 | F36: 1898 | G36: 1898
A37: Q13429634 | B37: Angelus August Eugeen Angillis | C37: Person | D37: 1700 | E37: =IF(D37=1700,G37,D37) -> 1710 | F37: 1710 | G37: 1710
A38: Q129255433 | B38: Ann Mary Eyre | C38: Person | D38: 1700 | E38: =IF(D38=1700,G38,D38) -> 1710 | F38: 1710 | G38: 1710
A39: Q116656531 | B39: Anna Demets | C39: Person | D39: 1700 | E39: =IF(D39=1700,G39,D39) -> 1710 | F39: 1710 | G39: 1710
A40: Q116508558 | B40: Anne Hill | C40: Person | D40: 1700 | E40: =IF(D40=1700,G40,D40) -> 1710 | F40: 1710 | G40: 1710
...

Sheet CleanNodes
A1: ID | B1: Label | C1: Category | D1: Startyear | E1: EndYear | F1: rol van persoon
A2: Q119454376 | B2: t Daghet in den Oosten | C2: Person | D2: 1710 | E2: 1710 | F2: =VLOOKUP(B2,V5Q1!B:F,5,0) -> medewerker
A3: Q115818424 | B3: Achiel Piepers | C3: Person | D3: 1889 | E3: 1889 | F3: =VLOOKUP(B3,V5Q1!B:F,5,0) -> correspondent
A4: Q119013873 | B4: Achiel Van de Putte | C4: Person | D4: 1892 | E4: 1892 | F4: =VLOOKUP(B4,V5Q1!B:F,5,0) -> correspondent
A5: Q119217729 | B5: Achille Croquison | C5: Person | D5: 1893 | E5: 1893 | F5: =VLOOKUP(B5,V5Q1!B:F,5,0) -> correspondent
A6: Q113754119 | B6: Adolf De Wolf | C6: Person | D6: 1886 | E6: 1898 | F6: =VLOOKUP(B6,V5Q1!B:F,5,0) -> correspondent
A7: Q2524668 | B7: Adolf Duclos | C7: Person | D7: 1710 | E7: 1710 | F7: =VLOOKUP(B7,V5Q1!B:F,5,0) -> correspondent
A8: Q43140929 | B8: Adolf Pauwels | C8: Person | D8: 1884 | E8: 1884 | F8: =VLOOKUP(B8,V5Q1!B:F,5,0) -> correspondent
A9: Q100534520 | B9: Adolf Verriest | C9: Person | D9: 1872 | E9: 1872 | F9: =VLOOKUP(B9,V5Q1!B:F,5,0) -> correspondent
A10: Q136793932 | B10: Adèle Serweytens | C10: Person | D10: 1710 | E10: 1710 | F10: =VLOOKUP(B10,V5Q1!B:F,5,0) -> bekende
A11: Q116687284 | B11: Agnes Mary Christophers | C11: Person | D11: 1857 | E11: 1857 | F11: =VLOOKUP(B11,V5Q1!B:F,5,0) -> correspondent
A12: Q118772822 | B12: Albert Aimé Marie Vandewalle | C12: Person | D12: 1895 | E12: 1895 | F12: =VLOOKUP(B12,V5Q1!B:F,5,0) -> correspondent
A13: Q586323 | B13: Albert Verwey | C13: Person | D13: 1710 | E13: 1710 | F13: =VLOOKUP(B13,V5Q1!B:F,5,0) -> correspondent
A14: Q2832059 | B14: Albéric Emmanuel Henri Marie Ghislain Ruzette | C14: Person | D14: 1710 | E14: 1710 | F14: =VLOOKUP(B14,V5Q1!B:F,5,0) -> correspondent
A15: Q115811921 | B15: Alexandre Berghman | C15: Person | D15: 1710 | E15: 1710 | F15: =VLOOKUP(B15,V5Q1!B:F,5,0) -> bekende
A16: Q56036018 | B16: Alexandre Bonvarlet | C16: Person | D16: 1885 | E16: 1891 | F16: =VLOOKUP(B16,V5Q1!B:F,5,0) -> correspondent
A17: Q118142378 | B17: Alfons Bouckaert | C17: Person | D17: 1895 | E17: 1896 | F17: =VLOOKUP(B17,V5Q1!B:F,5,0) -> correspondent
A18: Q110039191 | B18: Alfons Dassonville | C18: Person | D18: 1896 | E18: 1896 | F18: =VLOOKUP(B18,V5Q1!B:F,5,0) -> correspondent
A19: Q2100582 | B19: Alfons De Cock | C19: Person | D19: 1895 | E19: 1897 | F19: =VLOOKUP(B19,V5Q1!B:F,5,0) -> correspondent
A20: Q2638823 | B20: Alfons Janssens | C20: Person | D20: 1888 | E20: 1888 | F20: =VLOOKUP(B20,V5Q1!B:F,5,0) -> correspondent
A21: Q56036059 | B21: Alfons Maria Napoleon Prayon-van Zuylen van Nyevelt | C21: Person | D21: 1888 | E21: 1888 | F21: =VLOOKUP(B21,V5Q1!B:F,5,0) -> correspondent
A22: Q2539969 | B22: Alfons Siffer | C22: Person | D22: 1710 | E22: 1710 | F22: =VLOOKUP(B22,V5Q1!B:F,5,0) -> correspondent
A23: Q119621396 | B23: Alfons Steinmetz | C23: Person | D23: 1710 | E23: 1710 | F23: =VLOOKUP(B23,V5Q1!B:F,5,0) -> vriend
A24: Q2050293 | B24: Alfons Van Hee | C24: Person | D24: 1876 | E24: 1876 | F24: =VLOOKUP(B24,V5Q1!B:F,5,0) -> correspondent
A25: Q26845752 | B25: Alfred Guichon de Grandpont | C25: Person | D25: 1896 | E25: 1896 | F25: =VLOOKUP(B25,V5Q1!B:F,5,0) -> correspondent
A26: Q115979418 | B26: Aloysius Vandemaele | C26: Person | D26: 1850 | E26: 1890 | F26: =VLOOKUP(B26,V5Q1!B:F,5,0) -> correspondent
A27: Q2580620 | B27: Aloïs Nelis | C27: Person | D27: 1889 | E27: 1889 | F27: =VLOOKUP(B27,V5Q1!B:F,5,0) -> correspondent
A28: Q2298746 | B28: Aloïs Walgrave | C28: Person | D28: 1927 | E28: 1929 | F28: =VLOOKUP(B28,V5Q1!B:F,5,0) -> correspondent
A29: Q2450554 | B29: Alphonse De Leyn | C29: Person | D29: 1890 | E29: 1895 | F29: =VLOOKUP(B29,V5Q1!B:F,5,0) -> correspondent
A30: Q2099446 | B30: Amaat Joos | C30: Person | D30: 1897 | E30: 1897 | F30: =VLOOKUP(B30,V5Q1!B:F,5,0) -> correspondent
A31: Q3421496 | B31: Amaat Vyncke | C31: Person | D31: 1880 | E31: 1883 | F31: =VLOOKUP(B31,V5Q1!B:F,5,0) -> correspondent
A32: Q970036 | B32: Amand Neut | C32: Person | D32: 1892 | E32: 1892 | F32: =VLOOKUP(B32,V5Q1!B:F,5,0) -> correspondent
A33: Q2481707 | B33: Amand de Vos | C33: Person | D33: 1886 | E33: 1889 | F33: =VLOOKUP(B33,V5Q1!B:F,5,0) -> correspondent
A34: Q124619468 | B34: Amelia Vander Stichele | C34: Person | D34: 1710 | E34: 1710 | F34: =VLOOKUP(B34,V5Q1!B:F,5,0) -> correspondent
A35: Q1280942 | B35: Amédée Visart de Bocarmé | C35: Person | D35: 1886 | E35: 1886 | F35: =VLOOKUP(B35,V5Q1!B:F,5,0) -> correspondent
A36: Q119039774 | B36: Andries J. Winkler | C36: Person | D36: 1898 | E36: 1898 | F36: =VLOOKUP(B36,V5Q1!B:F,5,0) -> correspondent
A37: Q13429634 | B37: Angelus August Eugeen Angillis | C37: Person | D37: 1710 | E37: 1710 | F37: =VLOOKUP(B37,V5Q1!B:F,5,0) -> klasgenoot
A38: Q129255433 | B38: Ann Mary Eyre | C38: Person | D38: 1710 | E38: 1710 | F38: =VLOOKUP(B38,V5Q1!B:F,5,0) -> bekende
A39: Q116656531 | B39: Anna Demets | C39: Person | D39: 1710 | E39: 1710 | F39: =VLOOKUP(B39,V5Q1!B:F,5,0) -> correspondent
A40: Q116508558 | B40: Anne Hill | C40: Person | D40: 1710 | E40: 1710 | F40: =VLOOKUP(B40,V5Q1!B:F,5,0) -> correspondent
...

Sheet Edges
A1: Source | B1: Target | C1: Type | D1: Weight | E1: rolLabel | F1: FinalStartyear | G1: FinalEndYear
A2: Q119454376 | B2: Q336977 | C2: Directed | D2: 1 | E2: medewerker | F2: 1800 | G2: 1950
A3: Q115818424 | B3: Q336977 | C3: Directed | D3: 1 | E3: correspondent | F3: 1889 | G3: 1889
A4: Q119013873 | B4: Q336977 | C4: Directed | D4: 1 | E4: correspondent | F4: 1892 | G4: 1892
A5: Q119217729 | B5: Q336977 | C5: Directed | D5: 1 | E5: correspondent | F5: 1893 | G5: 1893
A6: Q113754119 | B6: Q336977 | C6: Directed | D6: 1 | E6: correspondent | F6: 1886 | G6: 1898
A7: Q2524668 | B7: Q2491266 | C7: Directed | D7: 1 | E7: correspondent | F7: 1800 | G7: 1950
A8: Q2524668 | B8: Q120729190 | C8: Directed | D8: 1 | E8: correspondent | F8: 1800 | G8: 1950
A9: Q2524668 | B9: Q115820195 | C9: Directed | D9: 1 | E9: correspondent | F9: 1889 | G9: 1889
A10: Q2524668 | B10: Q110039178 | C10: Directed | D10: 1 | E10: correspondent | F10: 1879 | G10: 1950
A11: Q2524668 | B11: Q2298746 | C11: Directed | D11: 1 | E11: correspondent | F11: 1800 | G11: 1950
A12: Q2524668 | B12: Q2361397 | C12: Directed | D12: 1 | E12: correspondent | F12: 1800 | G12: 1950
A13: Q2524668 | B13: Q120900509 | C13: Directed | D13: 1 | E13: correspondent | F13: 1800 | G13: 1950
A14: Q2524668 | B14: Q120733873 | C14: Directed | D14: 1 | E14: correspondent | F14: 1800 | G14: 1950
A15: Q2524668 | B15: Q115815004 | C15: Directed | D15: 1 | E15: correspondent | F15: 1800 | G15: 1950
A16: Q2524668 | B16: Q2546317 | C16: Directed | D16: 1 | E16: correspondent | F16: 1800 | G16: 1950
A17: Q2524668 | B17: Q336977 | C17: Directed | D17: 1 | E17: correspondent | F17: 1867 | G17: 1885
A18: Q2524668 | B18: Q13575404 | C18: Directed | D18: 1 | E18: correspondent | F18: 1800 | G18: 1950
A19: Q2524668 | B19: Q115811334 | C19: Directed | D19: 1 | E19: correspondent | F19: 1800 | G19: 1950
A20: Q2524668 | B20: Q2542423 | C20: Directed | D20: 1 | E20: correspondent | F20: 1800 | G20: 1950
A21: Q2524668 | B21: Q1978794 | C21: Directed | D21: 1 | E21: correspondent | F21: 1800 | G21: 1950
A22: Q2524668 | B22: Q2099446 | C22: Directed | D22: 1 | E22: correspondent | F22: 1800 | G22: 1950
A23: Q2524668 | B23: Q110039361 | C23: Directed | D23: 1 | E23: correspondent | F23: 1800 | G23: 1950
A24: Q2524668 | B24: Q62080181 | C24: Directed | D24: 1 | E24: correspondent | F24: 1800 | G24: 1950
A25: Q2524668 | B25: Q2617184 | C25: Directed | D25: 1 | E25: correspondent | F25: 1800 | G25: 1950
A26: Q2524668 | B26: Q329468 | C26: Directed | D26: 1 | E26: correspondent | F26: 1884 | G26: 1884
A27: Q2524668 | B27: Q1920135 | C27: Directed | D27: 1 | E27: correspondent | F27: 1800 | G27: 1950
A28: Q2524668 | B28: Q56036067 | C28: Directed | D28: 1 | E28: correspondent | F28: 1800 | G28: 1950
A29: Q2524668 | B29: Q784390 | C29: Directed | D29: 1 | E29: correspondent | F29: 1889 | G29: 1891
A30: Q2524668 | B30: Q2496044 | C30: Directed | D30: 1 | E30: correspondent | F30: 1800 | G30: 1950
A31: Q43140929 | B31: Q336977 | C31: Directed | D31: 1 | E31: correspondent | F31: 1884 | G31: 1884
A32: Q100534520 | B32: Q336977 | C32: Directed | D32: 1 | E32: correspondent | F32: 1800 | G32: 1872
A33: Q100534520 | B33: Q784390 | C33: Directed | D33: 1 | E33: correspondent | F33: 1886 | G33: 1886
A34: Q100534520 | B34: Q336977 | C34: Directed | D34: 1 | E34: vriend | F34: 1800 | G34: 1950
A35: Q136793932 | B35: Q336977 | C35: Directed | D35: 1 | E35: bekende | F35: 1800 | G35: 1950
A36: Q116687284 | B36: Q336977 | C36: Directed | D36: 1 | E36: correspondent | F36: 1857 | G36: 1857
